Workbook

Sheet まとめ
A1: KOKUSAI ELECTRIC（6525）：貿易統計による27/3期2Q売上のナウキャスト
A2: 単位：億円。数値はすべて他シートへのリンク（緑字）。作成日 2026-09-28、貿易統計は2026年8月分速報まで。
A4: 項目 | D4: 値
A5: 構造モデル k=0（基準） | D5: =ナウキャスト!G22 -> 845.54497
A6: 構造モデル k=0（低〜高） | D6: =TEXT(ナウキャスト!G21,"#,##0")&"〜"&TEXT(ナウキャスト!G23,"#,##0") -> 806〜868
A7: 構造モデル k=1（6-8月実績のみ） | D7: =ナウキャスト!G27 -> 792.45118
A8: 単一モデル k=0（基準）／k=1 | D8: =TEXT(ナウキャスト!J22,"#,##0")&"／"&TEXT(ナウキャスト!J27,"#,##0") -> 812／735
A9: 予測誤差の目安（構造 k=0 のLOOCV RMSE） | D9: =回帰!$F$23 -> 76.331108
A10: 会社計画が示す2Q売上 | D10: =ナウキャスト!D32 -> 856
A11: 計画達成に必要な9月輸出の前年比（7-8月は約＋40％） | D11: =ナウキャスト!D44 -> 0.50484762
A12: 計画が示す実質シェア（過去の最大値） | D12: =TEXT(ナウキャスト!D34,"0.0%")&"（"&TEXT(ナウキャスト!F35,"0.0%")&"）" -> 5.9%（6.1%）
A14: モデル精度（12四半期、leave-one-out）
A15: モデル | C15: R² | D15: LOOCV RMSE
A16: 単一 k=0 | C16: =回帰!$E$20 -> 0.46196353 | D16: =回帰!$F$20 -> 71.189384
A17: 構造 k=0 | C17: =回帰!$E$23 -> 0.46176286 | D17: =回帰!$F$23 -> 76.331108
A18: 単一 k=1 | C18: =回帰!$E$43 -> 0.44325558 | D18: =回帰!$F$43 -> 74.538144
A19: 構造 k=1 | C19: =回帰!$E$46 -> 0.42983211 | D19: =回帰!$F$46 -> 77.617814
A20: ランダムウォーク | D20: =回帰!$F$24 -> 112.62811
A21: うちグローバル売上×中国以外（k=0） | C21: =回帰!$E$22 -> 0.79792948
A23: 所見
A24: ・7-8月の輸出（前年比＋40％）を売上に換算すると、2Qは構造モデルで約790〜870億円（基準846億円）、単一モデルで約740〜830億円であり、計画856億円と同水準かやや下である。
A25: ・計画達成には、9月の輸出が前年比＋50％程度まで加速するか、KOKUSAIのシェアが過去最高圏に留まる必要がある。
A26: ・差は予測誤差（±70〜80億円）の範囲内であり、方向感の確認に留まる。9月速報（10/21）で再計算すれば決算前に精度が上がる。
A27: ・グローバル売上と中国以外向け輸出はR²0.8と強く連動する。一方、中国地場売上と対中輸出の連動は弱く、全社の精度を押し下げている。
A28: ・富山（伏木税関支署管内）の半導体等製造装置輸出は年23億円規模に過ぎず、税関別データから工場を特定する方法はKOKUSAIでは機能しなかった。

Sheet 速報_原データ
A1: 財務省 貿易統計 月次速報：概況品「半導体等製造装置」の地域別輸出（原データ）
A2: 青字＝各月の速報PDFから転記した値。価額は百万円、前年同月比は％（例：40.1＝＋40.1％）。
A4: 月 | B4: 地域 | C4: 価額（百万円） | D4: 前年同月比（％） | E4: 数量（トン） | F4: 数量前年比（％） | G4: 出所PDF | I4: 2024年5月の前年同月比（概要PDFより）
A5: 45383 | B5: ASEAN | C5: 17542 | D5: 27.4 | E5: 545 | F5: -1.2 | G5: https://www.customs.go.jp/toukei/shinbun/trade-st/2024/2024044.pdf | I5: 月 | J5: 地域 | K5: 前年同月比（％）
A6: 45383 | B6: Asia | C6: 322037 | D6: 45.2 | E6: 11129 | F6: 43.8 | G6: https://www.customs.go.jp/toukei/shinbun/trade-st/2024/2024044.pdf | I6: 45413 | J6: World | K6: 45.9
A7: 45383 | B7: China | C7: 188866 | D7: 95.4 | E7: 6494 | F7: 94.8 | G7: https://www.customs.go.jp/toukei/shinbun/trade-st/2024/2024044.pdf | I7: 45413 | J7: Asia | K7: 56.2
A8: 45383 | B8: EU | C8: 12280 | D8: -44.5 | E8: 395 | F8: -43.9 | G8: https://www.customs.go.jp/toukei/shinbun/trade-st/2024/2024044.pdf | I8: 45413 | J8: China | K8: 130.7
A9: 45383 | B9: Korea | C9: 45082 | D9: -0.4 | E9: 1611 | F9: 28.9 | G9: https://www.customs.go.jp/toukei/shinbun/trade-st/2024/2024044.pdf | I9: 45413 | J9: US | K9: 137.8
A10: 45383 | B10: US | C10: 42838 | D10: -16.3 | E10: 1188 | F10: -24.7 | G10: https://www.customs.go.jp/toukei/shinbun/trade-st/2024/2024044.pdf | I10: 出所: https://www.customs.go.jp/toukei/shinbun/trade-st/gaiyo2024_05.pdf
A11: 45383 | B11: World | C11: 379038 | D11: 28.2 | E11: 12780 | F11: 27.3 | G11: https://www.customs.go.jp/toukei/shinbun/trade-st/2024/2024044.pdf
A12: 45444 | B12: ASEAN | C12: 16156 | D12: 13.8 | E12: 426 | F12: -30 | G12: https://www.customs.go.jp/toukei/shinbun/trade-st/2024/2024064.pdf
A13: 45444 | B13: Asia | C13: 338211 | D13: 42.9 | E13: 11035 | F13: 28.5 | G13: https://www.customs.go.jp/toukei/shinbun/trade-st/2024/2024064.pdf
A14: 45444 | B14: China | C14: 192584 | D14: 47.7 | E14: 6249 | F14: 30.5 | G14: https://www.customs.go.jp/toukei/shinbun/trade-st/2024/2024064.pdf
A15: 45444 | B15: EU | C15: 10419 | D15: -48.7 | E15: 280 | F15: -49.7 | G15: https://www.customs.go.jp/toukei/shinbun/trade-st/2024/2024064.pdf
A16: 45444 | B16: Korea | C16: 54349 | D16: 7.6 | E16: 1963 | F16: 42.6 | G16: https://www.customs.go.jp/toukei/shinbun/trade-st/2024/2024064.pdf
A17: 45444 | B17: US | C17: 47981 | D17: 58.4 | E17: 1018 | F17: 18.2 | G17: https://www.customs.go.jp/toukei/shinbun/trade-st/2024/2024064.pdf
A18: 45444 | B18: World | C18: 397166 | D18: 37.9 | E18: 12343 | F18: 23 | G18: https://www.customs.go.jp/toukei/shinbun/trade-st/2024/2024064.pdf
A19: 45474 | B19: ASEAN | C19: 19766 | D19: 35.4 | E19: 564 | F19: -14.4 | G19: https://www.customs.go.jp/toukei/shinbun/trade-st/2024/2024074.pdf
A20: 45474 | B20: Asia | C20: 314213 | D20: 32.6 | E20: 9989 | F20: -2.3 | G20: https://www.customs.go.jp/toukei/shinbun/trade-st/2024/2024074.pdf
A21: 45474 | B21: China | C21: 163858 | D21: 16.6 | E21: 5287 | F21: -19.1 | G21: https://www.customs.go.jp/toukei/shinbun/trade-st/2024/2024074.pdf
A22: 45474 | B22: EU | C22: 8783 | D22: -49.1 | E22: 261 | F22: -56.9 | G22: https://www.customs.go.jp/toukei/shinbun/trade-st/2024/2024074.pdf
... A200: 46235 | B200: World | C200: 489764 | D200: 40.1 | E200: 15572 | F200: 43.1 | G200: https://www.customs.go.jp/toukei/shinbun/trade-st/2026/2026084.pdf

Sheet 貿易_月次
A1: 半導体等製造装置の輸出（億円）— 月次パネル
A2: 当月の速報値を優先。無い月は翌年同月の速報値÷(1＋前年同月比)で逆算。2023年5月は2段逆算、韓国・ASEAN・EUの同月は前後月の平均で補間。
B3: World | C3: Asia | D3: China | E3: Korea | F3: US | G3: EU | H3: ASEAN
A4: 月 | B4: 世界 | C4: アジア | D4: 中国 | E4: 韓国 | F4: 米国 | G4: EU | H4: ASEAN | I4: 中国以外 | J4: アジア残差（台湾等） | K4: 値の出所
A5: 45017 | B5: =IF(COUNTIFS(速報_原データ!$A$5:$A$200,$A5,速報_原データ!$B$5:$B$200,B$3)>0,SUMIFS(速報_原データ!$C$5:$C$200,速報_原データ!$A$5:$A$200,$A5,速報_原データ!$B$5:$B$200,B$3)/100,IF(COUNTIFS(速報_原データ!$A$5:$A$200,EDATE($A5,12),速報_原データ!$B$5:$B$200,B$3)>0,SUMIFS(速報_原データ!$C$5:$C$200,速報_原データ!$A$5:$A$200,EDATE($A5,12),速報_原データ!$B$5:$B$200,B$3)/100/(1+SUMIFS(速報_原データ!$D$5:$D$200,速報_原データ!$A$5:$A$200,EDATE($A5,12),速報_原データ!$B$5:$B$200,B$3)/100),IF(COUNTIFS(速報_原データ!$I$6:$I$9,EDATE($A5,12),速報_原データ!$J$6:$J$9,B$3)>0,B17/(1+SUMIFS(速報_原データ!$K$6:$K$9,速報_原データ!$I$6:$I$9,EDATE($A5,12),速報_原データ!$J$6:$J$9,B$3)/100),AVERAGE(B4,B6)))) -> 2956.6147 | C5: =IF(COUNTIFS(速報_原データ!$A$5:$A$200,$A5,速報_原データ!$B$5:$B$200,C$3)>0,SUMIFS(速報_原データ!$C$5:$C$200,速報_原データ!$A$5:$A$200,$A5,速報_原データ!$B$5:$B$200,C$3)/100,IF(COUNTIFS(速報_原データ!$A$5:$A$200,EDATE($A5,12),速報_原データ!$B$5:$B$200,C$3)>0,SUMIFS(速報_原データ!$C$5:$C$200,速報_原データ!$A$5:$A$200,EDATE($A5,12),速報_原データ!$B$5:$B$200,C$3)/100/(1+SUMIFS(速報_原データ!$D$5:$D$200,速報_原データ!$A$5:$A$200,EDATE($A5,12),速報_原データ!$B$5:$B$200,C$3)/100),IF(COUNTIFS(速報_原データ!$I$6:$I$9,EDATE($A5,12),速報_原データ!$J$6:$J$9,C$3)>0,C17/(1+SUMIFS(速報_原データ!$K$6:$K$9,速報_原データ!$I$6:$I$9,EDATE($A5,12),速報_原データ!$J$6:$J$9,C$3)/100),AVERAGE(C4,C6)))) -> 2217.8857 | D5: =IF(COUNTIFS(速報_原データ!$A$5:$A$200,$A5,速報_原データ!$B$5:$B$200,D$3)>0,SUMIFS(速報_原データ!$C$5:$C$200,速報_原データ!$A$5:$A$200,$A5,速報_原データ!$B$5:$B$200,D$3)/100,IF(COUNTIFS(速報_原データ!$A$5:$A$200,EDATE($A5,12),速報_原データ!$B$5:$B$200,D$3)>0,SUMIFS(速報_原データ!$C$5:$C$200,速報_原データ!$A$5:$A$200,EDATE($A5,12),速報_原データ!$B$5:$B$200,D$3)/100/(1+SUMIFS(速報_原データ!$D$5:$D$200,速報_原データ!$A$5:$A$200,EDATE($A5,12),速報_原データ!$B$5:$B$200,D$3)/100),IF(COUNTIFS(速報_原データ!$I$6:$I$9,EDATE($A5,12),速報_原データ!$J$6:$J$9,D$3)>0,D17/(1+SUMIFS(速報_原データ!$K$6:$K$9,速報_原データ!$I$6:$I$9,EDATE($A5,12),速報_原データ!$J$6:$J$9,D$3)/100),AVERAGE(D4,D6)))) -> 966.5609 | E5: =IF(COUNTIFS(速報_原データ!$A$5:$A$200,$A5,速報_原データ!$B$5:$B$200,E$3)>0,SUMIFS(速報_原データ!$C$5:$C$200,速報_原データ!$A$5:$A$200,$A5,速報_原データ!$B$5:$B$200,E$3)/100,IF(COUNTIFS(速報_原データ!$A$5:$A$200,EDATE($A5,12),速報_原データ!$B$5:$B$200,E$3)>0,SUMIFS(速報_原データ!$C$5:$C$200,速報_原データ!$A$5:$A$200,EDATE($A5,12),速報_原データ!$B$5:$B$200,E$3)/100/(1+SUMIFS(速報_原データ!$D$5:$D$200,速報_原データ!$A$5:$A$200,EDATE($A5,12),速報_原データ!$B$5:$B$200,E$3)/100),IF(COUNTIFS(速報_原データ!$I$6:$I$9,EDATE($A5,12),速報_原データ!$J$6:$J$9,E$3)>0,E17/(1+SUMIFS(速報_原データ!$K$6:$K$9,速報_原データ!$I$6:$I$9,EDATE($A5,12),速報_原データ!$J$6:$J$9,E$3)/100),AVERAGE(E4,E6)))) -> 452.63052 | F5: =IF(COUNTIFS(速報_原データ!$A$5:$A$200,$A5,速報_原データ!$B$5:$B$200,F$3)>0,SUMIFS(速報_原データ!$C$5:$C$200,速報_原データ!$A$5:$A$200,$A5,速報_原データ!$B$5:$B$200,F$3)/100,IF(COUNTIFS(速報_原データ!$A$5:$A$200,EDATE($A5,12),速報_原データ!$B$5:$B$200,F$3)>0,SUMIFS(速報_原データ!$C$5:$C$200,速報_原データ!$A$5:$A$200,EDATE($A5,12),速報_原データ!$B$5:$B$200,F$3)/100/(1+SUMIFS(速報_原データ!$D$5:$D$200,速報_原データ!$A$5:$A$200,EDATE($A5,12),速報_原データ!$B$5:$B$200,F$3)/100),IF(COUNTIFS(速報_原データ!$I$6:$I$9,EDATE($A5,12),速報_原データ!$J$6:$J$9,F$3)>0,F17/(1+SUMIFS(速報_原データ!$K$6:$K$9,速報_原データ!$I$6:$I$9,EDATE($A5,12),速報_原データ!$J$6:$J$9,F$3)/100),AVERAGE(F4,F6)))) -> 511.80406 | G5: =IF(COUNTIFS(速報_原データ!$A$5:$A$200,$A5,速報_原データ!$B$5:$B$200,G$3)>0,SUMIFS(速報_原データ!$C$5:$C$200,速報_原データ!$A$5:$A$200,$A5,速報_原データ!$B$5:$B$200,G$3)/100,IF(COUNTIFS(速報_原データ!$A$5:$A$200,EDATE($A5,12),速報_原データ!$B$5:$B$200,G$3)>0,SUMIFS(速報_原データ!$C$5:$C$200,速報_原データ!$A$5:$A$200,EDATE($A5,12),速報_原データ!$B$5:$B$200,G$3)/100/(1+SUMIFS(速報_原データ!$D$5:$D$200,速報_原データ!$A$5:$A$200,EDATE($A5,12),速報_原データ!$B$5:$B$200,G$3)/100),IF(COUNTIFS(速報_原データ!$I$6:$I$9,EDATE($A5,12),速報_原データ!$J$6:$J$9,G$3)>0,G17/(1+SUMIFS(速報_原データ!$K$6:$K$9,速報_原データ!$I$6:$I$9,EDATE($A5,12),速報_原データ!$J$6:$J$9,G$3)/100),AVERAGE(G4,G6)))) -> 221.26126 | H5: =IF(COUNTIFS(速報_原データ!$A$5:$A$200,$A5,速報_原データ!$B$5:$B$200,H$3)>0,SUMIFS(速報_原データ!$C$5:$C$200,速報_原データ!$A$5:$A$200,$A5,速報_原データ!$B$5:$B$200,H$3)/100,IF(COUNTIFS(速報_原データ!$A$5:$A$200,EDATE($A5,12),速報_原データ!$B$5:$B$200,H$3)>0,SUMIFS(速報_原データ!$C$5:$C$200,速報_原データ!$A$5:$A$200,EDATE($A5,12),速報_原データ!$B$5:$B$200,H$3)/100/(1+SUMIFS(速報_原データ!$D$5:$D$200,速報_原データ!$A$5:$A$200,EDATE($A5,12),速報_原データ!$B$5:$B$200,H$3)/100),IF(COUNTIFS(速報_原データ!$I$6:$I$9,EDATE($A5,12),速報_原データ!$J$6:$J$9,H$3)>0,H17/(1+SUMIFS(速報_原データ!$K$6:$K$9,速報_原データ!$I$6:$I$9,EDATE($A5,12),速報_原データ!$J$6:$J$9,H$3)/100),AVERAGE(H4,H6)))) -> 137.69231 | I5: =B5-D5 -> 1990.0538 | J5: =C5-D5-E5-H5 -> 661.00194 | K5: 翌年同月速報の前年比から逆算
A6: 45047 | B6: =IF(COUNTIFS(速報_原データ!$A$5:$A$200,$A6,速報_原データ!$B$5:$B$200,B$3)>0,SUMIFS(速報_原データ!$C$5:$C$200,速報_原データ!$A$5:$A$200,$A6,速報_原データ!$B$5:$B$200,B$3)/100,IF(COUNTIFS(速報_原データ!$A$5:$A$200,EDATE($A6,12),速報_原データ!$B$5:$B$200,B$3)>0,SUMIFS(速報_原データ!$C$5:$C$200,速報_原データ!$A$5:$A$200,EDATE($A6,12),速報_原データ!$B$5:$B$200,B$3)/100/(1+SUMIFS(速報_原データ!$D$5:$D$200,速報_原データ!$A$5:$A$200,EDATE($A6,12),速報_原データ!$B$5:$B$200,B$3)/100),IF(COUNTIFS(速報_原データ!$I$6:$I$9,EDATE($A6,12),速報_原データ!$J$6:$J$9,B$3)>0,B18/(1+SUMIFS(速報_原データ!$K$6:$K$9,速報_原データ!$I$6:$I$9,EDATE($A6,12),速報_原データ!$J$6:$J$9,B$3)/100),AVERAGE(B5,B7)))) -> 2348.2233 | C6: =IF(COUNTIFS(速報_原データ!$A$5:$A$200,$A6,速報_原データ!$B$5:$B$200,C$3)>0,SUMIFS(速報_原データ!$C$5:$C$200,速報_原データ!$A$5:$A$200,$A6,速報_原データ!$B$5:$B$200,C$3)/100,IF(COUNTIFS(速報_原データ!$A$5:$A$200,EDATE($A6,12),速報_原データ!$B$5:$B$200,C$3)>0,SUMIFS(速報_原データ!$C$5:$C$200,速報_原データ!$A$5:$A$200,EDATE($A6,12),速報_原データ!$B$5:$B$200,C$3)/100/(1+SUMIFS(速報_原データ!$D$5:$D$200,速報_原データ!$A$5:$A$200,EDATE($A6,12),速報_原データ!$B$5:$B$200,C$3)/100),IF(COUNTIFS(速報_原データ!$I$6:$I$9,EDATE($A6,12),速報_原データ!$J$6:$J$9,C$3)>0,C18/(1+SUMIFS(速報_原データ!$K$6:$K$9,速報_原データ!$I$6:$I$9,EDATE($A6,12),速報_原データ!$J$6:$J$9,C$3)/100),AVERAGE(C5,C7)))) -> 1897.3356 | D6: =IF(COUNTIFS(速報_原データ!$A$5:$A$200,$A6,速報_原データ!$B$5:$B$200,D$3)>0,SUMIFS(速報_原データ!$C$5:$C$200,速報_原データ!$A$5:$A$200,$A6,速報_原データ!$B$5:$B$200,D$3)/100,IF(COUNTIFS(速報_原データ!$A$5:$A$200,EDATE($A6,12),速報_原データ!$B$5:$B$200,D$3)>0,SUMIFS(速報_原データ!$C$5:$C$200,速報_原データ!$A$5:$A$200,EDATE($A6,12),速報_原データ!$B$5:$B$200,D$3)/100/(1+SUMIFS(速報_原データ!$D$5:$D$200,速報_原データ!$A$5:$A$200,EDATE($A6,12),速報_原データ!$B$5:$B$200,D$3)/100),IF(COUNTIFS(速報_原データ!$I$6:$I$9,EDATE($A6,12),速報_原データ!$J$6:$J$9,D$3)>0,D18/(1+SUMIFS(速報_原データ!$K$6:$K$9,速報_原データ!$I$6:$I$9,EDATE($A6,12),速報_原データ!$J$6:$J$9,D$3)/100),AVERAGE(D5,D7)))) -> 816.893 | E6: =IF(COUNTIFS(速報_原データ!$A$5:$A$200,$A6,速報_原データ!$B$5:$B$200,E$3)>0,SUMIFS(速報_原データ!$C$5:$C$200,速報_原データ!$A$5:$A$200,$A6,速報_原データ!$B$5:$B$200,E$3)/100,IF(COUNTIFS(速報_原データ!$A$5:$A$200,EDATE($A6,12),速報_原データ!$B$5:$B$200,E$3)>0,SUMIFS(速報_原データ!$C$5:$C$200,速報_原データ!$A$5:$A$200,EDATE($A6,12),速報_原データ!$B$5:$B$200,E$3)/100/(1+SUMIFS(速報_原データ!$D$5:$D$200,速報_原データ!$A$5:$A$200,EDATE($A6,12),速報_原データ!$B$5:$B$200,E$3)/100),IF(COUNTIFS(速報_原データ!$I$6:$I$9,EDATE($A6,12),速報_原データ!$J$6:$J$9,E$3)>0,E18/(1+SUMIFS(速報_原データ!$K$6:$K$9,速報_原データ!$I$6:$I$9,EDATE($A6,12),速報_原データ!$J$6:$J$9,E$3)/100),AVERAGE(E5,E7)))) -> 478.86638 | F6: =IF(COUNTIFS(速報_原データ!$A$5:$A$200,$A6,速報_原データ!$B$5:$B$200,F$3)>0,SUMIFS(速報_原データ!$C$5:$C$200,速報_原データ!$A$5:$A$200,$A6,速報_原データ!$B$5:$B$200,F$3)/100,IF(COUNTIFS(速報_原データ!$A$5:$A$200,EDATE($A6,12),速報_原データ!$B$5:$B$200,F$3)>0,SUMIFS(速報_原データ!$C$5:$C$200,速報_原データ!$A$5:$A$200,EDATE($A6,12),速報_原データ!$B$5:$B$200,F$3)/100/(1+SUMIFS(速報_原データ!$D$5:$D$200,速報_原データ!$A$5:$A$200,EDATE($A6,12),速報_原データ!$B$5:$B$200,F$3)/100),IF(COUNTIFS(速報_原データ!$I$6:$I$9,EDATE($A6,12),速報_原データ!$J$6:$J$9,F$3)>0,F18/(1+SUMIFS(速報_原データ!$K$6:$K$9,速報_原データ!$I$6:$I$9,EDATE($A6,12),速報_原データ!$J$6:$J$9,F$3)/100),AVERAGE(F5,F7)))) -> 165.80106 | G6: =IF(COUNTIFS(速報_原データ!$A$5:$A$200,$A6,速報_原データ!$B$5:$B$200,G$3)>0,SUMIFS(速報_原データ!$C$5:$C$200,速報_原データ!$A$5:$A$200,$A6,速報_原データ!$B$5:$B$200,G$3)/100,IF(COUNTIFS(速報_原データ!$A$5:$A$200,EDATE($A6,12),速報_原データ!$B$5:$B$200,G$3)>0,SUMIFS(速報_原データ!$C$5:$C$200,速報_原データ!$A$5:$A$200,EDATE($A6,12),速報_原データ!$B$5:$B$200,G$3)/100/(1+SUMIFS(速報_原データ!$D$5:$D$200,速報_原データ!$A$5:$A$200,EDATE($A6,12),速報_原データ!$B$5:$B$200,G$3)/100),IF(COUNTIFS(速報_原データ!$I$6:$I$9,EDATE($A6,12),速報_原データ!$J$6:$J$9,G$3)>0,G18/(1+SUMIFS(速報_原データ!$K$6:$K$9,速報_原データ!$I$6:$I$9,EDATE($A6,12),速報_原データ!$J$6:$J$9,G$3)/100),AVERAGE(G5,G7)))) -> 212.18034 | H6: =IF(COUNTIFS(速報_原データ!$A$5:$A$200,$A6,速報_原データ!$B$5:$B$200,H$3)>0,SUMIFS(速報_原データ!$C$5:$C$200,速報_原データ!$A$5:$A$200,$A6,速報_原データ!$B$5:$B$200,H$3)/100,IF(COUNTIFS(速報_原データ!$A$5:$A$200,EDATE($A6,12),速報_原データ!$B$5:$B$200,H$3)>0,SUMIFS(速報_原データ!$C$5:$C$200,速報_原データ!$A$5:$A$200,EDATE($A6,12),速報_原データ!$B$5:$B$200,H$3)/100/(1+SUMIFS(速報_原データ!$D$5:$D$200,速報_原データ!$A$5:$A$200,EDATE($A6,12),速報_原データ!$B$5:$B$200,H$3)/100),IF(COUNTIFS(速報_原データ!$I$6:$I$9,EDATE($A6,12),速報_原データ!$J$6:$J$9,H$3)>0,H18/(1+SUMIFS(速報_原データ!$K$6:$K$9,速報_原データ!$I$6:$I$9,EDATE($A6,12),速報_原データ!$J$6:$J$9,H$3)/100),AVERAGE(H5,H7)))) -> 139.83034 | I6: =B6-D6 -> 1531.3303 | J6: =C6-D6-E6-H6 -> 461.74586 | K6: 2段逆算（韓国・ASEAN・EUは補間）
A7: 45078 | B7: =IF(COUNTIFS(速報_原データ!$A$5:$A$200,$A7,速報_原データ!$B$5:$B$200,B$3)>0,SUMIFS(速報_原データ!$C$5:$C$200,速報_原データ!$A$5:$A$200,$A7,速報_原データ!$B$5:$B$200,B$3)/100,IF(COUNTIFS(速報_原データ!$A$5:$A$200,EDATE($A7,12),速報_原データ!$B$5:$B$200,B$3)>0,SUMIFS(速報_原データ!$C$5:$C$200,速報_原データ!$A$5:$A$200,EDATE($A7,12),速報_原データ!$B$5:$B$200,B$3)/100/(1+SUMIFS(速報_原データ!$D$5:$D$200,速報_原データ!$A$5:$A$200,EDATE($A7,12),速報_原データ!$B$5:$B$200,B$3)/100),IF(COUNTIFS(速報_原データ!$I$6:$I$9,EDATE($A7,12),速報_原データ!$J$6:$J$9,B$3)>0,B19/(1+SUMIFS(速報_原データ!$K$6:$K$9,速報_原データ!$I$6:$I$9,EDATE($A7,12),速報_原データ!$J$6:$J$9,B$3)/100),AVERAGE(B6,B8)))) -> 2880.1015 | C7: =IF(COUNTIFS(速報_原データ!$A$5:$A$200,$A7,速報_原データ!$B$5:$B$200,C$3)>0,SUMIFS(速報_原データ!$C$5:$C$200,速報_原データ!$A$5:$A$200,$A7,速報_原データ!$B$5:$B$200,C$3)/100,IF(COUNTIFS(速報_原データ!$A$5:$A$200,EDATE($A7,12),速報_原データ!$B$5:$B$200,C$3)>0,SUMIFS(速報_原データ!$C$5:$C$200,速報_原データ!$A$5:$A$200,EDATE($A7,12),速報_原データ!$B$5:$B$200,C$3)/100/(1+SUMIFS(速報_原データ!$D$5:$D$200,速報_原データ!$A$5:$A$200,EDATE($A7,12),速報_原データ!$B$5:$B$200,C$3)/100),IF(COUNTIFS(速報_原データ!$I$6:$I$9,EDATE($A7,12),速報_原データ!$J$6:$J$9,C$3)>0,C19/(1+SUMIFS(速報_原データ!$K$6:$K$9,速報_原データ!$I$6:$I$9,EDATE($A7,12),速報_原データ!$J$6:$J$9,C$3)/100),AVERAGE(C6,C8)))) -> 2366.767 | D7: =IF(COUNTIFS(速報_原データ!$A$5:$A$200,$A7,速報_原データ!$B$5:$B$200,D$3)>0,SUMIFS(速報_原データ!$C$5:$C$200,速報_原データ!$A$5:$A$200,$A7,速報_原データ!$B$5:$B$200,D$3)/100,IF(COUNTIFS(速報_原データ!$A$5:$A$200,EDATE($A7,12),速報_原データ!$B$5:$B$200,D$3)>0,SUMIFS(速報_原データ!$C$5:$C$200,速報_原データ!$A$5:$A$200,EDATE($A7,12),速報_原データ!$B$5:$B$200,D$3)/100/(1+SUMIFS(速報_原データ!$D$5:$D$200,速報_原データ!$A$5:$A$200,EDATE($A7,12),速報_原データ!$B$5:$B$200,D$3)/100),IF(COUNTIFS(速報_原データ!$I$6:$I$9,EDATE($A7,12),速報_原データ!$J$6:$J$9,D$3)>0,D19/(1+SUMIFS(速報_原データ!$K$6:$K$9,速報_原データ!$I$6:$I$9,EDATE($A7,12),速報_原データ!$J$6:$J$9,D$3)/100),AVERAGE(D6,D8)))) -> 1303.8863 | E7: =IF(COUNTIFS(速報_原データ!$A$5:$A$200,$A7,速報_原データ!$B$5:$B$200,E$3)>0,SUMIFS(速報_原データ!$C$5:$C$200,速報_原データ!$A$5:$A$200,$A7,速報_原データ!$B$5:$B$200,E$3)/100,IF(COUNTIFS(速報_原データ!$A$5:$A$200,EDATE($A7,12),速報_原データ!$B$5:$B$200,E$3)>0,SUMIFS(速報_原データ!$C$5:$C$200,速報_原データ!$A$5:$A$200,EDATE($A7,12),速報_原データ!$B$5:$B$200,E$3)/100/(1+SUMIFS(速報_原データ!$D$5:$D$200,速報_原データ!$A$5:$A$200,EDATE($A7,12),速報_原データ!$B$5:$B$200,E$3)/100),IF(COUNTIFS(速報_原データ!$I$6:$I$9,EDATE($A7,12),速報_原データ!$J$6:$J$9,E$3)>0,E19/(1+SUMIFS(速報_原データ!$K$6:$K$9,速報_原データ!$I$6:$I$9,EDATE($A7,12),速報_原データ!$J$6:$J$9,E$3)/100),AVERAGE(E6,E8)))) -> 505.10223 | F7: =IF(COUNTIFS(速報_原データ!$A$5:$A$200,$A7,速報_原データ!$B$5:$B$200,F$3)>0,SUMIFS(速報_原データ!$C$5:$C$200,速報_原データ!$A$5:$A$200,$A7,速報_原データ!$B$5:$B$200,F$3)/100,IF(COUNTIFS(速報_原データ!$A$5:$A$200,EDATE($A7,12),速報_原データ!$B$5:$B$200,F$3)>0,SUMIFS(速報_原データ!$C$5:$C$200,速報_原データ!$A$5:$A$200,EDATE($A7,12),速報_原データ!$B$5:$B$200,F$3)/100/(1+SUMIFS(速報_原データ!$D$5:$D$200,速報_原データ!$A$5:$A$200,EDATE($A7,12),速報_原データ!$B$5:$B$200,F$3)/100),IF(COUNTIFS(速報_原データ!$I$6:$I$9,EDATE($A7,12),速報_原データ!$J$6:$J$9,F$3)>0,F19/(1+SUMIFS(速報_原データ!$K$6:$K$9,速報_原データ!$I$6:$I$9,EDATE($A7,12),速報_原データ!$J$6:$J$9,F$3)/100),AVERAGE(F6,F8)))) -> 302.91035 | G7: =IF(COUNTIFS(速報_原データ!$A$5:$A$200,$A7,速報_原データ!$B$5:$B$200,G$3)>0,SUMIFS(速報_原データ!$C$5:$C$200,速報_原データ!$A$5:$A$200,$A7,速報_原データ!$B$5:$B$200,G$3)/100,IF(COUNTIFS(速報_原データ!$A$5:$A$200,EDATE($A7,12),速報_原データ!$B$5:$B$200,G$3)>0,SUMIFS(速報_原データ!$C$5:$C$200,速報_原データ!$A$5:$A$200,EDATE($A7,12),速報_原データ!$B$5:$B$200,G$3)/100/(1+SUMIFS(速報_原データ!$D$5:$D$200,速報_原データ!$A$5:$A$200,EDATE($A7,12),速報_原データ!$B$5:$B$200,G$3)/100),IF(COUNTIFS(速報_原データ!$I$6:$I$9,EDATE($A7,12),速報_原データ!$J$6:$J$9,G$3)>0,G19/(1+SUMIFS(速報_原データ!$K$6:$K$9,速報_原データ!$I$6:$I$9,EDATE($A7,12),速報_原データ!$J$6:$J$9,G$3)/100),AVERAGE(G6,G8)))) -> 203.09942 | H7: =IF(COUNTIFS(速報_原データ!$A$5:$A$200,$A7,速報_原データ!$B$5:$B$200,H$3)>0,SUMIFS(速報_原データ!$C$5:$C$200,速報_原データ!$A$5:$A$200,$A7,速報_原データ!$B$5:$B$200,H$3)/100,IF(COUNTIFS(速報_原データ!$A$5:$A$200,EDATE($A7,12),速報_原データ!$B$5:$B$200,H$3)>0,SUMIFS(速報_原データ!$C$5:$C$200,速報_原データ!$A$5:$A$200,EDATE($A7,12),速報_原データ!$B$5:$B$200,H$3)/100/(1+SUMIFS(速報_原データ!$D$5:$D$200,速報_原データ!$A$5:$A$200,EDATE($A7,12),速報_原データ!$B$5:$B$200,H$3)/100),IF(COUNTIFS(速報_原データ!$I$6:$I$9,EDATE($A7,12),速報_原データ!$J$6:$J$9,H$3)>0,H19/(1+SUMIFS(速報_原データ!$K$6:$K$9,速報_原データ!$I$6:$I$9,EDATE($A7,12),速報_原データ!$J$6:$J$9,H$3)/100),AVERAGE(H6,H8)))) -> 141.96837 | I7: =B7-D7 -> 1576.2153 | J7: =C7-D7-E7-H7 -> 415.81012 | K7: 翌年同月速報の前年比から逆算
A8: 45108 | B8: =IF(COUNTIFS(速報_原データ!$A$5:$A$200,$A8,速報_原データ!$B$5:$B$200,B$3)>0,SUMIFS(速報_原データ!$C$5:$C$200,速報_原データ!$A$5:$A$200,$A8,速報_原データ!$B$5:$B$200,B$3)/100,IF(COUNTIFS(速報_原データ!$A$5:$A$200,EDATE($A8,12),速報_原データ!$B$5:$B$200,B$3)>0,SUMIFS(速報_原データ!$C$5:$C$200,速報_原データ!$A$5:$A$200,EDATE($A8,12),速報_原データ!$B$5:$B$200,B$3)/100/(1+SUMIFS(速報_原データ!$D$5:$D$200,速報_原データ!$A$5:$A$200,EDATE($A8,12),速報_原データ!$B$5:$B$200,B$3)/100),IF(COUNTIFS(速報_原データ!$I$6:$I$9,EDATE($A8,12),速報_原データ!$J$6:$J$9,B$3)>0,B20/(1+SUMIFS(速報_原データ!$K$6:$K$9,速報_原データ!$I$6:$I$9,EDATE($A8,12),速報_原データ!$J$6:$J$9,B$3)/100),AVERAGE(B7,B9)))) -> 2883.7559 | C8: =IF(COUNTIFS(速報_原データ!$A$5:$A$200,$A8,速報_原データ!$B$5:$B$200,C$3)>0,SUMIFS(速報_原データ!$C$5:$C$200,速報_原データ!$A$5:$A$200,$A8,速報_原データ!$B$5:$B$200,C$3)/100,IF(COUNTIFS(速報_原データ!$A$5:$A$200,EDATE($A8,12),速報_原データ!$B$5:$B$200,C$3)>0,SUMIFS(速報_原データ!$C$5:$C$200,速報_原データ!$A$5:$A$200,EDATE($A8,12),速報_原データ!$B$5:$B$200,C$3)/100/(1+SUMIFS(速報_原データ!$D$5:$D$200,速報_原データ!$A$5:$A$200,EDATE($A8,12),速報_原データ!$B$5:$B$200,C$3)/100),IF(COUNTIFS(速報_原データ!$I$6:$I$9,EDATE($A8,12),速報_原データ!$J$6:$J$9,C$3)>0,C20/(1+SUMIFS(速報_原データ!$K$6:$K$9,速報_原データ!$I$6:$I$9,EDATE($A8,12),速報_原データ!$J$6:$J$9,C$3)/100),AVERAGE(C7,C9)))) -> 2369.6305 | D8: =IF(COUNTIFS(速報_原データ!$A$5:$A$200,$A8,速報_原データ!$B$5:$B$200,D$3)>0,SUMIFS(速報_原データ!$C$5:$C$200,速報_原データ!$A$5:$A$200,$A8,速報_原データ!$B$5:$B$200,D$3)/100,IF(COUNTIFS(速報_原データ!$A$5:$A$200,EDATE($A8,12),速報_原データ!$B$5:$B$200,D$3)>0,SUMIFS(速報_原データ!$C$5:$C$200,速報_原データ!$A$5:$A$200,EDATE($A8,12),速報_原データ!$B$5:$B$200,D$3)/100/(1+SUMIFS(速報_原データ!$D$5:$D$200,速報_原データ!$A$5:$A$200,EDATE($A8,12),速報_原データ!$B$5:$B$200,D$3)/100),IF(COUNTIFS(速報_原データ!$I$6:$I$9,EDATE($A8,12),速報_原データ!$J$6:$J$9,D$3)>0,D20/(1+SUMIFS(速報_原データ!$K$6:$K$9,速報_原データ!$I$6:$I$9,EDATE($A8,12),速報_原データ!$J$6:$J$9,D$3)/100),AVERAGE(D7,D9)))) -> 1405.3002 | E8: =IF(COUNTIFS(速報_原データ!$A$5:$A$200,$A8,速報_原データ!$B$5:$B$200,E$3)>0,SUMIFS(速報_原データ!$C$5:$C$200,速報_原データ!$A$5:$A$200,$A8,速報_原データ!$B$5:$B$200,E$3)/100,IF(COUNTIFS(速報_原データ!$A$5:$A$200,EDATE($A8,12),速報_原データ!$B$5:$B$200,E$3)>0,SUMIFS(速報_原データ!$C$5:$C$200,速報_原データ!$A$5:$A$200,EDATE($A8,12),速報_原データ!$B$5:$B$200,E$3)/100/(1+SUMIFS(速報_原データ!$D$5:$D$200,速報_原データ!$A$5:$A$200,EDATE($A8,12),速報_原データ!$B$5:$B$200,E$3)/100),IF(COUNTIFS(速報_原データ!$I$6:$I$9,EDATE($A8,12),速報_原データ!$J$6:$J$9,E$3)>0,E20/(1+SUMIFS(速報_原データ!$K$6:$K$9,速報_原データ!$I$6:$I$9,EDATE($A8,12),速報_原データ!$J$6:$J$9,E$3)/100),AVERAGE(E7,E9)))) -> 440.55938 | F8: =IF(COUNTIFS(速報_原データ!$A$5:$A$200,$A8,速報_原データ!$B$5:$B$200,F$3)>0,SUMIFS(速報_原データ!$C$5:$C$200,速報_原データ!$A$5:$A$200,$A8,速報_原データ!$B$5:$B$200,F$3)/100,IF(COUNTIFS(速報_原データ!$A$5:$A$200,EDATE($A8,12),速報_原データ!$B$5:$B$200,F$3)>0,SUMIFS(速報_原データ!$C$5:$C$200,速報_原データ!$A$5:$A$200,EDATE($A8,12),速報_原データ!$B$5:$B$200,F$3)/100/(1+SUMIFS(速報_原データ!$D$5:$D$200,速報_原データ!$A$5:$A$200,EDATE($A8,12),速報_原データ!$B$5:$B$200,F$3)/100),IF(COUNTIFS(速報_原データ!$I$6:$I$9,EDATE($A8,12),速報_原データ!$J$6:$J$9,F$3)>0,F20/(1+SUMIFS(速報_原データ!$K$6:$K$9,速報_原データ!$I$6:$I$9,EDATE($A8,12),速報_原データ!$J$6:$J$9,F$3)/100),AVERAGE(F7,F9)))) -> 336.11621 | G8: =IF(COUNTIFS(速報_原データ!$A$5:$A$200,$A8,速報_原データ!$B$5:$B$200,G$3)>0,SUMIFS(速報_原データ!$C$5:$C$200,速報_原データ!$A$5:$A$200,$A8,速報_原データ!$B$5:$B$200,G$3)/100,IF(COUNTIFS(速報_原データ!$A$5:$A$200,EDATE($A8,12),速報_原データ!$B$5:$B$200,G$3)>0,SUMIFS(速報_原データ!$C$5:$C$200,速報_原データ!$A$5:$A$200,EDATE($A8,12),速報_原データ!$B$5:$B$200,G$3)/100/(1+SUMIFS(速報_原データ!$D$5:$D$200,速報_原データ!$A$5:$A$200,EDATE($A8,12),速報_原データ!$B$5:$B$200,G$3)/100),IF(COUNTIFS(速報_原データ!$I$6:$I$9,EDATE($A8,12),速報_原データ!$J$6:$J$9,G$3)>0,G20/(1+SUMIFS(速報_原データ!$K$6:$K$9,速報_原データ!$I$6:$I$9,EDATE($A8,12),速報_原データ!$J$6:$J$9,G$3)/100),AVERAGE(G7,G9)))) -> 172.55403 | H8: =IF(COUNTIFS(速報_原データ!$A$5:$A$200,$A8,速報_原データ!$B$5:$B$200,H$3)>0,SUMIFS(速報_原データ!$C$5:$C$200,速報_原データ!$A$5:$A$200,$A8,速報_原データ!$B$5:$B$200,H$3)/100,IF(COUNTIFS(速報_原データ!$A$5:$A$200,EDATE($A8,12),速報_原データ!$B$5:$B$200,H$3)>0,SUMIFS(速報_原データ!$C$5:$C$200,速報_原データ!$A$5:$A$200,EDATE($A8,12),速報_原データ!$B$5:$B$200,H$3)/100/(1+SUMIFS(速報_原データ!$D$5:$D$200,速報_原データ!$A$5:$A$200,EDATE($A8,12),速報_原データ!$B$5:$B$200,H$3)/100),IF(COUNTIFS(速報_原データ!$I$6:$I$9,EDATE($A8,12),速報_原データ!$J$6:$J$9,H$3)>0,H20/(1+SUMIFS(速報_原データ!$K$6:$K$9,速報_原データ!$I$6:$I$9,EDATE($A8,12),速報_原データ!$J$6:$J$9,H$3)/100),AVERAGE(H7,H9)))) -> 145.98227 | I8: =B8-D8 -> 1478.4557 | J8: =C8-D8-E8-H8 -> 377.78864 | K8: 翌年同月速報の前年比から逆算
A9: 45139 | B9: =IF(COUNTIFS(速報_原データ!$A$5:$A$200,$A9,速報_原データ!$B$5:$B$200,B$3)>0,SUMIFS(速報_原データ!$C$5:$C$200,速報_原データ!$A$5:$A$200,$A9,速報_原データ!$B$5:$B$200,B$3)/100,IF(COUNTIFS(速報_原データ!$A$5:$A$200,EDATE($A9,12),速報_原データ!$B$5:$B$200,B$3)>0,SUMIFS(速報_原データ!$C$5:$C$200,速報_原データ!$A$5:$A$200,EDATE($A9,12),速報_原データ!$B$5:$B$200,B$3)/100/(1+SUMIFS(速報_原データ!$D$5:$D$200,速報_原データ!$A$5:$A$200,EDATE($A9,12),速報_原データ!$B$5:$B$200,B$3)/100),IF(COUNTIFS(速報_原データ!$I$6:$I$9,EDATE($A9,12),速報_原データ!$J$6:$J$9,B$3)>0,B21/(1+SUMIFS(速報_原データ!$K$6:$K$9,速報_原データ!$I$6:$I$9,EDATE($A9,12),速報_原データ!$J$6:$J$9,B$3)/100),AVERAGE(B8,B10)))) -> 2209.5619 | C9: =IF(COUNTIFS(速報_原データ!$A$5:$A$200,$A9,速報_原データ!$B$5:$B$200,C$3)>0,SUMIFS(速報_原データ!$C$5:$C$200,速報_原データ!$A$5:$A$200,$A9,速報_原データ!$B$5:$B$200,C$3)/100,IF(COUNTIFS(速報_原データ!$A$5:$A$200,EDATE($A9,12),速報_原データ!$B$5:$B$200,C$3)>0,SUMIFS(速報_原データ!$C$5:$C$200,速報_原データ!$A$5:$A$200,EDATE($A9,12),速報_原データ!$B$5:$B$200,C$3)/100/(1+SUMIFS(速報_原データ!$D$5:$D$200,速報_原データ!$A$5:$A$200,EDATE($A9,12),速報_原データ!$B$5:$B$200,C$3)/100),IF(COUNTIFS(速報_原データ!$I$6:$I$9,EDATE($A9,12),速報_原データ!$J$6:$J$9,C$3)>0,C21/(1+SUMIFS(速報_原データ!$K$6:$K$9,速報_原データ!$I$6:$I$9,EDATE($A9,12),速報_原データ!$J$6:$J$9,C$3)/100),AVERAGE(C8,C10)))) -> 1788.133 | D9: =IF(COUNTIFS(速報_原データ!$A$5:$A$200,$A9,速報_原データ!$B$5:$B$200,D$3)>0,SUMIFS(速報_原データ!$C$5:$C$200,速報_原データ!$A$5:$A$200,$A9,速報_原データ!$B$5:$B$200,D$3)/100,IF(COUNTIFS(速報_原データ!$A$5:$A$200,EDATE($A9,12),速報_原データ!$B$5:$B$200,D$3)>0,SUMIFS(速報_原データ!$C$5:$C$200,速報_原データ!$A$5:$A$200,EDATE($A9,12),速報_原データ!$B$5:$B$200,D$3)/100/(1+SUMIFS(速報_原データ!$D$5:$D$200,速報_原データ!$A$5:$A$200,EDATE($A9,12),速報_原データ!$B$5:$B$200,D$3)/100),IF(COUNTIFS(速報_原データ!$I$6:$I$9,EDATE($A9,12),速報_原データ!$J$6:$J$9,D$3)>0,D21/(1+SUMIFS(速報_原データ!$K$6:$K$9,速報_原データ!$I$6:$I$9,EDATE($A9,12),速報_原データ!$J$6:$J$9,D$3)/100),AVERAGE(D8,D10)))) -> 1113.4097 | E9: =IF(COUNTIFS(速報_原データ!$A$5:$A$200,$A9,速報_原データ!$B$5:$B$200,E$3)>0,SUMIFS(速報_原データ!$C$5:$C$200,速報_原データ!$A$5:$A$200,$A9,速報_原データ!$B$5:$B$200,E$3)/100,IF(COUNTIFS(速報_原データ!$A$5:$A$200,EDATE($A9,12),速報_原データ!$B$5:$B$200,E$3)>0,SUMIFS(速報_原データ!$C$5:$C$200,速報_原データ!$A$5:$A$200,EDATE($A9,12),速報_原データ!$B$5:$B$200,E$3)/100/(1+SUMIFS(速報_原データ!$D$5:$D$200,速報_原データ!$A$5:$A$200,EDATE($A9,12),速報_原データ!$B$5:$B$200,E$3)/100),IF(COUNTIFS(速報_原データ!$I$6:$I$9,EDATE($A9,12),速報_原データ!$J$6:$J$9,E$3)>0,E21/(1+SUMIFS(速報_原データ!$K$6:$K$9,速報_原データ!$I$6:$I$9,EDATE($A9,12),速報_原データ!$J$6:$J$9,E$3)/100),AVERAGE(E8,E10)))) -> 290.47249 | F9: =IF(COUNTIFS(速報_原データ!$A$5:$A$200,$A9,速報_原データ!$B$5:$B$200,F$3)>0,SUMIFS(速報_原データ!$C$5:$C$200,速報_原データ!$A$5:$A$200,$A9,速報_原データ!$B$5:$B$200,F$3)/100,IF(COUNTIFS(速報_原データ!$A$5:$A$200,EDATE($A9,12),速報_原データ!$B$5:$B$200,F$3)>0,SUMIFS(速報_原データ!$C$5:$C$200,速報_原データ!$A$5:$A$200,EDATE($A9,12),速報_原データ!$B$5:$B$200,F$3)/100/(1+SUMIFS(速報_原データ!$D$5:$D$200,速報_原データ!$A$5:$A$200,EDATE($A9,12),速報_原データ!$B$5:$B$200,F$3)/100),IF(COUNTIFS(速報_原データ!$I$6:$I$9,EDATE($A9,12),速報_原データ!$J$6:$J$9,F$3)>0,F21/(1+SUMIFS(速報_原データ!$K$6:$K$9,速報_原データ!$I$6:$I$9,EDATE($A9,12),速報_原データ!$J$6:$J$9,F$3)/100),AVERAGE(F8,F10)))) -> 263.91089 | G9: =IF(COUNTIFS(速報_原データ!$A$5:$A$200,$A9,速報_原データ!$B$5:$B$200,G$3)>0,SUMIFS(速報_原データ!$C$5:$C$200,速報_原データ!$A$5:$A$200,$A9,速報_原データ!$B$5:$B$200,G$3)/100,IF(COUNTIFS(速報_原データ!$A$5:$A$200,EDATE($A9,12),速報_原データ!$B$5:$B$200,G$3)>0,SUMIFS(速報_原データ!$C$5:$C$200,速報_原データ!$A$5:$A$200,EDATE($A9,12),速報_原データ!$B$5:$B$200,G$3)/100/(1+SUMIFS(速報_原データ!$D$5:$D$200,速報_原データ!$A$5:$A$200,EDATE($A9,12),速報_原データ!$B$5:$B$200,G$3)/100),IF(COUNTIFS(速報_原データ!$I$6:$I$9,EDATE($A9,12),速報_原データ!$J$6:$J$9,G$3)>0,G21/(1+SUMIFS(速報_原データ!$K$6:$K$9,速報_原データ!$I$6:$I$9,EDATE($A9,12),速報_原データ!$J$6:$J$9,G$3)/100),AVERAGE(G8,G10)))) -> 139.9759 | H9: =IF(COUNTIFS(速報_原データ!$A$5:$A$200,$A9,速報_原データ!$B$5:$B$200,H$3)>0,SUMIFS(速報_原データ!$C$5:$C$200,速報_原データ!$A$5:$A$200,$A9,速報_原データ!$B$5:$B$200,H$3)/100,IF(COUNTIFS(速報_原データ!$A$5:$A$200,EDATE($A9,12),速報_原データ!$B$5:$B$200,H$3)>0,SUMIFS(速報_原データ!$C$5:$C$200,速報_原データ!$A$5:$A$200,EDATE($A9,12),速報_原データ!$B$5:$B$200,H$3)/100/(1+SUMIFS(速報_原データ!$D$5:$D$200,速報_原データ!$A$5:$A$200,EDATE($A9,12),速報_原データ!$B$5:$B$200,H$3)/100),IF(COUNTIFS(速報_原データ!$I$6:$I$9,EDATE($A9,12),速報_原データ!$J$6:$J$9,H$3)>0,H21/(1+SUMIFS(速報_原データ!$K$6:$K$9,速報_原データ!$I$6:$I$9,EDATE($A9,12),速報_原データ!$J$6:$J$9,H$3)/100),AVERAGE(H8,H10)))) -> 139.41216 | I9: =B9-D9 -> 1096.1522 | J9: =C9-D9-E9-H9 -> 244.8387 | K9: 翌年同月速報の前年比から逆算
A10: 45170 | B10: =IF(COUNTIFS(速報_原データ!$A$5:$A$200,$A10,速報_原データ!$B$5:$B$200,B$3)>0,SUMIFS(速報_原データ!$C$5:$C$200,速報_原データ!$A$5:$A$200,$A10,速報_原データ!$B$5:$B$200,B$3)/100,IF(COUNTIFS(速報_原データ!$A$5:$A$200,EDATE($A10,12),速報_原データ!$B$5:$B$200,B$3)>0,SUMIFS(速報_原データ!$C$5:$C$200,速報_原データ!$A$5:$A$200,EDATE($A10,12),速報_原データ!$B$5:$B$200,B$3)/100/(1+SUMIFS(速報_原データ!$D$5:$D$200,速報_原データ!$A$5:$A$200,EDATE($A10,12),速報_原データ!$B$5:$B$200,B$3)/100),IF(COUNTIFS(速報_原データ!$I$6:$I$9,EDATE($A10,12),速報_原データ!$J$6:$J$9,B$3)>0,B22/(1+SUMIFS(速報_原データ!$K$6:$K$9,速報_原データ!$I$6:$I$9,EDATE($A10,12),速報_原データ!$J$6:$J$9,B$3)/100),AVERAGE(B9,B11)))) -> 3143.5234 | C10: =IF(COUNTIFS(速報_原データ!$A$5:$A$200,$A10,速報_原データ!$B$5:$B$200,C$3)>0,SUMIFS(速報_原データ!$C$5:$C$200,速報_原データ!$A$5:$A$200,$A10,速報_原データ!$B$5:$B$200,C$3)/100,IF(COUNTIFS(速報_原データ!$A$5:$A$200,EDATE($A10,12),速報_原データ!$B$5:$B$200,C$3)>0,SUMIFS(速報_原データ!$C$5:$C$200,速報_原データ!$A$5:$A$200,EDATE($A10,12),速報_原データ!$B$5:$B$200,C$3)/100/(1+SUMIFS(速報_原データ!$D$5:$D$200,速報_原データ!$A$5:$A$200,EDATE($A10,12),速報_原データ!$B$5:$B$200,C$3)/100),IF(COUNTIFS(速報_原データ!$I$6:$I$9,EDATE($A10,12),速報_原データ!$J$6:$J$9,C$3)>0,C22/(1+SUMIFS(速報_原データ!$K$6:$K$9,速報_原データ!$I$6:$I$9,EDATE($A10,12),速報_原データ!$J$6:$J$9,C$3)/100),AVERAGE(C9,C11)))) -> 2634.847 | D10: =IF(COUNTIFS(速報_原データ!$A$5:$A$200,$A10,速報_原データ!$B$5:$B$200,D$3)>0,SUMIFS(速報_原データ!$C$5:$C$200,速報_原データ!$A$5:$A$200,$A10,速報_原データ!$B$5:$B$200,D$3)/100,IF(COUNTIFS(速報_原データ!$A$5:$A$200,EDATE($A10,12),速報_原データ!$B$5:$B$200,D$3)>0,SUMIFS(速報_原データ!$C$5:$C$200,速報_原データ!$A$5:$A$200,EDATE($A10,12),速報_原データ!$B$5:$B$200,D$3)/100/(1+SUMIFS(速報_原データ!$D$5:$D$200,速報_原データ!$A$5:$A$200,EDATE($A10,12),速報_原データ!$B$5:$B$200,D$3)/100),IF(COUNTIFS(速報_原データ!$I$6:$I$9,EDATE($A10,12),速報_原データ!$J$6:$J$9,D$3)>0,D22/(1+SUMIFS(速報_原データ!$K$6:$K$9,速報_原データ!$I$6:$I$9,EDATE($A10,12),速報_原データ!$J$6:$J$9,D$3)/100),AVERAGE(D9,D11)))) -> 1666.7038 | E10: =IF(COUNTIFS(速報_原データ!$A$5:$A$200,$A10,速報_原データ!$B$5:$B$200,E$3)>0,SUMIFS(速報_原データ!$C$5:$C$200,速報_原データ!$A$5:$A$200,$A10,速報_原データ!$B$5:$B$200,E$3)/100,IF(COUNTIFS(速報_原データ!$A$5:$A$200,EDATE($A10,12),速報_原データ!$B$5:$B$200,E$3)>0,SUMIFS(速報_原データ!$C$5:$C$200,速報_原データ!$A$5:$A$200,EDATE($A10,12),速報_原データ!$B$5:$B$200,E$3)/100/(1+SUMIFS(速報_原データ!$D$5:$D$200,速報_原データ!$A$5:$A$200,EDATE($A10,12),速報_原データ!$B$5:$B$200,E$3)/100),IF(COUNTIFS(速報_原データ!$I$6:$I$9,EDATE($A10,12),速報_原データ!$J$6:$J$9,E$3)>0,E22/(1+SUMIFS(速報_原データ!$K$6:$K$9,速報_原データ!$I$6:$I$9,EDATE($A10,12),速報_原データ!$J$6:$J$9,E$3)/100),AVERAGE(E9,E11)))) -> 446.48097 | F10: =IF(COUNTIFS(速報_原データ!$A$5:$A$200,$A10,速報_原データ!$B$5:$B$200,F$3)>0,SUMIFS(速報_原データ!$C$5:$C$200,速報_原データ!$A$5:$A$200,$A10,速報_原データ!$B$5:$B$200,F$3)/100,IF(COUNTIFS(速報_原データ!$A$5:$A$200,EDATE($A10,12),速報_原データ!$B$5:$B$200,F$3)>0,SUMIFS(速報_原データ!$C$5:$C$200,速報_原データ!$A$5:$A$200,EDATE($A10,12),速報_原データ!$B$5:$B$200,F$3)/100/(1+SUMIFS(速報_原データ!$D$5:$D$200,速報_原データ!$A$5:$A$200,EDATE($A10,12),速報_原データ!$B$5:$B$200,F$3)/100),IF(COUNTIFS(速報_原データ!$I$6:$I$9,EDATE($A10,12),速報_原データ!$J$6:$J$9,F$3)>0,F22/(1+SUMIFS(速報_原データ!$K$6:$K$9,速報_原データ!$I$6:$I$9,EDATE($A10,12),速報_原データ!$J$6:$J$9,F$3)/100),AVERAGE(F9,F11)))) -> 334.7851 | G10: =IF(COUNTIFS(速報_原データ!$A$5:$A$200,$A10,速報_原データ!$B$5:$B$200,G$3)>0,SUMIFS(速報_原データ!$C$5:$C$200,速報_原データ!$A$5:$A$200,$A10,速報_原データ!$B$5:$B$200,G$3)/100,IF(COUNTIFS(速報_原データ!$A$5:$A$200,EDATE($A10,12),速報_原データ!$B$5:$B$200,G$3)>0,SUMIFS(速報_原データ!$C$5:$C$200,速報_原データ!$A$5:$A$200,EDATE($A10,12),速報_原データ!$B$5:$B$200,G$3)/100/(1+SUMIFS(速報_原データ!$D$5:$D$200,速報_原データ!$A$5:$A$200,EDATE($A10,12),速報_原データ!$B$5:$B$200,G$3)/100),IF(COUNTIFS(速報_原データ!$I$6:$I$9,EDATE($A10,12),速報_原データ!$J$6:$J$9,G$3)>0,G22/(1+SUMIFS(速報_原データ!$K$6:$K$9,速報_原データ!$I$6:$I$9,EDATE($A10,12),速報_原データ!$J$6:$J$9,G$3)/100),AVERAGE(G9,G11)))) -> 167.20395 | H10: =IF(COUNTIFS(速報_原データ!$A$5:$A$200,$A10,速報_原データ!$B$5:$B$200,H$3)>0,SUMIFS(速報_原データ!$C$5:$C$200,速報_原データ!$A$5:$A$200,$A10,速報_原データ!$B$5:$B$200,H$3)/100,IF(COUNTIFS(速報_原データ!$A$5:$A$200,EDATE($A10,12),速報_原データ!$B$5:$B$200,H$3)>0,SUMIFS(速報_原データ!$C$5:$C$200,速報_原データ!$A$5:$A$200,EDATE($A10,12),速報_原データ!$B$5:$B$200,H$3)/100/(1+SUMIFS(速報_原データ!$D$5:$D$200,速報_原データ!$A$5:$A$200,EDATE($A10,12),速報_原データ!$B$5:$B$200,H$3)/100),IF(COUNTIFS(速報_原データ!$I$6:$I$9,EDATE($A10,12),速報_原データ!$J$6:$J$9,H$3)>0,H22/(1+SUMIFS(速報_原データ!$K$6:$K$9,速報_原データ!$I$6:$I$9,EDATE($A10,12),速報_原データ!$J$6:$J$9,H$3)/100),AVERAGE(H9,H11)))) -> 174.63538 | I10: =B10-D10 -> 1476.8196 | J10: =C10-D10-E10-H10 -> 347.0269 | K10: 翌年同月速報の前年比から逆算
A11: 45200 | B11: =IF(COUNTIFS(速報_原データ!$A$5:$A$200,$A11,速報_原データ!$B$5:$B$200,B$3)>0,SUMIFS(速報_原データ!$C$5:$C$200,速報_原データ!$A$5:$A$200,$A11,速報_原データ!$B$5:$B$200,B$3)/100,IF(COUNTIFS(速報_原データ!$A$5:$A$200,EDATE($A11,12),速報_原データ!$B$5:$B$200,B$3)>0,SUMIFS(速報_原データ!$C$5:$C$200,速報_原データ!$A$5:$A$200,EDATE($A11,12),速報_原データ!$B$5:$B$200,B$3)/100/(1+SUMIFS(速報_原データ!$D$5:$D$200,速報_原データ!$A$5:$A$200,EDATE($A11,12),速報_原データ!$B$5:$B$200,B$3)/100),IF(COUNTIFS(速報_原データ!$I$6:$I$9,EDATE($A11,12),速報_原データ!$J$6:$J$9,B$3)>0,B23/(1+SUMIFS(速報_原データ!$K$6:$K$9,速報_原データ!$I$6:$I$9,EDATE($A11,12),速報_原データ!$J$6:$J$9,B$3)/100),AVERAGE(B10,B12)))) -> 2858.331 | C11: =IF(COUNTIFS(速報_原データ!$A$5:$A$200,$A11,速報_原データ!$B$5:$B$200,C$3)>0,SUMIFS(速報_原データ!$C$5:$C$200,速報_原データ!$A$5:$A$200,$A11,速報_原データ!$B$5:$B$200,C$3)/100,IF(COUNTIFS(速報_原データ!$A$5:$A$200,EDATE($A11,12),速報_原データ!$B$5:$B$200,C$3)>0,SUMIFS(速報_原データ!$C$5:$C$200,速報_原データ!$A$5:$A$200,EDATE($A11,12),速報_原データ!$B$5:$B$200,C$3)/100/(1+SUMIFS(速報_原データ!$D$5:$D$200,速報_原データ!$A$5:$A$200,EDATE($A11,12),速報_原データ!$B$5:$B$200,C$3)/100),IF(COUNTIFS(速報_原データ!$I$6:$I$9,EDATE($A11,12),速報_原データ!$J$6:$J$9,C$3)>0,C23/(1+SUMIFS(速報_原データ!$K$6:$K$9,速報_原データ!$I$6:$I$9,EDATE($A11,12),速報_原データ!$J$6:$J$9,C$3)/100),AVERAGE(C10,C12)))) -> 2188.3844 | D11: =IF(COUNTIFS(速報_原データ!$A$5:$A$200,$A11,速報_原データ!$B$5:$B$200,D$3)>0,SUMIFS(速報_原データ!$C$5:$C$200,速報_原データ!$A$5:$A$200,$A11,速報_原データ!$B$5:$B$200,D$3)/100,IF(COUNTIFS(速報_原データ!$A$5:$A$200,EDATE($A11,12),速報_原データ!$B$5:$B$200,D$3)>0,SUMIFS(速報_原データ!$C$5:$C$200,速報_原データ!$A$5:$A$200,EDATE($A11,12),速報_原データ!$B$5:$B$200,D$3)/100/(1+SUMIFS(速報_原データ!$D$5:$D$200,速報_原データ!$A$5:$A$200,EDATE($A11,12),速報_原データ!$B$5:$B$200,D$3)/100),IF(COUNTIFS(速報_原データ!$I$6:$I$9,EDATE($A11,12),速報_原データ!$J$6:$J$9,D$3)>0,D23/(1+SUMIFS(速報_原データ!$K$6:$K$9,速報_原データ!$I$6:$I$9,EDATE($A11,12),速報_原データ!$J$6:$J$9,D$3)/100),AVERAGE(D10,D12)))) -> 1379.6177 | E11: =IF(COUNTIFS(速報_原データ!$A$5:$A$200,$A11,速報_原データ!$B$5:$B$200,E$3)>0,SUMIFS(速報_原データ!$C$5:$C$200,速報_原データ!$A$5:$A$200,$A11,速報_原データ!$B$5:$B$200,E$3)/100,IF(COUNTIFS(速報_原データ!$A$5:$A$200,EDATE($A11,12),速報_原データ!$B$5:$B$200,E$3)>0,SUMIFS(速報_原データ!$C$5:$C$200,速報_原データ!$A$5:$A$200,EDATE($A11,12),速報_原データ!$B$5:$B$200,E$3)/100/(1+SUMIFS(速報_原データ!$D$5:$D$200,速報_原データ!$A$5:$A$200,EDATE($A11,12),速報_原データ!$B$5:$B$200,E$3)/100),IF(COUNTIFS(速報_原データ!$I$6:$I$9,EDATE($A11,12),速報_原データ!$J$6:$J$9,E$3)>0,E23/(1+SUMIFS(速報_原データ!$K$6:$K$9,速報_原データ!$I$6:$I$9,EDATE($A11,12),速報_原データ!$J$6:$J$9,E$3)/100),AVERAGE(E10,E12)))) -> 279.40784 | F11: =IF(COUNTIFS(速報_原データ!$A$5:$A$200,$A11,速報_原データ!$B$5:$B$200,F$3)>0,SUMIFS(速報_原データ!$C$5:$C$200,速報_原データ!$A$5:$A$200,$A11,速報_原データ!$B$5:$B$200,F$3)/100,IF(COUNTIFS(速報_原データ!$A$5:$A$200,EDATE($A11,12),速報_原データ!$B$5:$B$200,F$3)>0,SUMIFS(速報_原データ!$C$5:$C$200,速報_原データ!$A$5:$A$200,EDATE($A11,12),速報_原データ!$B$5:$B$200,F$3)/100/(1+SUMIFS(速報_原データ!$D$5:$D$200,速報_原データ!$A$5:$A$200,EDATE($A11,12),速報_原データ!$B$5:$B$200,F$3)/100),IF(COUNTIFS(速報_原データ!$I$6:$I$9,EDATE($A11,12),速報_原データ!$J$6:$J$9,F$3)>0,F23/(1+SUMIFS(速報_原データ!$K$6:$K$9,速報_原データ!$I$6:$I$9,EDATE($A11,12),速報_原データ!$J$6:$J$9,F$3)/100),AVERAGE(F10,F12)))) -> 499.86111 | G11: =IF(COUNTIFS(速報_原データ!$A$5:$A$200,$A11,速報_原データ!$B$5:$B$200,G$3)>0,SUMIFS(速報_原データ!$C$5:$C$200,速報_原データ!$A$5:$A$200,$A11,速報_原データ!$B$5:$B$200,G$3)/100,IF(COUNTIFS(速報_原データ!$A$5:$A$200,EDATE($A11,12),速報_原データ!$B$5:$B$200,G$3)>0,SUMIFS(速報_原データ!$C$5:$C$200,速報_原データ!$A$5:$A$200,EDATE($A11,12),速報_原データ!$B$5:$B$200,G$3)/100/(1+SUMIFS(速報_原データ!$D$5:$D$200,速報_原データ!$A$5:$A$200,EDATE($A11,12),速報_原データ!$B$5:$B$200,G$3)/100),IF(COUNTIFS(速報_原データ!$I$6:$I$9,EDATE($A11,12),速報_原データ!$J$6:$J$9,G$3)>0,G23/(1+SUMIFS(速報_原データ!$K$6:$K$9,速報_原データ!$I$6:$I$9,EDATE($A11,12),速報_原データ!$J$6:$J$9,G$3)/100),AVERAGE(G10,G12)))) -> 166.2169 | H11: =IF(COUNTIFS(速報_原データ!$A$5:$A$200,$A11,速報_原データ!$B$5:$B$200,H$3)>0,SUMIFS(速報_原データ!$C$5:$C$200,速報_原データ!$A$5:$A$200,$A11,速報_原データ!$B$5:$B$200,H$3)/100,IF(COUNTIFS(速報_原データ!$A$5:$A$200,EDATE($A11,12),速報_原データ!$B$5:$B$200,H$3)>0,SUMIFS(速報_原データ!$C$5:$C$200,速報_原データ!$A$5:$A$200,EDATE($A11,12),速報_原データ!$B$5:$B$200,H$3)/100/(1+SUMIFS(速報_原データ!$D$5:$D$200,速報_原データ!$A$5:$A$200,EDATE($A11,12),速報_原データ!$B$5:$B$200,H$3)/100),IF(COUNTIFS(速報_原データ!$I$6:$I$9,EDATE($A11,12),速報_原データ!$J$6:$J$9,H$3)>0,H23/(1+SUMIFS(速報_原データ!$K$6:$K$9,速報_原データ!$I$6:$I$9,EDATE($A11,12),速報_原データ!$J$6:$J$9,H$3)/100),AVERAGE(H10,H12)))) -> 143.84651 | I11: =B11-D11 -> 1478.7133 | J11: =C11-D11-E11-H11 -> 385.51233 | K11: 翌年同月速報の前年比から逆算
A12: 45231 | B12: =IF(COUNTIFS(速報_原データ!$A$5:$A$200,$A12,速報_原データ!$B$5:$B$200,B$3)>0,SUMIFS(速報_原データ!$C$5:$C$200,速報_原データ!$A$5:$A$200,$A12,速報_原データ!$B$5:$B$200,B$3)/100,IF(COUNTIFS(速報_原データ!$A$5:$A$200,EDATE($A12,12),速報_原データ!$B$5:$B$200,B$3)>0,SUMIFS(速報_原データ!$C$5:$C$200,速報_原データ!$A$5:$A$200,EDATE($A12,12),速報_原データ!$B$5:$B$200,B$3)/100/(1+SUMIFS(速報_原データ!$D$5:$D$200,速報_原データ!$A$5:$A$200,EDATE($A12,12),速報_原データ!$B$5:$B$200,B$3)/100),IF(COUNTIFS(速報_原データ!$I$6:$I$9,EDATE($A12,12),速報_原データ!$J$6:$J$9,B$3)>0,B24/(1+SUMIFS(速報_原データ!$K$6:$K$9,速報_原データ!$I$6:$I$9,EDATE($A12,12),速報_原データ!$J$6:$J$9,B$3)/100),AVERAGE(B11,B13)))) -> 2833.9137 | C12: =IF(COUNTIFS(速報_原データ!$A$5:$A$200,$A12,速報_原データ!$B$5:$B$200,C$3)>0,SUMIFS(速報_原データ!$C$5:$C$200,速報_原データ!$A$5:$A$200,$A12,速報_原データ!$B$5:$B$200,C$3)/100,IF(COUNTIFS(速報_原データ!$A$5:$A$200,EDATE($A12,12),速報_原データ!$B$5:$B$200,C$3)>0,SUMIFS(速報_原データ!$C$5:$C$200,速報_原データ!$A$5:$A$200,EDATE($A12,12),速報_原データ!$B$5:$B$200,C$3)/100/(1+SUMIFS(速報_原データ!$D$5:$D$200,速報_原データ!$A$5:$A$200,EDATE($A12,12),速報_原データ!$B$5:$B$200,C$3)/100),IF(COUNTIFS(速報_原データ!$I$6:$I$9,EDATE($A12,12),速報_原データ!$J$6:$J$9,C$3)>0,C24/(1+SUMIFS(速報_原データ!$K$6:$K$9,速報_原データ!$I$6:$I$9,EDATE($A12,12),速報_原データ!$J$6:$J$9,C$3)/100),AVERAGE(C11,C13)))) -> 2353.8231 | D12: =IF(COUNTIFS(速報_原データ!$A$5:$A$200,$A12,速報_原データ!$B$5:$B$200,D$3)>0,SUMIFS(速報_原データ!$C$5:$C$200,速報_原データ!$A$5:$A$200,$A12,速報_原データ!$B$5:$B$200,D$3)/100,IF(COUNTIFS(速報_原データ!$A$5:$A$200,EDATE($A12,12),速報_原データ!$B$5:$B$200,D$3)>0,SUMIFS(速報_原データ!$C$5:$C$200,速報_原データ!$A$5:$A$200,EDATE($A12,12),速報_原データ!$B$5:$B$200,D$3)/100/(1+SUMIFS(速報_原データ!$D$5:$D$200,速報_原データ!$A$5:$A$200,EDATE($A12,12),速報_原データ!$B$5:$B$200,D$3)/100),IF(COUNTIFS(速報_原データ!$I$6:$I$9,EDATE($A12,12),速報_原データ!$J$6:$J$9,D$3)>0,D24/(1+SUMIFS(速報_原データ!$K$6:$K$9,速報_原データ!$I$6:$I$9,EDATE($A12,12),速報_原データ!$J$6:$J$9,D$3)/100),AVERAGE(D11,D13)))) -> 1575.1823 | E12: =IF(COUNTIFS(速報_原データ!$A$5:$A$200,$A12,速報_原データ!$B$5:$B$200,E$3)>0,SUMIFS(速報_原データ!$C$5:$C$200,速報_原データ!$A$5:$A$200,$A12,速報_原データ!$B$5:$B$200,E$3)/100,IF(COUNTIFS(速報_原データ!$A$5:$A$200,EDATE($A12,12),速報_原データ!$B$5:$B$200,E$3)>0,SUMIFS(速報_原データ!$C$5:$C$200,速報_原データ!$A$5:$A$200,EDATE($A12,12),速報_原データ!$B$5:$B$200,E$3)/100/(1+SUMIFS(速報_原データ!$D$5:$D$200,速報_原データ!$A$5:$A$200,EDATE($A12,12),速報_原データ!$B$5:$B$200,E$3)/100),IF(COUNTIFS(速報_原データ!$I$6:$I$9,EDATE($A12,12),速報_原データ!$J$6:$J$9,E$3)>0,E24/(1+SUMIFS(速報_原データ!$K$6:$K$9,速報_原データ!$I$6:$I$9,EDATE($A12,12),速報_原データ!$J$6:$J$9,E$3)/100),AVERAGE(E11,E13)))) -> 293.03844 | F12: =IF(COUNTIFS(速報_原データ!$A$5:$A$200,$A12,速報_原データ!$B$5:$B$200,F$3)>0,SUMIFS(速報_原データ!$C$5:$C$200,速報_原データ!$A$5:$A$200,$A12,速報_原データ!$B$5:$B$200,F$3)/100,IF(COUNTIFS(速報_原データ!$A$5:$A$200,EDATE($A12,12),速報_原データ!$B$5:$B$200,F$3)>0,SUMIFS(速報_原データ!$C$5:$C$200,速報_原データ!$A$5:$A$200,EDATE($A12,12),速報_原データ!$B$5:$B$200,F$3)/100/(1+SUMIFS(速報_原データ!$D$5:$D$200,速報_原データ!$A$5:$A$200,EDATE($A12,12),速報_原データ!$B$5:$B$200,F$3)/100),IF(COUNTIFS(速報_原データ!$I$6:$I$9,EDATE($A12,12),速報_原データ!$J$6:$J$9,F$3)>0,F24/(1+SUMIFS(速報_原データ!$K$6:$K$9,速報_原データ!$I$6:$I$9,EDATE($A12,12),速報_原データ!$J$6:$J$9,F$3)/100),AVERAGE(F11,F13)))) -> 357.14286 | G12: =IF(COUNTIFS(速報_原データ!$A$5:$A$200,$A12,速報_原データ!$B$5:$B$200,G$3)>0,SUMIFS(速報_原データ!$C$5:$C$200,速報_原データ!$A$5:$A$200,$A12,速報_原データ!$B$5:$B$200,G$3)/100,IF(COUNTIFS(速報_原データ!$A$5:$A$200,EDATE($A12,12),速報_原データ!$B$5:$B$200,G$3)>0,SUMIFS(速報_原データ!$C$5:$C$200,速報_原データ!$A$5:$A$200,EDATE($A12,12),速報_原データ!$B$5:$B$200,G$3)/100/(1+SUMIFS(速報_原データ!$D$5:$D$200,速報_原データ!$A$5:$A$200,EDATE($A12,12),速報_原データ!$B$5:$B$200,G$3)/100),IF(COUNTIFS(速報_原データ!$I$6:$I$9,EDATE($A12,12),速報_原データ!$J$6:$J$9,G$3)>0,G24/(1+SUMIFS(速報_原データ!$K$6:$K$9,速報_原データ!$I$6:$I$9,EDATE($A12,12),速報_原データ!$J$6:$J$9,G$3)/100),AVERAGE(G11,G13)))) -> 114.23645 | H12: =IF(COUNTIFS(速報_原データ!$A$5:$A$200,$A12,速報_原データ!$B$5:$B$200,H$3)>0,SUMIFS(速報_原データ!$C$5:$C$200,速報_原データ!$A$5:$A$200,$A12,速報_原データ!$B$5:$B$200,H$3)/100,IF(COUNTIFS(速報_原データ!$A$5:$A$200,EDATE($A12,12),速報_原データ!$B$5:$B$200,H$3)>0,SUMIFS(速報_原データ!$C$5:$C$200,速報_原データ!$A$5:$A$200,EDATE($A12,12),速報_原データ!$B$5:$B$200,H$3)/100/(1+SUMIFS(速報_原データ!$D$5:$D$200,速報_原データ!$A$5:$A$200,EDATE($A12,12),速報_原データ!$B$5:$B$200,H$3)/100),IF(COUNTIFS(速報_原データ!$I$6:$I$9,EDATE($A12,12),速報_原データ!$J$6:$J$9,H$3)>0,H24/(1+SUMIFS(速報_原データ!$K$6:$K$9,速報_原データ!$I$6:$I$9,EDATE($A12,12),速報_原データ!$J$6:$J$9,H$3)/100),AVERAGE(H11,H13)))) -> 143.6339 | I12: =B12-D12 -> 1258.7314 | J12: =C12-D12-E12-H12 -> 341.96842 | K12: 翌年同月速報の前年比から逆算
A13: 45261 | B13: =IF(COUNTIFS(速報_原データ!$A$5:$A$200,$A13,速報_原データ!$B$5:$B$200,B$3)>0,SUMIFS(速報_原データ!$C$5:$C$200,速報_原データ!$A$5:$A$200,$A13,速報_原データ!$B$5:$B$200,B$3)/100,IF(COUNTIFS(速報_原データ!$A$5:$A$200,EDATE($A13,12),速報_原データ!$B$5:$B$200,B$3)>0,SUMIFS(速報_原データ!$C$5:$C$200,速報_原データ!$A$5:$A$200,EDATE($A13,12),速報_原データ!$B$5:$B$200,B$3)/100/(1+SUMIFS(速報_原データ!$D$5:$D$200,速報_原データ!$A$5:$A$200,EDATE($A13,12),速報_原データ!$B$5:$B$200,B$3)/100),IF(COUNTIFS(速報_原データ!$I$6:$I$9,EDATE($A13,12),速報_原データ!$J$6:$J$9,B$3)>0,B25/(1+SUMIFS(速報_原データ!$K$6:$K$9,速報_原データ!$I$6:$I$9,EDATE($A13,12),速報_原データ!$J$6:$J$9,B$3)/100),AVERAGE(B12,B14)))) -> 4071.0759 | C13: =IF(COUNTIFS(速報_原データ!$A$5:$A$200,$A13,速報_原データ!$B$5:$B$200,C$3)>0,SUMIFS(速報_原データ!$C$5:$C$200,速報_原データ!$A$5:$A$200,$A13,速報_原データ!$B$5:$B$200,C$3)/100,IF(COUNTIFS(速報_原データ!$A$5:$A$200,EDATE($A13,12),速報_原データ!$B$5:$B$200,C$3)>0,SUMIFS(速報_原データ!$C$5:$C$200,速報_原データ!$A$5:$A$200,EDATE($A13,12),速報_原データ!$B$5:$B$200,C$3)/100/(1+SUMIFS(速報_原データ!$D$5:$D$200,速報_原データ!$A$5:$A$200,EDATE($A13,12),速報_原データ!$B$5:$B$200,C$3)/100),IF(COUNTIFS(速報_原データ!$I$6:$I$9,EDATE($A13,12),速報_原データ!$J$6:$J$9,C$3)>0,C25/(1+SUMIFS(速報_原データ!$K$6:$K$9,速報_原データ!$I$6:$I$9,EDATE($A13,12),速報_原データ!$J$6:$J$9,C$3)/100),AVERAGE(C12,C14)))) -> 3532.6619 | D13: =IF(COUNTIFS(速報_原データ!$A$5:$A$200,$A13,速報_原データ!$B$5:$B$200,D$3)>0,SUMIFS(速報_原データ!$C$5:$C$200,速報_原データ!$A$5:$A$200,$A13,速報_原データ!$B$5:$B$200,D$3)/100,IF(COUNTIFS(速報_原データ!$A$5:$A$200,EDATE($A13,12),速報_原データ!$B$5:$B$200,D$3)>0,SUMIFS(速報_原データ!$C$5:$C$200,速報_原データ!$A$5:$A$200,EDATE($A13,12),速報_原データ!$B$5:$B$200,D$3)/100/(1+SUMIFS(速報_原データ!$D$5:$D$200,速報_原データ!$A$5:$A$200,EDATE($A13,12),速報_原データ!$B$5:$B$200,D$3)/100),IF(COUNTIFS(速報_原データ!$I$6:$I$9,EDATE($A13,12),速報_原データ!$J$6:$J$9,D$3)>0,D25/(1+SUMIFS(速報_原データ!$K$6:$K$9,速報_原データ!$I$6:$I$9,EDATE($A13,12),速報_原データ!$J$6:$J$9,D$3)/100),AVERAGE(D12,D14)))) -> 2224.1518 | E13: =IF(COUNTIFS(速報_原データ!$A$5:$A$200,$A13,速報_原データ!$B$5:$B$200,E$3)>0,SUMIFS(速報_原データ!$C$5:$C$200,速報_原データ!$A$5:$A$200,$A13,速報_原データ!$B$5:$B$200,E$3)/100,IF(COUNTIFS(速報_原データ!$A$5:$A$200,EDATE($A13,12),速報_原データ!$B$5:$B$200,E$3)>0,SUMIFS(速報_原データ!$C$5:$C$200,速報_原データ!$A$5:$A$200,EDATE($A13,12),速報_原データ!$B$5:$B$200,E$3)/100/(1+SUMIFS(速報_原データ!$D$5:$D$200,速報_原データ!$A$5:$A$200,EDATE($A13,12),速報_原データ!$B$5:$B$200,E$3)/100),IF(COUNTIFS(速報_原データ!$I$6:$I$9,EDATE($A13,12),速報_原データ!$J$6:$J$9,E$3)>0,E25/(1+SUMIFS(速報_原データ!$K$6:$K$9,速報_原データ!$I$6:$I$9,EDATE($A13,12),速報_原データ!$J$6:$J$9,E$3)/100),AVERAGE(E12,E14)))) -> 576.84341 | F13: =IF(COUNTIFS(速報_原データ!$A$5:$A$200,$A13,速報_原データ!$B$5:$B$200,F$3)>0,SUMIFS(速報_原データ!$C$5:$C$200,速報_原データ!$A$5:$A$200,$A13,速報_原データ!$B$5:$B$200,F$3)/100,IF(COUNTIFS(速報_原データ!$A$5:$A$200,EDATE($A13,12),速報_原データ!$B$5:$B$200,F$3)>0,SUMIFS(速報_原データ!$C$5:$C$200,速報_原データ!$A$5:$A$200,EDATE($A13,12),速報_原データ!$B$5:$B$200,F$3)/100/(1+SUMIFS(速報_原データ!$D$5:$D$200,速報_原データ!$A$5:$A$200,EDATE($A13,12),速報_原データ!$B$5:$B$200,F$3)/100),IF(COUNTIFS(速報_原データ!$I$6:$I$9,EDATE($A13,12),速報_原データ!$J$6:$J$9,F$3)>0,F25/(1+SUMIFS(速報_原データ!$K$6:$K$9,速報_原データ!$I$6:$I$9,EDATE($A13,12),速報_原データ!$J$6:$J$9,F$3)/100),AVERAGE(F12,F14)))) -> 407.62231 | G13: =IF(COUNTIFS(速報_原データ!$A$5:$A$200,$A13,速報_原データ!$B$5:$B$200,G$3)>0,SUMIFS(速報_原データ!$C$5:$C$200,速報_原データ!$A$5:$A$200,$A13,速報_原データ!$B$5:$B$200,G$3)/100,IF(COUNTIFS(速報_原データ!$A$5:$A$200,EDATE($A13,12),速報_原データ!$B$5:$B$200,G$3)>0,SUMIFS(速報_原データ!$C$5:$C$200,速報_原データ!$A$5:$A$200,EDATE($A13,12),速報_原データ!$B$5:$B$200,G$3)/100/(1+SUMIFS(速報_原データ!$D$5:$D$200,速報_原データ!$A$5:$A$200,EDATE($A13,12),速報_原データ!$B$5:$B$200,G$3)/100),IF(COUNTIFS(速報_原データ!$I$6:$I$9,EDATE($A13,12),速報_原データ!$J$6:$J$9,G$3)>0,G25/(1+SUMIFS(速報_原データ!$K$6:$K$9,速報_原データ!$I$6:$I$9,EDATE($A13,12),速報_原データ!$J$6:$J$9,G$3)/100),AVERAGE(G12,G14)))) -> 119.26941 | H13: =IF(COUNTIFS(速報_原データ!$A$5:$A$200,$A13,速報_原データ!$B$5:$B$200,H$3)>0,SUMIFS(速報_原データ!$C$5:$C$200,速報_原データ!$A$5:$A$200,$A13,速報_原データ!$B$5:$B$200,H$3)/100,IF(COUNTIFS(速報_原データ!$A$5:$A$200,EDATE($A13,12),速報_原データ!$B$5:$B$200,H$3)>0,SUMIFS(速報_原データ!$C$5:$C$200,速報_原データ!$A$5:$A$200,EDATE($A13,12),速報_原データ!$B$5:$B$200,H$3)/100/(1+SUMIFS(速報_原データ!$D$5:$D$200,速報_原データ!$A$5:$A$200,EDATE($A13,12),速報_原データ!$B$5:$B$200,H$3)/100),IF(COUNTIFS(速報_原データ!$I$6:$I$9,EDATE($A13,12),速報_原データ!$J$6:$J$9,H$3)>0,H25/(1+SUMIFS(速報_原データ!$K$6:$K$9,速報_原データ!$I$6:$I$9,EDATE($A13,12),速報_原データ!$J$6:$J$9,H$3)/100),AVERAGE(H12,H14)))) -> 202.08955 | I13: =B13-D13 -> 1846.9242 | J13: =C13-D13-E13-H13 -> 529.57712 | K13: 翌年同月速報の前年比から逆算
A14: 45292 | B14: =IF(COUNTIFS(速報_原データ!$A$5:$A$200,$A14,速報_原データ!$B$5:$B$200,B$3)>0,SUMIFS(速報_原データ!$C$5:$C$200,速報_原データ!$A$5:$A$200,$A14,速報_原データ!$B$5:$B$200,B$3)/100,IF(COUNTIFS(速報_原データ!$A$5:$A$200,EDATE($A14,12),速報_原データ!$B$5:$B$200,B$3)>0,SUMIFS(速報_原データ!$C$5:$C$200,速報_原データ!$A$5:$A$200,EDATE($A14,12),速報_原データ!$B$5:$B$200,B$3)/100/(1+SUMIFS(速報_原データ!$D$5:$D$200,速報_原データ!$A$5:$A$200,EDATE($A14,12),速報_原データ!$B$5:$B$200,B$3)/100),IF(COUNTIFS(速報_原データ!$I$6:$I$9,EDATE($A14,12),速報_原データ!$J$6:$J$9,B$3)>0,B26/(1+SUMIFS(速報_原データ!$K$6:$K$9,速報_原データ!$I$6:$I$9,EDATE($A14,12),速報_原データ!$J$6:$J$9,B$3)/100),AVERAGE(B13,B15)))) -> 2911.3246 | C14: =IF(COUNTIFS(速報_原データ!$A$5:$A$200,$A14,速報_原データ!$B$5:$B$200,C$3)>0,SUMIFS(速報_原データ!$C$5:$C$200,速報_原データ!$A$5:$A$200,$A14,速報_原データ!$B$5:$B$200,C$3)/100,IF(COUNTIFS(速報_原データ!$A$5:$A$200,EDATE($A14,12),速報_原データ!$B$5:$B$200,C$3)>0,SUMIFS(速報_原データ!$C$5:$C$200,速報_原データ!$A$5:$A$200,EDATE($A14,12),速報_原データ!$B$5:$B$200,C$3)/100/(1+SUMIFS(速報_原データ!$D$5:$D$200,速報_原データ!$A$5:$A$200,EDATE($A14,12),速報_原データ!$B$5:$B$200,C$3)/100),IF(COUNTIFS(速報_原データ!$I$6:$I$9,EDATE($A14,12),速報_原データ!$J$6:$J$9,C$3)>0,C26/(1+SUMIFS(速報_原データ!$K$6:$K$9,速報_原データ!$I$6:$I$9,EDATE($A14,12),速報_原データ!$J$6:$J$9,C$3)/100),AVERAGE(C13,C15)))) -> 2413.3721 | D14: =IF(COUNTIFS(速報_原データ!$A$5:$A$200,$A14,速報_原データ!$B$5:$B$200,D$3)>0,SUMIFS(速報_原データ!$C$5:$C$200,速報_原データ!$A$5:$A$200,$A14,速報_原データ!$B$5:$B$200,D$3)/100,IF(COUNTIFS(速報_原データ!$A$5:$A$200,EDATE($A14,12),速報_原データ!$B$5:$B$200,D$3)>0,SUMIFS(速報_原データ!$C$5:$C$200,速報_原データ!$A$5:$A$200,EDATE($A14,12),速報_原データ!$B$5:$B$200,D$3)/100/(1+SUMIFS(速報_原データ!$D$5:$D$200,速報_原データ!$A$5:$A$200,EDATE($A14,12),速報_原データ!$B$5:$B$200,D$3)/100),IF(COUNTIFS(速報_原データ!$I$6:$I$9,EDATE($A14,12),速報_原データ!$J$6:$J$9,D$3)>0,D26/(1+SUMIFS(速報_原データ!$K$6:$K$9,速報_原データ!$I$6:$I$9,EDATE($A14,12),速報_原データ!$J$6:$J$9,D$3)/100),AVERAGE(D13,D15)))) -> 1240.9975 | E14: =IF(COUNTIFS(速報_原データ!$A$5:$A$200,$A14,速報_原データ!$B$5:$B$200,E$3)>0,SUMIFS(速報_原データ!$C$5:$C$200,速報_原データ!$A$5:$A$200,$A14,速報_原データ!$B$5:$B$200,E$3)/100,IF(COUNTIFS(速報_原データ!$A$5:$A$200,EDATE($A14,12),速報_原データ!$B$5:$B$200,E$3)>0,SUMIFS(速報_原データ!$C$5:$C$200,速報_原データ!$A$5:$A$200,EDATE($A14,12),速報_原データ!$B$5:$B$200,E$3)/100/(1+SUMIFS(速報_原データ!$D$5:$D$200,速報_原データ!$A$5:$A$200,EDATE($A14,12),速報_原データ!$B$5:$B$200,E$3)/100),IF(COUNTIFS(速報_原データ!$I$6:$I$9,EDATE($A14,12),速報_原データ!$J$6:$J$9,E$3)>0,E26/(1+SUMIFS(速報_原データ!$K$6:$K$9,速報_原データ!$I$6:$I$9,EDATE($A14,12),速報_原データ!$J$6:$J$9,E$3)/100),AVERAGE(E13,E15)))) -> 598.60355 | F14: =IF(COUNTIFS(速報_原データ!$A$5:$A$200,$A14,速報_原データ!$B$5:$B$200,F$3)>0,SUMIFS(速報_原データ!$C$5:$C$200,速報_原データ!$A$5:$A$200,$A14,速報_原データ!$B$5:$B$200,F$3)/100,IF(COUNTIFS(速報_原データ!$A$5:$A$200,EDATE($A14,12),速報_原データ!$B$5:$B$200,F$3)>0,SUMIFS(速報_原データ!$C$5:$C$200,速報_原データ!$A$5:$A$200,EDATE($A14,12),速報_原データ!$B$5:$B$200,F$3)/100/(1+SUMIFS(速報_原データ!$D$5:$D$200,速報_原データ!$A$5:$A$200,EDATE($A14,12),速報_原データ!$B$5:$B$200,F$3)/100),IF(COUNTIFS(速報_原データ!$I$6:$I$9,EDATE($A14,12),速報_原データ!$J$6:$J$9,F$3)>0,F26/(1+SUMIFS(速報_原データ!$K$6:$K$9,速報_原データ!$I$6:$I$9,EDATE($A14,12),速報_原データ!$J$6:$J$9,F$3)/100),AVERAGE(F13,F15)))) -> 362.10526 | G14: =IF(COUNTIFS(速報_原データ!$A$5:$A$200,$A14,速報_原データ!$B$5:$B$200,G$3)>0,SUMIFS(速報_原データ!$C$5:$C$200,速報_原データ!$A$5:$A$200,$A14,速報_原データ!$B$5:$B$200,G$3)/100,IF(COUNTIFS(速報_原データ!$A$5:$A$200,EDATE($A14,12),速報_原データ!$B$5:$B$200,G$3)>0,SUMIFS(速報_原データ!$C$5:$C$200,速報_原データ!$A$5:$A$200,EDATE($A14,12),速報_原データ!$B$5:$B$200,G$3)/100/(1+SUMIFS(速報_原データ!$D$5:$D$200,速報_原データ!$A$5:$A$200,EDATE($A14,12),速報_原データ!$B$5:$B$200,G$3)/100),IF(COUNTIFS(速報_原データ!$I$6:$I$9,EDATE($A14,12),速報_原データ!$J$6:$J$9,G$3)>0,G26/(1+SUMIFS(速報_原データ!$K$6:$K$9,速報_原データ!$I$6:$I$9,EDATE($A14,12),速報_原データ!$J$6:$J$9,G$3)/100),AVERAGE(G13,G15)))) -> 129.10663 | H14: =IF(COUNTIFS(速報_原データ!$A$5:$A$200,$A14,速報_原データ!$B$5:$B$200,H$3)>0,SUMIFS(速報_原データ!$C$5:$C$200,速報_原データ!$A$5:$A$200,$A14,速報_原データ!$B$5:$B$200,H$3)/100,IF(COUNTIFS(速報_原データ!$A$5:$A$200,EDATE($A14,12),速報_原データ!$B$5:$B$200,H$3)>0,SUMIFS(速報_原データ!$C$5:$C$200,速報_原データ!$A$5:$A$200,EDATE($A14,12),速報_原データ!$B$5:$B$200,H$3)/100/(1+SUMIFS(速報_原データ!$D$5:$D$200,速報_原データ!$A$5:$A$200,EDATE($A14,12),速報_原データ!$B$5:$B$200,H$3)/100),IF(COUNTIFS(速報_原データ!$I$6:$I$9,EDATE($A14,12),速報_原データ!$J$6:$J$9,H$3)>0,H26/(1+SUMIFS(速報_原データ!$K$6:$K$9,速報_原データ!$I$6:$I$9,EDATE($A14,12),速報_原データ!$J$6:$J$9,H$3)/100),AVERAGE(H13,H15)))) -> 187.63547 | I14: =B14-D14 -> 1670.3271 | J14: =C14-D14-E14-H14 -> 386.1356 | K14: 翌年同月速報の前年比から逆算
A15: 45323 | B15: =IF(COUNTIFS(速報_原データ!$A$5:$A$200,$A15,速報_原データ!$B$5:$B$200,B$3)>0,SUMIFS(速報_原データ!$C$5:$C$200,速報_原データ!$A$5:$A$200,$A15,速報_原データ!$B$5:$B$200,B$3)/100,IF(COUNTIFS(速報_原データ!$A$5:$A$200,EDATE($A15,12),速報_原データ!$B$5:$B$200,B$3)>0,SUMIFS(速報_原データ!$C$5:$C$200,速報_原データ!$A$5:$A$200,EDATE($A15,12),速報_原データ!$B$5:$B$200,B$3)/100/(1+SUMIFS(速報_原データ!$D$5:$D$200,速報_原データ!$A$5:$A$200,EDATE($A15,12),速報_原データ!$B$5:$B$200,B$3)/100),IF(COUNTIFS(速報_原データ!$I$6:$I$9,EDATE($A15,12),速報_原データ!$J$6:$J$9,B$3)>0,B27/(1+SUMIFS(速報_原データ!$K$6:$K$9,速報_原データ!$I$6:$I$9,EDATE($A15,12),速報_原データ!$J$6:$J$9,B$3)/100),AVERAGE(B14,B16)))) -> 3104.3975 | C15: =IF(COUNTIFS(速報_原データ!$A$5:$A$200,$A15,速報_原データ!$B$5:$B$200,C$3)>0,SUMIFS(速報_原データ!$C$5:$C$200,速報_原データ!$A$5:$A$200,$A15,速報_原データ!$B$5:$B$200,C$3)/100,IF(COUNTIFS(速報_原データ!$A$5:$A$200,EDATE($A15,12),速報_原データ!$B$5:$B$200,C$3)>0,SUMIFS(速報_原データ!$C$5:$C$200,速報_原データ!$A$5:$A$200,EDATE($A15,12),速報_原データ!$B$5:$B$200,C$3)/100/(1+SUMIFS(速報_原データ!$D$5:$D$200,速報_原データ!$A$5:$A$200,EDATE($A15,12),速報_原データ!$B$5:$B$200,C$3)/100),IF(COUNTIFS(速報_原データ!$I$6:$I$9,EDATE($A15,12),速報_原データ!$J$6:$J$9,C$3)>0,C27/(1+SUMIFS(速報_原データ!$K$6:$K$9,速報_原データ!$I$6:$I$9,EDATE($A15,12),速報_原データ!$J$6:$J$9,C$3)/100),AVERAGE(C14,C16)))) -> 2612.649 | D15: =IF(COUNTIFS(速報_原データ!$A$5:$A$200,$A15,速報_原データ!$B$5:$B$200,D$3)>0,SUMIFS(速報_原データ!$C$5:$C$200,速報_原データ!$A$5:$A$200,$A15,速報_原データ!$B$5:$B$200,D$3)/100,IF(COUNTIFS(速報_原データ!$A$5:$A$200,EDATE($A15,12),速報_原データ!$B$5:$B$200,D$3)>0,SUMIFS(速報_原データ!$C$5:$C$200,速報_原データ!$A$5:$A$200,EDATE($A15,12),速報_原データ!$B$5:$B$200,D$3)/100/(1+SUMIFS(速報_原データ!$D$5:$D$200,速報_原データ!$A$5:$A$200,EDATE($A15,12),速報_原データ!$B$5:$B$200,D$3)/100),IF(COUNTIFS(速報_原データ!$I$6:$I$9,EDATE($A15,12),速報_原データ!$J$6:$J$9,D$3)>0,D27/(1+SUMIFS(速報_原データ!$K$6:$K$9,速報_原データ!$I$6:$I$9,EDATE($A15,12),速報_原データ!$J$6:$J$9,D$3)/100),AVERAGE(D14,D16)))) -> 1655.8343 | E15: =IF(COUNTIFS(速報_原データ!$A$5:$A$200,$A15,速報_原データ!$B$5:$B$200,E$3)>0,SUMIFS(速報_原データ!$C$5:$C$200,速報_原データ!$A$5:$A$200,$A15,速報_原データ!$B$5:$B$200,E$3)/100,IF(COUNTIFS(速報_原データ!$A$5:$A$200,EDATE($A15,12),速報_原データ!$B$5:$B$200,E$3)>0,SUMIFS(速報_原データ!$C$5:$C$200,速報_原データ!$A$5:$A$200,EDATE($A15,12),速報_原データ!$B$5:$B$200,E$3)/100/(1+SUMIFS(速報_原データ!$D$5:$D$200,速報_原データ!$A$5:$A$200,EDATE($A15,12),速報_原データ!$B$5:$B$200,E$3)/100),IF(COUNTIFS(速報_原データ!$I$6:$I$9,EDATE($A15,12),速報_原データ!$J$6:$J$9,E$3)>0,E27/(1+SUMIFS(速報_原データ!$K$6:$K$9,速報_原データ!$I$6:$I$9,EDATE($A15,12),速報_原データ!$J$6:$J$9,E$3)/100),AVERAGE(E14,E16)))) -> 487.67629 | F15: =IF(COUNTIFS(速報_原データ!$A$5:$A$200,$A15,速報_原データ!$B$5:$B$200,F$3)>0,SUMIFS(速報_原データ!$C$5:$C$200,速報_原データ!$A$5:$A$200,$A15,速報_原データ!$B$5:$B$200,F$3)/100,IF(COUNTIFS(速報_原データ!$A$5:$A$200,EDATE($A15,12),速報_原データ!$B$5:$B$200,F$3)>0,SUMIFS(速報_原データ!$C$5:$C$200,速報_原データ!$A$5:$A$200,EDATE($A15,12),速報_原データ!$B$5:$B$200,F$3)/100/(1+SUMIFS(速報_原データ!$D$5:$D$200,速報_原データ!$A$5:$A$200,EDATE($A15,12),速報_原データ!$B$5:$B$200,F$3)/100),IF(COUNTIFS(速報_原データ!$I$6:$I$9,EDATE($A15,12),速報_原データ!$J$6:$J$9,F$3)>0,F27/(1+SUMIFS(速報_原データ!$K$6:$K$9,速報_原データ!$I$6:$I$9,EDATE($A15,12),速報_原データ!$J$6:$J$9,F$3)/100),AVERAGE(F14,F16)))) -> 360.67278 | G15: =IF(COUNTIFS(速報_原データ!$A$5:$A$200,$A15,速報_原データ!$B$5:$B$200,G$3)>0,SUMIFS(速報_原データ!$C$5:$C$200,速報_原データ!$A$5:$A$200,$A15,速報_原データ!$B$5:$B$200,G$3)/100,IF(COUNTIFS(速報_原データ!$A$5:$A$200,EDATE($A15,12),速報_原データ!$B$5:$B$200,G$3)>0,SUMIFS(速報_原データ!$C$5:$C$200,速報_原データ!$A$5:$A$200,EDATE($A15,12),速報_原データ!$B$5:$B$200,G$3)/100/(1+SUMIFS(速報_原データ!$D$5:$D$200,速報_原データ!$A$5:$A$200,EDATE($A15,12),速報_原データ!$B$5:$B$200,G$3)/100),IF(COUNTIFS(速報_原データ!$I$6:$I$9,EDATE($A15,12),速報_原データ!$J$6:$J$9,G$3)>0,G27/(1+SUMIFS(速報_原データ!$K$6:$K$9,速報_原データ!$I$6:$I$9,EDATE($A15,12),速報_原データ!$J$6:$J$9,G$3)/100),AVERAGE(G14,G16)))) -> 126.60848 | H15: =IF(COUNTIFS(速報_原データ!$A$5:$A$200,$A15,速報_原データ!$B$5:$B$200,H$3)>0,SUMIFS(速報_原データ!$C$5:$C$200,速報_原データ!$A$5:$A$200,$A15,速報_原データ!$B$5:$B$200,H$3)/100,IF(COUNTIFS(速報_原データ!$A$5:$A$200,EDATE($A15,12),速報_原データ!$B$5:$B$200,H$3)>0,SUMIFS(速報_原データ!$C$5:$C$200,速報_原データ!$A$5:$A$200,EDATE($A15,12),速報_原データ!$B$5:$B$200,H$3)/100/(1+SUMIFS(速報_原データ!$D$5:$D$200,速報_原データ!$A$5:$A$200,EDATE($A15,12),速報_原データ!$B$5:$B$200,H$3)/100),IF(COUNTIFS(速報_原データ!$I$6:$I$9,EDATE($A15,12),速報_原データ!$J$6:$J$9,H$3)>0,H27/(1+SUMIFS(速報_原データ!$K$6:$K$9,速報_原データ!$I$6:$I$9,EDATE($A15,12),速報_原データ!$J$6:$J$9,H$3)/100),AVERAGE(H14,H16)))) -> 148.75491 | I15: =B15-D15 -> 1448.5632 | J15: =C15-D15-E15-H15 -> 320.38353 | K15: 翌年同月速報の前年比から逆算
A16: 45352 | B16: =IF(COUNTIFS(速報_原データ!$A$5:$A$200,$A16,速報_原データ!$B$5:$B$200,B$3)>0,SUMIFS(速報_原データ!$C$5:$C$200,速報_原データ!$A$5:$A$200,$A16,速報_原データ!$B$5:$B$200,B$3)/100,IF(COUNTIFS(速報_原データ!$A$5:$A$200,EDATE($A16,12),速報_原データ!$B$5:$B$200,B$3)>0,SUMIFS(速報_原データ!$C$5:$C$200,速報_原データ!$A$5:$A$200,EDATE($A16,12),速報_原データ!$B$5:$B$200,B$3)/100/(1+SUMIFS(速報_原データ!$D$5:$D$200,速報_原データ!$A$5:$A$200,EDATE($A16,12),速報_原データ!$B$5:$B$200,B$3)/100),IF(COUNTIFS(速報_原データ!$I$6:$I$9,EDATE($A16,12),速報_原データ!$J$6:$J$9,B$3)>0,B28/(1+SUMIFS(速報_原データ!$K$6:$K$9,速報_原データ!$I$6:$I$9,EDATE($A16,12),速報_原データ!$J$6:$J$9,B$3)/100),AVERAGE(B15,B17)))) -> 4349.2147 | C16: =IF(COUNTIFS(速報_原データ!$A$5:$A$200,$A16,速報_原データ!$B$5:$B$200,C$3)>0,SUMIFS(速報_原データ!$C$5:$C$200,速報_原データ!$A$5:$A$200,$A16,速報_原データ!$B$5:$B$200,C$3)/100,IF(COUNTIFS(速報_原データ!$A$5:$A$200,EDATE($A16,12),速報_原データ!$B$5:$B$200,C$3)>0,SUMIFS(速報_原データ!$C$5:$C$200,速報_原データ!$A$5:$A$200,EDATE($A16,12),速報_原データ!$B$5:$B$200,C$3)/100/(1+SUMIFS(速報_原データ!$D$5:$D$200,速報_原データ!$A$5:$A$200,EDATE($A16,12),速報_原データ!$B$5:$B$200,C$3)/100),IF(COUNTIFS(速報_原データ!$I$6:$I$9,EDATE($A16,12),速報_原データ!$J$6:$J$9,C$3)>0,C28/(1+SUMIFS(速報_原データ!$K$6:$K$9,速報_原データ!$I$6:$I$9,EDATE($A16,12),速報_原データ!$J$6:$J$9,C$3)/100),AVERAGE(C15,C17)))) -> 3731.9686 | D16: =IF(COUNTIFS(速報_原データ!$A$5:$A$200,$A16,速報_原データ!$B$5:$B$200,D$3)>0,SUMIFS(速報_原データ!$C$5:$C$200,速報_原データ!$A$5:$A$200,$A16,速報_原データ!$B$5:$B$200,D$3)/100,IF(COUNTIFS(速報_原データ!$A$5:$A$200,EDATE($A16,12),速報_原データ!$B$5:$B$200,D$3)>0,SUMIFS(速報_原データ!$C$5:$C$200,速報_原データ!$A$5:$A$200,EDATE($A16,12),速報_原データ!$B$5:$B$200,D$3)/100/(1+SUMIFS(速報_原データ!$D$5:$D$200,速報_原データ!$A$5:$A$200,EDATE($A16,12),速報_原データ!$B$5:$B$200,D$3)/100),IF(COUNTIFS(速報_原データ!$I$6:$I$9,EDATE($A16,12),速報_原データ!$J$6:$J$9,D$3)>0,D28/(1+SUMIFS(速報_原データ!$K$6:$K$9,速報_原データ!$I$6:$I$9,EDATE($A16,12),速報_原データ!$J$6:$J$9,D$3)/100),AVERAGE(D15,D17)))) -> 2315.7701 | E16: =IF(COUNTIFS(速報_原データ!$A$5:$A$200,$A16,速報_原データ!$B$5:$B$200,E$3)>0,SUMIFS(速報_原データ!$C$5:$C$200,速報_原データ!$A$5:$A$200,$A16,速報_原データ!$B$5:$B$200,E$3)/100,IF(COUNTIFS(速報_原データ!$A$5:$A$200,EDATE($A16,12),速報_原データ!$B$5:$B$200,E$3)>0,SUMIFS(速報_原データ!$C$5:$C$200,速報_原データ!$A$5:$A$200,EDATE($A16,12),速報_原データ!$B$5:$B$200,E$3)/100/(1+SUMIFS(速報_原データ!$D$5:$D$200,速報_原データ!$A$5:$A$200,EDATE($A16,12),速報_原データ!$B$5:$B$200,E$3)/100),IF(COUNTIFS(速報_原データ!$I$6:$I$9,EDATE($A16,12),速報_原データ!$J$6:$J$9,E$3)>0,E28/(1+SUMIFS(速報_原データ!$K$6:$K$9,速報_原データ!$I$6:$I$9,EDATE($A16,12),速報_原データ!$J$6:$J$9,E$3)/100),AVERAGE(E15,E17)))) -> 603.34139 | F16: =IF(COUNTIFS(速報_原データ!$A$5:$A$200,$A16,速報_原データ!$B$5:$B$200,F$3)>0,SUMIFS(速報_原データ!$C$5:$C$200,速報_原データ!$A$5:$A$200,$A16,速報_原データ!$B$5:$B$200,F$3)/100,IF(COUNTIFS(速報_原データ!$A$5:$A$200,EDATE($A16,12),速報_原データ!$B$5:$B$200,F$3)>0,SUMIFS(速報_原データ!$C$5:$C$200,速報_原データ!$A$5:$A$200,EDATE($A16,12),速報_原データ!$B$5:$B$200,F$3)/100/(1+SUMIFS(速報_原データ!$D$5:$D$200,速報_原データ!$A$5:$A$200,EDATE($A16,12),速報_原データ!$B$5:$B$200,F$3)/100),IF(COUNTIFS(速報_原データ!$I$6:$I$9,EDATE($A16,12),速報_原データ!$J$6:$J$9,F$3)>0,F28/(1+SUMIFS(速報_原データ!$K$6:$K$9,速報_原データ!$I$6:$I$9,EDATE($A16,12),速報_原データ!$J$6:$J$9,F$3)/100),AVERAGE(F15,F17)))) -> 463.94366 | G16: =IF(COUNTIFS(速報_原データ!$A$5:$A$200,$A16,速報_原データ!$B$5:$B$200,G$3)>0,SUMIFS(速報_原データ!$C$5:$C$200,速報_原データ!$A$5:$A$200,$A16,速報_原データ!$B$5:$B$200,G$3)/100,IF(COUNTIFS(速報_原データ!$A$5:$A$200,EDATE($A16,12),速報_原データ!$B$5:$B$200,G$3)>0,SUMIFS(速報_原データ!$C$5:$C$200,速報_原データ!$A$5:$A$200,EDATE($A16,12),速報_原データ!$B$5:$B$200,G$3)/100/(1+SUMIFS(速報_原データ!$D$5:$D$200,速報_原データ!$A$5:$A$200,EDATE($A16,12),速報_原データ!$B$5:$B$200,G$3)/100),IF(COUNTIFS(速報_原データ!$I$6:$I$9,EDATE($A16,12),速報_原データ!$J$6:$J$9,G$3)>0,G28/(1+SUMIFS(速報_原データ!$K$6:$K$9,速報_原データ!$I$6:$I$9,EDATE($A16,12),速報_原データ!$J$6:$J$9,G$3)/100),AVERAGE(G15,G17)))) -> 145.26485 | H16: =IF(COUNTIFS(速報_原データ!$A$5:$A$200,$A16,速報_原データ!$B$5:$B$200,H$3)>0,SUMIFS(速報_原データ!$C$5:$C$200,速報_原データ!$A$5:$A$200,$A16,速報_原データ!$B$5:$B$200,H$3)/100,IF(COUNTIFS(速報_原データ!$A$5:$A$200,EDATE($A16,12),速報_原データ!$B$5:$B$200,H$3)>0,SUMIFS(速報_原データ!$C$5:$C$200,速報_原データ!$A$5:$A$200,EDATE($A16,12),速報_原データ!$B$5:$B$200,H$3)/100/(1+SUMIFS(速報_原データ!$D$5:$D$200,速報_原データ!$A$5:$A$200,EDATE($A16,12),速報_原データ!$B$5:$B$200,H$3)/100),IF(COUNTIFS(速報_原データ!$I$6:$I$9,EDATE($A16,12),速報_原データ!$J$6:$J$9,H$3)>0,H28/(1+SUMIFS(速報_原データ!$K$6:$K$9,速報_原データ!$I$6:$I$9,EDATE($A16,12),速報_原データ!$J$6:$J$9,H$3)/100),AVERAGE(H15,H17)))) -> 191.92568 | I16: =B16-D16 -> 2033.4446 | J16: =C16-D16-E16-H16 -> 620.93141 | K16: 翌年同月速報の前年比から逆算
