Workbook

Sheet 手順
A1: 作り方：黄色のセルを上から順に埋める（完成版＝KOKUSAI_貿易統計ナウキャスト.xlsx が答え）
A2: 凡例：青字＝入力済みのデータ、黄色＝自分で式を入れるセル、緑字＝他シートの参照。
A3: 式の写し方：E列のセルをダブルクリック（または数式バー）で式の文字をコピーし、D列のセルに貼り付けて確定する。F列の範囲へはフィルハンドルで広げる。
A4: 確認：H列の値と同じになれば正解。ずれたら、そのステップの前のステップから見直す。
A5: 流れ：Step1 売上を中国地場とグローバルに分ける → Step2 月次の輸出パネル → Step3 四半期に集計（ラグk） → Step4 回帰と精度 → Step5 2Qの予測と計画比較。
A7: No | B7: Step | C7: シート | D7: セル | E7: 入れる式（文字としてコピーする） | F7: コピー先 | G7: 意味 | H7: 確認値（答え）
A8: 1 | B8: 1 | C8: KOKUSAI_四半期 | D8: H5 | E8: =D5*G5 | F8: H5:H17 | G8: 中国地場売上＝売上×中国地場比率 | H8: H6＝220.5
A9: 2 | B9: 1 | C9: KOKUSAI_四半期 | D9: I5 | E9: =D5-H5 | F9: I5:I17 | G9: グローバル売上＝売上−中国地場 | H9: I6＝229.5
A10: 3 | B10: 2 | C10: 貿易_月次 | D10: B5 | E10: =IF(COUNTIFS('速報_原データ'!$A:$A,$A5,'速報_原データ'!$B:$B,B$3)>0,SUMIFS('速報_原データ'!$C:$C,'速報_原データ'!$A:$A,$A5,'速報_原データ'!$B:$B,B$3)/100,IF(COUNTIFS('速報_原データ'!$A:$A,EDATE($A5,12),'速報_原データ'!$B:$B,B$3)>0,SUMIFS('速報_原データ'!$C:$C,'速報_原データ'!$A:$A,EDATE($A5,12),'速報_原データ'!$B:$B,B$3)/100/(1+SUMIFS('速報_原データ'!$D:$D,'速報_原データ'!$A:$A,EDATE($A5,12),'速報_原データ'!$B:$B,B$3)/100),IF(COUNTIFS('速報_原データ'!$I:$I,EDATE($A5,12),'速報_原データ'!$J:$J,B$3)>0,B17/(1+SUMIFS('速報_原データ'!$K:$K,'速報_原データ'!$I:$I,EDATE($A5,12),'速報_原データ'!$J:$J,B$3)/100),AVERAGE(B4,B6)))) | F10: B5:H45 | G10: ①当月速報があればその値、②なければ翌年同月の値÷(1＋前年比)、③2023年5月は2段逆算、④それでも無ければ前後月の平均。÷100で百万円→億円 | H10: B5＝2,956.6 / D6＝816.9 / D17＝1,888.7
A11: 4 | B11: 2 | C11: 貿易_月次 | D11: I5 | E11: =B5-D5 | F11: I5:I45 | G11: 中国以外＝世界−中国 | H11: I5＝1,990.1
A12: 5 | B12: 2 | C12: 貿易_月次 | D12: J5 | E12: =C5-D5-E5-H5 | F12: J5:J45 | G12: アジア残差（台湾・香港・インド等の合計の代理）
A13: 6 | B13: 3 | C13: 四半期集計 | D13: D6 | E13: =IF(COUNTIFS('貿易_月次'!$A:$A,">="&EDATE($B6,-2-$E$3),'貿易_月次'!$A:$A,"<="&EDATE($B6,-$E$3))=3,SUMIFS('貿易_月次'!$B:$B,'貿易_月次'!$A:$A,">="&EDATE($B6,-2-$E$3),'貿易_月次'!$A:$A,"<="&EDATE($B6,-$E$3)),"") | F13: D6:D19 | G13: k=0：期末月からk=E3か月ずらした3か月の世界輸出を合計。3か月そろわなければ空欄 | H13: D7＝8,236.8 / E7＝4,185.4 / F7＝4,051.4
A14: 7 | B14: 3 | C14: 四半期集計 | D14: E6 | E14: =IF(COUNTIFS('貿易_月次'!$A:$A,">="&EDATE($B6,-2-$E$3),'貿易_月次'!$A:$A,"<="&EDATE($B6,-$E$3))=3,SUMIFS('貿易_月次'!$D:$D,'貿易_月次'!$A:$A,">="&EDATE($B6,-2-$E$3),'貿易_月次'!$A:$A,"<="&EDATE($B6,-$E$3)),"") | F14: E6:E19 | G14: k=0：期末月からk=E3か月ずらした3か月の中国輸出を合計。3か月そろわなければ空欄
A15: 8 | B15: 3 | C15: 四半期集計 | D15: F6 | E15: =IF(COUNTIFS('貿易_月次'!$A:$A,">="&EDATE($B6,-2-$E$3),'貿易_月次'!$A:$A,"<="&EDATE($B6,-$E$3))=3,SUMIFS('貿易_月次'!$I:$I,'貿易_月次'!$A:$A,">="&EDATE($B6,-2-$E$3),'貿易_月次'!$A:$A,"<="&EDATE($B6,-$E$3)),"") | F15: F6:F19 | G15: k=0：期末月からk=E3か月ずらした3か月の中国以外輸出を合計。3か月そろわなければ空欄
A16: 9 | B16: 3 | C16: 四半期集計 | D16: G6 | E16: =IF(COUNTIFS('貿易_月次'!$A:$A,">="&EDATE($B6,-2-$E$3),'貿易_月次'!$A:$A,"<="&EDATE($B6,-$E$3))=3,SUMIFS('貿易_月次'!$E:$E,'貿易_月次'!$A:$A,">="&EDATE($B6,-2-$E$3),'貿易_月次'!$A:$A,"<="&EDATE($B6,-$E$3)),"") | F16: G6:G19 | G16: k=0：期末月からk=E3か月ずらした3か月の韓国輸出を合計。3か月そろわなければ空欄
A17: 10 | B17: 3 | C17: 四半期集計 | D17: H6 | E17: =IF(AND(ISNUMBER(C6),ISNUMBER(D6)),C6/D6,"") | F17: H6:H18 | G17: 実質シェア＝KOKUSAI売上÷世界輸出 | H17: H7＝5.5%
A18: 11 | B18: 3 | C18: 四半期集計 | D18: I6 | E18: =IF(COUNTIFS('貿易_月次'!$A:$A,">="&EDATE($B6,-2-$J$3),'貿易_月次'!$A:$A,"<="&EDATE($B6,-$J$3))=3,SUMIFS('貿易_月次'!$B:$B,'貿易_月次'!$A:$A,">="&EDATE($B6,-2-$J$3),'貿易_月次'!$A:$A,"<="&EDATE($B6,-$J$3)),"") | F18: I6:I19 | G18: k=1：1か月前にずらした3か月の世界輸出 | H18: I7＝7,973.4 / I19＝14,443.4
A19: 12 | B19: 3 | C19: 四半期集計 | D19: J6 | E19: =IF(COUNTIFS('貿易_月次'!$A:$A,">="&EDATE($B6,-2-$J$3),'貿易_月次'!$A:$A,"<="&EDATE($B6,-$J$3))=3,SUMIFS('貿易_月次'!$D:$D,'貿易_月次'!$A:$A,">="&EDATE($B6,-2-$J$3),'貿易_月次'!$A:$A,"<="&EDATE($B6,-$J$3)),"") | F19: J6:J19 | G19: k=1：1か月前にずらした3か月の中国輸出
A20: 13 | B20: 3 | C20: 四半期集計 | D20: K6 | E20: =IF(COUNTIFS('貿易_月次'!$A:$A,">="&EDATE($B6,-2-$J$3),'貿易_月次'!$A:$A,"<="&EDATE($B6,-$J$3))=3,SUMIFS('貿易_月次'!$I:$I,'貿易_月次'!$A:$A,">="&EDATE($B6,-2-$J$3),'貿易_月次'!$A:$A,"<="&EDATE($B6,-$J$3)),"") | F20: K6:K19 | G20: k=1：1か月前にずらした3か月の中国以外輸出
A21: 14 | B21: 3 | C21: 四半期集計 | D21: L6 | E21: =IF(COUNTIFS('貿易_月次'!$A:$A,">="&EDATE($B6,-2-$J$3),'貿易_月次'!$A:$A,"<="&EDATE($B6,-$J$3))=3,SUMIFS('貿易_月次'!$E:$E,'貿易_月次'!$A:$A,">="&EDATE($B6,-2-$J$3),'貿易_月次'!$A:$A,"<="&EDATE($B6,-$J$3)),"") | F21: L6:L19 | G21: k=1：1か月前にずらした3か月の韓国輸出
A22: 15 | B22: 3 | C22: 四半期集計 | D22: M6 | E22: =IF(AND(ISNUMBER(C6),ISNUMBER(I6)),C6/I6,"") | F22: M6:M18 | G22: 実質シェア（k=1） | H22: M7＝5.6%
A23: 16 | B23: 4a（k=0） | C23: 回帰 | D23: C20 | E23: =INTERCEPT($B$6:$B$17,$E$6:$E$17) | G23: 単一：切片a | H23: C20＝12.0
A24: 17 | B24: 4a（k=0） | C24: 回帰 | D24: D20 | E24: =SLOPE($B$6:$B$17,$E$6:$E$17) | G24: 単一：傾きb（輸出1億円あたりの売上） | H24: D20＝0.0516
A25: 18 | B25: 4a（k=0） | C25: 回帰 | D25: E20 | E25: =RSQ($B$6:$B$17,$E$6:$E$17) | G25: 単一：R² | H25: E20＝0.46
A26: 19 | B26: 4a（k=0） | C26: 回帰 | D26: C21 | E26: =INTERCEPT($C$6:$C$17,$F$6:$F$17) | G26: 中国地場：切片
A27: 20 | B27: 4a（k=0） | C27: 回帰 | D27: D21 | E27: =SLOPE($C$6:$C$17,$F$6:$F$17) | G27: 中国地場：傾き | H27: D21＝0.0537
A28: 21 | B28: 4a（k=0） | C28: 回帰 | D28: E21 | E28: =RSQ($C$6:$C$17,$F$6:$F$17) | G28: 中国地場：R²
A29: 22 | B29: 4a（k=0） | C29: 回帰 | D29: C22 | E29: =INTERCEPT($D$6:$D$17,$G$6:$G$17) | G29: グローバル：切片
A30: 23 | B30: 4a（k=0） | C30: 回帰 | D30: D22 | E30: =SLOPE($D$6:$D$17,$G$6:$G$17) | G30: グローバル：傾き | H30: D22＝0.0634
A31: 24 | B31: 4a（k=0） | C31: 回帰 | D31: E22 | E31: =RSQ($D$6:$D$17,$G$6:$G$17) | G31: グローバル：R² | H31: E22＝0.80
A32: 25 | B32: 4a（k=0） | C32: 回帰 | D32: H6 | E32: =$C$20+$D$20*E6 | F32: H6:H17 | G32: 単一モデルの予測値＝a＋b×世界 | H32: H6＝437.2
A33: 26 | B33: 4a（k=0） | C33: 回帰 | D33: I6 | E33: =B6-H6 | F33: I6:I17 | G33: 残差＝実績−予測
A34: 27 | B34: 4a（k=0） | C34: 回帰 | D34: J6 | E34: =1/COUNT($E$6:$E$17)+(E6-AVERAGE($E$6:$E$17))^2/DEVSQ($E$6:$E$17) | F34: J6:J17 | G34: てこ比h：その四半期のxが平均から離れているほど大きい
A35: 28 | B35: 4a（k=0） | C35: 回帰 | D35: K6 | E35: =I6/(1-J6) | F35: K6:K17 | G35: その四半期を抜いて推計した場合の誤差（LOO残差） | H35: K6＝32.9
A36: 29 | B36: 4a（k=0） | C36: 回帰 | D36: L6 | E36: =$C$21+$D$21*F6 | F36: L6:L17 | G36: 中国地場売上の予測＝a_c＋b_c×中国
A37: 30 | B37: 4a（k=0） | C37: 回帰 | D37: M6 | E37: =C6-L6 | F37: M6:M17 | G37: 中国地場の残差
A38: 31 | B38: 4a（k=0） | C38: 回帰 | D38: N6 | E38: =1/COUNT($F$6:$F$17)+(F6-AVERAGE($F$6:$F$17))^2/DEVSQ($F$6:$F$17) | F38: N6:N17 | G38: 中国地場式のてこ比
A39: 32 | B39: 4a（k=0） | C39: 回帰 | D39: O6 | E39: =$C$22+$D$22*G6 | F39: O6:O17 | G39: グローバル売上の予測＝a_g＋b_g×中国以外
A40: 33 | B40: 4a（k=0） | C40: 回帰 | D40: P6 | E40: =D6-O6 | F40: P6:P17 | G40: グローバルの残差
A41: 34 | B41: 4a（k=0） | C41: 回帰 | D41: Q6 | E41: =1/COUNT($G$6:$G$17)+(G6-AVERAGE($G$6:$G$17))^2/DEVSQ($G$6:$G$17) | F41: Q6:Q17 | G41: グローバル式のてこ比
...

Sheet 速報_原データ
A1: 財務省 貿易統計 月次速報：概況品「半導体等製造装置」の地域別輸出（原データ）
A2: 青字＝各月の速報PDFから転記した値。価額は百万円、前年同月比は％（例：40.1＝＋40.1％）。
A4: 月 | B4: 地域 | C4: 価額（百万円） | D4: 前年同月比（％） | E4: 数量（トン） | F4: 数量前年比（％） | G4: 出所PDF | I4: 2024年5月の前年同月比（概要PDFより）
A5: 45383 | B5: ASEAN | C5: 17542 | D5: 27.4 | E5: 545 | F5: -1.2 | G5: https://www.customs.go.jp/toukei/shinbun/trade-st/2024/2024044.pdf | I5: 月 | J5: 地域 | K5: 前年同月比（％）
A6: 45383 | B6: Asia | C6: 322037 | D6: 45.2 | E6: 11129 | F6: 43.8 | G6: https://www.customs.go.jp/toukei/shinbun/trade-st/2024/2024044.pdf | I6: 45413 | J6: World | K6: 45.9
A7: 45383 | B7: China | C7: 188866 | D7: 95.4 | E7: 6494 | F7: 94.8 | G7: https://www.customs.go.jp/toukei/shinbun/trade-st/2024/2024044.pdf | I7: 45413 | J7: Asia | K7: 56.2
A8: 45383 | B8: EU | C8: 12280 | D8: -44.5 | E8: 395 | F8: -43.9 | G8: https://www.customs.go.jp/toukei/shinbun/trade-st/2024/2024044.pdf | I8: 45413 | J8: China | K8: 130.7
A9: 45383 | B9: Korea | C9: 45082 | D9: -0.4 | E9: 1611 | F9: 28.9 | G9: https://www.customs.go.jp/toukei/shinbun/trade-st/2024/2024044.pdf | I9: 45413 | J9: US | K9: 137.8
A10: 45383 | B10: US | C10: 42838 | D10: -16.3 | E10: 1188 | F10: -24.7 | G10: https://www.customs.go.jp/toukei/shinbun/trade-st/2024/2024044.pdf | I10: 出所: https://www.customs.go.jp/toukei/shinbun/trade-st/gaiyo2024_05.pdf
A11: 45383 | B11: World | C11: 379038 | D11: 28.2 | E11: 12780 | F11: 27.3 | G11: https://www.customs.go.jp/toukei/shinbun/trade-st/2024/2024044.pdf
A12: 45444 | B12: ASEAN | C12: 16156 | D12: 13.8 | E12: 426 | F12: -30 | G12: https://www.customs.go.jp/toukei/shinbun/trade-st/2024/2024064.pdf
A13: 45444 | B13: Asia | C13: 338211 | D13: 42.9 | E13: 11035 | F13: 28.5 | G13: https://www.customs.go.jp/toukei/shinbun/trade-st/2024/2024064.pdf
A14: 45444 | B14: China | C14: 192584 | D14: 47.7 | E14: 6249 | F14: 30.5 | G14: https://www.customs.go.jp/toukei/shinbun/trade-st/2024/2024064.pdf
A15: 45444 | B15: EU | C15: 10419 | D15: -48.7 | E15: 280 | F15: -49.7 | G15: https://www.customs.go.jp/toukei/shinbun/trade-st/2024/2024064.pdf
A16: 45444 | B16: Korea | C16: 54349 | D16: 7.6 | E16: 1963 | F16: 42.6 | G16: https://www.customs.go.jp/toukei/shinbun/trade-st/2024/2024064.pdf
A17: 45444 | B17: US | C17: 47981 | D17: 58.4 | E17: 1018 | F17: 18.2 | G17: https://www.customs.go.jp/toukei/shinbun/trade-st/2024/2024064.pdf
A18: 45444 | B18: World | C18: 397166 | D18: 37.9 | E18: 12343 | F18: 23 | G18: https://www.customs.go.jp/toukei/shinbun/trade-st/2024/2024064.pdf
A19: 45474 | B19: ASEAN | C19: 19766 | D19: 35.4 | E19: 564 | F19: -14.4 | G19: https://www.customs.go.jp/toukei/shinbun/trade-st/2024/2024074.pdf
A20: 45474 | B20: Asia | C20: 314213 | D20: 32.6 | E20: 9989 | F20: -2.3 | G20: https://www.customs.go.jp/toukei/shinbun/trade-st/2024/2024074.pdf
A21: 45474 | B21: China | C21: 163858 | D21: 16.6 | E21: 5287 | F21: -19.1 | G21: https://www.customs.go.jp/toukei/shinbun/trade-st/2024/2024074.pdf
A22: 45474 | B22: EU | C22: 8783 | D22: -49.1 | E22: 261 | F22: -56.9 | G22: https://www.customs.go.jp/toukei/shinbun/trade-st/2024/2024074.pdf
... A200: 46235 | B200: World | C200: 489764 | D200: 40.1 | E200: 15572 | F200: 43.1 | G200: https://www.customs.go.jp/toukei/shinbun/trade-st/2026/2026084.pdf

Sheet 貿易_月次
A1: 半導体等製造装置の輸出（億円）— 月次パネル
A2: 当月の速報値を優先。無い月は翌年同月の速報値÷(1＋前年同月比)で逆算。2023年5月は2段逆算、韓国・ASEAN・EUの同月は前後月の平均で補間。
B3: World | C3: Asia | D3: China | E3: Korea | F3: US | G3: EU | H3: ASEAN
A4: 月 | B4: 世界 | C4: アジア | D4: 中国 | E4: 韓国 | F4: 米国 | G4: EU | H4: ASEAN | I4: 中国以外 | J4: アジア残差（台湾等） | K4: 値の出所
A5: 45017 | K5: 翌年同月速報の前年比から逆算
A6: 45047 | K6: 2段逆算（韓国・ASEAN・EUは補間）
A7: 45078 | K7: 翌年同月速報の前年比から逆算
A8: 45108 | K8: 翌年同月速報の前年比から逆算
A9: 45139 | K9: 翌年同月速報の前年比から逆算
A10: 45170 | K10: 翌年同月速報の前年比から逆算
A11: 45200 | K11: 翌年同月速報の前年比から逆算
A12: 45231 | K12: 翌年同月速報の前年比から逆算
A13: 45261 | K13: 翌年同月速報の前年比から逆算
A14: 45292 | K14: 翌年同月速報の前年比から逆算
A15: 45323 | K15: 翌年同月速報の前年比から逆算
A16: 45352 | K16: 翌年同月速報の前年比から逆算
... A45: 46235 | K45: 当月速報

Sheet KOKUSAI_四半期
A1: KOKUSAI ELECTRIC（6525）四半期売上収益（億円）
A2: 青字＝決算説明資料からの転記。27/3期から装置・サービスの区分基準が変更されたため、1Qの内訳は空欄。
A4: 四半期 | B4: 期間 | C4: 期末月 | D4: 売上収益 | E4: 装置（旧基準） | F4: サービス（旧基準） | G4: 中国地場比率 | H4: 中国地場売上 | I4: グローバル売上
A5: 24/3期 1Q | B5: 2023年4-6月 | C5: 45078 | D5: 327 | E5: 185 | F5: 142 | G5: 0.29
A6: 24/3期 2Q | B6: 2023年7-9月 | C6: 45170 | D6: 450 | E6: 262 | F6: 188 | G6: 0.49
A7: 24/3期 3Q | B7: 2023年10-12月 | C7: 45261 | D7: 540 | E7: 375 | F7: 164 | G7: 0.45
A8: 24/3期 4Q | B8: 2024年1-3月 | C8: 45352 | D8: 492 | E8: 361 | F8: 131 | G8: 0.5
A9: 25/3期 1Q | B9: 2024年4-6月 | C9: 45444 | D9: 652 | E9: 439 | F9: 214 | G9: 0.5
A10: 25/3期 2Q | B10: 2024年7-9月 | C10: 45536 | D10: 493 | E10: 315 | F10: 179 | G10: 0.44
A11: 25/3期 3Q | B11: 2024年10-12月 | C11: 45627 | D11: 601 | E11: 420 | F11: 182 | G11: 0.4
A12: 25/3期 4Q | B12: 2025年1-3月 | C12: 45717 | D12: 643 | E12: 470 | F12: 173 | G12: 0.41
A13: 26/3期 1Q | B13: 2025年4-6月 | C13: 45809 | D13: 518 | E13: 317 | F13: 201 | G13: 0.38
A14: 26/3期 2Q | B14: 2025年7-9月 | C14: 45901 | D14: 654 | E14: 416 | F14: 239 | G14: 0.44
A15: 26/3期 3Q | B15: 2025年10-12月 | C15: 45992 | D15: 559 | E15: 313 | F15: 246 | G15: 0.31
A16: 26/3期 4Q | B16: 2026年1-3月 | C16: 46082 | D16: 620 | E16: 355 | F16: 266 | G16: 0.26
A17: 27/3期 1Q | B17: 2026年4-6月 | C17: 46174 | D17: 754 | G17: 0.25
A19: 出所: 24/3期〜25/3期は25/3期決算説明資料、26/3期は26/3期決算説明資料、27/3期1Qは決算報道（売上754億円、中国地場25％）。
A20: 中国地場比率は会社開示の四半期比率を全社売上に掛けて金額化した近似（比率の母数が装置売上である場合は過大）。

Sheet 四半期集計
A1: 四半期ごとの輸出額（億円）— 期末月からkか月ずらした3か月合計
A2: k＝輸出（通関）が売上計上に先行する月数。k=1なら、7-9月期に6-8月の輸出を対応させる。
D3: k = | E3: 0 | F3: （k=0：同じ3か月） | I3: k = | J3: 1 | K3: （k=1：1か月先行）
A4: 四半期 | B4: 期末月 | C4: 売上収益 | D4: 世界 | E4: 中国 | F4: 中国以外 | G4: 韓国 | H4: 実質シェア | I4: 世界 | J4: 中国 | K4: 中国以外 | L4: 韓国 | M4: 実質シェア
A6: 24/3期 1Q | B6: =KOKUSAI_四半期!C5 -> 45078 | C6: =KOKUSAI_四半期!D5 -> 327
A7: 24/3期 2Q | B7: =KOKUSAI_四半期!C6 -> 45170 | C7: =KOKUSAI_四半期!D6 -> 450
A8: 24/3期 3Q | B8: =KOKUSAI_四半期!C7 -> 45261 | C8: =KOKUSAI_四半期!D7 -> 540
A9: 24/3期 4Q | B9: =KOKUSAI_四半期!C8 -> 45352 | C9: =KOKUSAI_四半期!D8 -> 492
A10: 25/3期 1Q | B10: =KOKUSAI_四半期!C9 -> 45444 | C10: =KOKUSAI_四半期!D9 -> 652
A11: 25/3期 2Q | B11: =KOKUSAI_四半期!C10 -> 45536 | C11: =KOKUSAI_四半期!D10 -> 493
A12: 25/3期 3Q | B12: =KOKUSAI_四半期!C11 -> 45627 | C12: =KOKUSAI_四半期!D11 -> 601
A13: 25/3期 4Q | B13: =KOKUSAI_四半期!C12 -> 45717 | C13: =KOKUSAI_四半期!D12 -> 643
A14: 26/3期 1Q | B14: =KOKUSAI_四半期!C13 -> 45809 | C14: =KOKUSAI_四半期!D13 -> 518
A15: 26/3期 2Q | B15: =KOKUSAI_四半期!C14 -> 45901 | C15: =KOKUSAI_四半期!D14 -> 654
A16: 26/3期 3Q | B16: =KOKUSAI_四半期!C15 -> 45992 | C16: =KOKUSAI_四半期!D15 -> 559
A17: 26/3期 4Q | B17: =KOKUSAI_四半期!C16 -> 46082 | C17: =KOKUSAI_四半期!D16 -> 620
A18: 27/3期 1Q | B18: =KOKUSAI_四半期!C17 -> 46174 | C18: =KOKUSAI_四半期!D17 -> 754
A19: 27/3期 2Q | B19: 46266
A21: 実質シェア＝KOKUSAI売上÷日本の半導体等製造装置輸出。27/3期2Qのk=0は9月分が未公表のため空欄（ナウキャストで推計）。

Sheet 回帰
A1: 回帰：売上収益と輸出額（サンプル＝24/3期2Q〜27/3期1Qの12四半期）
A2: 単一モデル：売上＝a＋b×世界。構造モデル：中国地場売上＝a_c＋b_c×中国、グローバル売上＝a_g＋b_g×中国以外、全社＝両者の和。LOO残差＝残差÷(1−h)（単回帰のleave-one-outの厳密式）。
A4: k=0（輸出と売上が同じ3か月）
A5: 四半期 | B5: 売上収益 | C5: 中国地場 | D5: グローバル | E5: 世界 | F5: 中国 | G5: 中国以外 | H5: 単一:予測 | I5: 単一:残差 | J5: 単一:h | K5: 単一:LOO残差 | L5: 中国地場:予測 | M5: 中国地場:残差 | N5: 中国地場:h | O5: グローバル:予測 | P5: グローバル:残差 | Q5: グローバル:h | R5: 構造:予測 | S5: 構造:残差 | T5: 構造:LOO残差
A6: =四半期集計!A7 -> 24/3期 2Q | B6: =KOKUSAI_四半期!D6 -> 450 | C6: =KOKUSAI_四半期!H6 -> 0 | D6: =KOKUSAI_四半期!I6 -> 0 | E6: =四半期集計!D7 -> 0 | F6: =四半期集計!E7 -> 0 | G6: =四半期集計!F7 -> 0
A7: =四半期集計!A8 -> 24/3期 3Q | B7: =KOKUSAI_四半期!D7 -> 540 | C7: =KOKUSAI_四半期!H7 -> 0 | D7: =KOKUSAI_四半期!I7 -> 0 | E7: =四半期集計!D8 -> 0 | F7: =四半期集計!E8 -> 0 | G7: =四半期集計!F8 -> 0
A8: =四半期集計!A9 -> 24/3期 4Q | B8: =KOKUSAI_四半期!D8 -> 492 | C8: =KOKUSAI_四半期!H8 -> 0 | D8: =KOKUSAI_四半期!I8 -> 0 | E8: =四半期集計!D9 -> 0 | F8: =四半期集計!E9 -> 0 | G8: =四半期集計!F9 -> 0
A9: =四半期集計!A10 -> 25/3期 1Q | B9: =KOKUSAI_四半期!D9 -> 652 | C9: =KOKUSAI_四半期!H9 -> 0 | D9: =KOKUSAI_四半期!I9 -> 0 | E9: =四半期集計!D10 -> 0 | F9: =四半期集計!E10 -> 0 | G9: =四半期集計!F10 -> 0
A10: =四半期集計!A11 -> 25/3期 2Q | B10: =KOKUSAI_四半期!D10 -> 493 | C10: =KOKUSAI_四半期!H10 -> 0 | D10: =KOKUSAI_四半期!I10 -> 0 | E10: =四半期集計!D11 -> 0 | F10: =四半期集計!E11 -> 0 | G10: =四半期集計!F11 -> 0
A11: =四半期集計!A12 -> 25/3期 3Q | B11: =KOKUSAI_四半期!D11 -> 601 | C11: =KOKUSAI_四半期!H11 -> 0 | D11: =KOKUSAI_四半期!I11 -> 0 | E11: =四半期集計!D12 -> 0 | F11: =四半期集計!E12 -> 0 | G11: =四半期集計!F12 -> 0
A12: =四半期集計!A13 -> 25/3期 4Q | B12: =KOKUSAI_四半期!D12 -> 643 | C12: =KOKUSAI_四半期!H12 -> 0 | D12: =KOKUSAI_四半期!I12 -> 0 | E12: =四半期集計!D13 -> 0 | F12: =四半期集計!E13 -> 0 | G12: =四半期集計!F13 -> 0
A13: =四半期集計!A14 -> 26/3期 1Q | B13: =KOKUSAI_四半期!D13 -> 518 | C13: =KOKUSAI_四半期!H13 -> 0 | D13: =KOKUSAI_四半期!I13 -> 0 | E13: =四半期集計!D14 -> 0 | F13: =四半期集計!E14 -> 0 | G13: =四半期集計!F14 -> 0
A14: =四半期集計!A15 -> 26/3期 2Q | B14: =KOKUSAI_四半期!D14 -> 654 | C14: =KOKUSAI_四半期!H14 -> 0 | D14: =KOKUSAI_四半期!I14 -> 0 | E14: =四半期集計!D15 -> 0 | F14: =四半期集計!E15 -> 0 | G14: =四半期集計!F15 -> 0
A15: =四半期集計!A16 -> 26/3期 3Q | B15: =KOKUSAI_四半期!D15 -> 559 | C15: =KOKUSAI_四半期!H15 -> 0 | D15: =KOKUSAI_四半期!I15 -> 0 | E15: =四半期集計!D16 -> 0 | F15: =四半期集計!E16 -> 0 | G15: =四半期集計!F16 -> 0
A16: =四半期集計!A17 -> 26/3期 4Q | B16: =KOKUSAI_四半期!D16 -> 620 | C16: =KOKUSAI_四半期!H16 -> 0 | D16: =KOKUSAI_四半期!I16 -> 0 | E16: =四半期集計!D17 -> 0 | F16: =四半期集計!E17 -> 0 | G16: =四半期集計!F17 -> 0
A17: =四半期集計!A18 -> 27/3期 1Q | B17: =KOKUSAI_四半期!D17 -> 754 | C17: =KOKUSAI_四半期!H17 -> 0 | D17: =KOKUSAI_四半期!I17 -> 0 | E17: =四半期集計!D18 -> 0 | F17: =四半期集計!E18 -> 0 | G17: =四半期集計!F18 -> 0
B19: モデル | C19: 切片 a | D19: 傾き b | E19: R² | F19: LOOCV RMSE（億円）
B20: 単一：全社×世界
B21: 構造：中国地場×中国
B22: 構造：グローバル×中国以外
B23: 構造：全社（和）
B24: 比較：ランダムウォーク
A27: k=1（輸出が1か月先行）
A28: 四半期 | B28: 売上収益 | C28: 中国地場 | D28: グローバル | E28: 世界 | F28: 中国 | G28: 中国以外 | H28: 単一:予測 | I28: 単一:残差 | J28: 単一:h | K28: 単一:LOO残差 | L28: 中国地場:予測 | M28: 中国地場:残差 | N28: 中国地場:h | O28: グローバル:予測 | P28: グローバル:残差 | Q28: グローバル:h | R28: 構造:予測 | S28: 構造:残差 | T28: 構造:LOO残差
A29: =四半期集計!A7 -> 24/3期 2Q | B29: =KOKUSAI_四半期!D6 -> 450 | C29: =KOKUSAI_四半期!H6 -> 0 | D29: =KOKUSAI_四半期!I6 -> 0 | E29: =四半期集計!I7 -> 0 | F29: =四半期集計!J7 -> 0 | G29: =四半期集計!K7 -> 0
A30: =四半期集計!A8 -> 24/3期 3Q | B30: =KOKUSAI_四半期!D7 -> 540 | C30: =KOKUSAI_四半期!H7 -> 0 | D30: =KOKUSAI_四半期!I7 -> 0 | E30: =四半期集計!I8 -> 0 | F30: =四半期集計!J8 -> 0 | G30: =四半期集計!K8 -> 0
A31: =四半期集計!A9 -> 24/3期 4Q | B31: =KOKUSAI_四半期!D8 -> 492 | C31: =KOKUSAI_四半期!H8 -> 0 | D31: =KOKUSAI_四半期!I8 -> 0 | E31: =四半期集計!I9 -> 0 | F31: =四半期集計!J9 -> 0 | G31: =四半期集計!K9 -> 0
A32: =四半期集計!A10 -> 25/3期 1Q | B32: =KOKUSAI_四半期!D9 -> 652 | C32: =KOKUSAI_四半期!H9 -> 0 | D32: =KOKUSAI_四半期!I9 -> 0 | E32: =四半期集計!I10 -> 0 | F32: =四半期集計!J10 -> 0 | G32: =四半期集計!K10 -> 0
A33: =四半期集計!A11 -> 25/3期 2Q | B33: =KOKUSAI_四半期!D10 -> 493 | C33: =KOKUSAI_四半期!H10 -> 0 | D33: =KOKUSAI_四半期!I10 -> 0 | E33: =四半期集計!I11 -> 0 | F33: =四半期集計!J11 -> 0 | G33: =四半期集計!K11 -> 0
A34: =四半期集計!A12 -> 25/3期 3Q | B34: =KOKUSAI_四半期!D11 -> 601 | C34: =KOKUSAI_四半期!H11 -> 0 | D34: =KOKUSAI_四半期!I11 -> 0 | E34: =四半期集計!I12 -> 0 | F34: =四半期集計!J12 -> 0 | G34: =四半期集計!K12 -> 0
A35: =四半期集計!A13 -> 25/3期 4Q | B35: =KOKUSAI_四半期!D12 -> 643 | C35: =KOKUSAI_四半期!H12 -> 0 | D35: =KOKUSAI_四半期!I12 -> 0 | E35: =四半期集計!I13 -> 0 | F35: =四半期集計!J13 -> 0 | G35: =四半期集計!K13 -> 0
A36: =四半期集計!A14 -> 26/3期 1Q | B36: =KOKUSAI_四半期!D13 -> 518 | C36: =KOKUSAI_四半期!H13 -> 0 | D36: =KOKUSAI_四半期!I13 -> 0 | E36: =四半期集計!I14 -> 0 | F36: =四半期集計!J14 -> 0 | G36: =四半期集計!K14 -> 0
A37: =四半期集計!A15 -> 26/3期 2Q | B37: =KOKUSAI_四半期!D14 -> 654 | C37: =KOKUSAI_四半期!H14 -> 0 | D37: =KOKUSAI_四半期!I14 -> 0 | E37: =四半期集計!I15 -> 0 | F37: =四半期集計!J15 -> 0 | G37: =四半期集計!K15 -> 0
A38: =四半期集計!A16 -> 26/3期 3Q | B38: =KOKUSAI_四半期!D15 -> 559 | C38: =KOKUSAI_四半期!H15 -> 0 | D38: =KOKUSAI_四半期!I15 -> 0 | E38: =四半期集計!I16 -> 0 | F38: =四半期集計!J16 -> 0 | G38: =四半期集計!K16 -> 0
A39: =四半期集計!A17 -> 26/3期 4Q | B39: =KOKUSAI_四半期!D16 -> 620 | C39: =KOKUSAI_四半期!H16 -> 0 | D39: =KOKUSAI_四半期!I16 -> 0 | E39: =四半期集計!I17 -> 0 | F39: =四半期集計!J17 -> 0 | G39: =四半期集計!K17 -> 0
A40: =四半期集計!A18 -> 27/3期 1Q | B40: =KOKUSAI_四半期!D17 -> 754 | C40: =KOKUSAI_四半期!H17 -> 0 | D40: =KOKUSAI_四半期!I17 -> 0 | E40: =四半期集計!I18 -> 0 | F40: =四半期集計!J18 -> 0 | G40: =四半期集計!K18 -> 0
B42: モデル | C42: 切片 a | D42: 傾き b | E42: R² | F42: LOOCV RMSE（億円）
B43: 単一：全社×世界
B44: 構造：中国地場×中国
B45: 構造：グローバル×中国以外
...

Sheet ナウキャスト
A1: 27/3期2Q（2026年7-9月）売上収益のナウキャスト（億円）
A2: k=0は9月の輸出を季節比で推計（9月速報は10/21公表予定）。k=1は6-8月の実績だけで完結する。帯＝予測±LOOCV RMSE。
A4: ① 9月÷7-8月平均（過去の季節比）
A5: 年 | B5: 中国 | C5: 中国以外 | D5: 世界
A6: 2023
A7: 2024
A8: 2025
A9: 平均
A10: 最大
A12: ② 9月の季節比の前提（シナリオ） | G12: 2026年7-8月の輸出実績
A13: シナリオ | B13: 中国 | C13: 中国以外 | D13: 世界 | E13: 説明 | H13: 中国 | I13: 中国以外 | J13: 世界
A14: 低 | B14: 1 | C14: 1 | D14: 1 | E14: 9月＝7-8月平均（季節性なし） | G14: 7月
A15: 基準 | E15: 過去3年平均の季節比 | G15: 8月
A16: 高 | E16: 過去3年の最大の季節比 | G16: 合計
G17: 平均
A19: ③ k=0（7-8月実績＋9月推計）
A20: シナリオ | B20: 中国 7-9月 | C20: 中国以外 7-9月 | D20: 世界 7-9月 | E20: 構造:中国地場 | F20: 構造:グローバル | G20: 構造:全社 | H20: 帯 下限 | I20: 帯 上限 | J20: 単一:全社
A21: 低
A22: 基準
A23: 高
A25: ④ k=1（6-8月の実績のみ）
B26: 中国 6-8月 | C26: 中国以外 6-8月 | D26: 世界 6-8月 | E26: 構造:中国地場 | F26: 構造:グローバル | G26: 構造:全社 | H26: 帯 下限 | I26: 帯 上限 | J26: 単一:全社
A27: 実績
A29: ⑤ 会社計画との比較
A30: 上期（4-9月）売上収益計画（修正後） | D30: 1610
A31: 1Q実績
A32: 計画が示す2Q売上
A33: 構造モデル k=0 基準との差（計画−予測）
A34: 計画が示す実質シェア（2Q計画÷6-8月の世界輸出）
A35: 過去の実質シェア（k=1）最小／平均／最大
A37: ⑥ 計画達成に必要な9月の輸出（構造 k=0、基準シナリオの地域構成を維持）
A38: 基準シナリオの9月推計：中国
A39: 基準シナリオの9月推計：中国以外
A40: 9月を1倍にしたときの売上増分
A41: 必要な倍率
A42: 必要な9月の世界輸出（億円）
A43: 2025年9月の世界輸出（億円）
... A45: 参考：7月・8月の世界輸出の前年同月比

Sheet 出所・注記
A1: 出所・注記
A3: 【出所】
A4: 財務省 貿易統計 月次速報PDF（各月）: https://www.customs.go.jp/toukei/shinbun/trade-st/ （URLは速報_原データのG列）
A5: 財務省 貿易統計 2024年5月分 概要: https://www.customs.go.jp/toukei/shinbun/trade-st/gaiyo2024_05.pdf
A6: KOKUSAI ELECTRIC 25/3期 決算説明資料: https://finance-frontend-pc-dist.west.edge.storage-yahoo.jp/disclosure/20250513/20250513544797.pdf
A7: KOKUSAI ELECTRIC 26/3期 決算説明資料: https://finance.stockweather.co.jp/contents/dispPDF.aspx?disclosure=20260513527733
A8: 27/3期1Q実績（売上754億円、中国地場25％）: https://global-net.co.jp/archives/13621
A9: 27/3期上期計画1,610億円: https://finance.yahoo.co.jp/quote/6525.T/financials
A10: 伏木税関支署 2023年貿易概況: https://www.customs.go.jp/osaka/toukei/shosho/fushiki_2023nen.pdf
A12: 【注記】
A13: 1. 概況品「半導体等製造装置」はHS8486全体（FPD製造装置・部分品を含む）である。KOKUSAI固有の品目ではなく、同社は輸出全体の約4〜6％にあたる。
A14: 2. 速報値を使用している。翌年の前年比から逆算した値と当月速報値の差は、確認できた112組で最大0.7％（平均0.01％）である。
... A19: 7. 国内向け販売（JASM、Rapidus等）と海外生産分は輸出統計に現れない。
