Workbook

Sheet 手順書
B1: SPE輸入統計と企業売上の比較：Excelでの再現手順書
B2: まとめ | C2: 日本発の半導体製造装置の輸入額（台湾・韓国・EU・米国）を月次で集計し、3か月窓のQoQを企業の四半期QoQと相関させる。ラグ（シフト月）を変えて、輸入が企業売上に先行するか、同時か、遅行するかを見る。マクロは使わず、下記の関数だけで再現できる。
B3: 使用関数 | C3: SUMIFS、COUNTIFS、COUNT、SUM、INDEX、MATCH、MAX、LN、IFERROR、IF、AND、OR、ISNUMBER、SUMPRODUCT、CORREL
B4: 必要なもの | C4: Excel 2010以降（Excel 2007でも動作する関数のみ）。新しい関数（XLOOKUP、FILTER、LET等）は使っていない。
A6: 1 | B6: シート構成 | C6: 手順書／設定／四半期比較／月次集計／企業売上／ラグ走査_作業／ラグ相関／raw_月次輸入実績／raw_台湾月次。青字は入力値、黒字は数式。
A7: 2 | B7: 生データを貼る | C7: raw_月次輸入実績：A列＝月（例 2023-01-01、書式 yyyy-mm）、B列＝輸入地域（韓国／EU27／米国／中国）、C列＝HS6（文字列）、D列＝輸入額（通貨単位）、E列＝通貨、F列＝FPD除外フラグ。元ファイル「月次輸入実績」シートのK列（輸入額）をD列に貼る。
C8: F列の式（2行目）：=IF(C2="848630",0,1) ※FPD製造装置（848630）を除外するためのフラグ。行を追加したら下へコピーする。
C9: raw_台湾月次：A列＝年月、B列＝CCCコード（文字列）、C列＝分析用金額（USD）、D列＝利用状態。元ファイル「月次データ」シートのF列を貼る。台湾は4桁「8486」の合計行のみを使う（11桁の内訳と足すと二重計上になる）。
A10: 3 | B10: 設定する | C10: 設定!B3にEUR→USDの換算レート（初期値1.10）、設定!B4に比較用シフト月s（初期値3）を入れる。
A11: 4 | B11: 月次集計（地域別の月次合計） | C11: 月次集計!B2（韓国）の式：
C12: =IF(COUNTIFS(raw_月次輸入実績!$A$2:$A$20000,$A2,raw_月次輸入実績!$B$2:$B$20000,"韓国",raw_月次輸入実績!$F$2:$F$20000,1)=0,"",SUMIFS(raw_月次輸入実績!$D$2:$D$20000,raw_月次輸入実績!$A$2:$A$20000,$A2,raw_月次輸入実績!$B$2:$B$20000,"韓国",raw_月次輸入実績!$F$2:$F$20000,1))
C13: 要点：該当行が1件もない月は0ではなく空白にする（欠測を0にしない）。EU27・米国は"韓国"を"EU27"・"米国"に替える。
C14: 台湾（E2）：=IF(COUNTIFS(raw_台湾月次!$A$2:$A$20000,$A2,raw_台湾月次!$B$2:$B$20000,"8486",raw_台湾月次!$D$2:$D$20000,"利用可")=0,"",SUMIFS(raw_台湾月次!$C$2:$C$20000,raw_台湾月次!$A$2:$A$20000,$A2,raw_台湾月次!$B$2:$B$20000,"8486",raw_台湾月次!$D$2:$D$20000,"利用可"))
C15: EU27のUSD換算（F2）：=IF(C2="","",C2*設定!$B$3) ／ CORE3（G2）：=IF(COUNT(B2,E2,F2)=3,B2+E2+F2,"")
A16: 5 | B16: 3か月ローリング合計 | C16: 月次集計!H4（韓国_3M）：=IF(COUNT(B2:B4)=3,SUM(B2:B4),"") ※3か月のうち1か月でも欠けたら空白。台湾はE列、EUはF列、米国はD列、CORE3はG列を使う。
A17: 6 | B17: 企業売上を入力する | C17: 企業売上シートのB〜E列（暦四半期の売上、億円）に決算資料の値を入れる。3社合計（F列）：=IF(COUNT(B4,C4,E4)=3,B4+C4+E4,"") ／ QoQ（H5）：=IF(AND(ISNUMBER(B5),ISNUMBER(B4)),LN(B5/B4),"")
C18: 東京エレクトロン・SCREEN・KOKUSAIは決算期が3月で、四半期末が暦の3・6・9・12月と一致するため、そのまま暦四半期として扱える。
A19: 7 | B19: 輸入QoQをシフトして作る | C19: ラグ走査_作業の各列は、地域×シフト月sごとの輸入QoQである。四半期末の月番号e（B列）に対して次の式を使う。
C20: =IF(OR($B4+C$2-3<1,$B4+C$2>設定!$B$5),"",IFERROR(LN(INDEX(月次集計!$H$2:$H$45,$B4+C$2)/INDEX(月次集計!$H$2:$H$45,$B4+C$2-3)),""))
C21: 意味：月次の3M合計のうち、「eにsを足した月」までの窓の合計を、その3か月前の窓の合計で割り、LNを取る。s＝0は暦四半期そのもの、s＝3は次の四半期、s＝−3は前の四半期に相当する。
A22: 8 | B22: 相関を計算する | C22: ラグ相関シートB4：=IF(SUMPRODUCT(--ISNUMBER(x),--ISNUMBER(y))<6,"",IFERROR(CORREL(x,y),"")) x＝ラグ走査_作業の該当列（4〜17行）、y＝企業売上のQoQ列（4〜17行）。
C23: ペアの片方が空白の四半期はCORRELが自動的に除外する。使えた四半期数（N）は同シート20行目以降に表示され、6未満なら相関を出さない。
A24: 9 | B24: 結果の読み方 | C24: 負のシフトで相関が高い＝輸入が企業売上に先行（フォーキャスト向き）。0付近＝同時（ナウキャスト向き）。正のシフトで高い＝輸入が遅行（企業売上の確認用）。ラグ相関シートの35〜36行目に最大相関のシフトと値を出す。
C25: 注意：Nは11〜12四半期と小さく、シフトを13通り走査しているため、最大値には偶然の相関が含まれる。Python版の置換検定では、台湾×東京エレクトロンのp値は0.004（QoQ）だった。この検定はExcelには入れていない。
A26: 10 | B26: 四半期比較で個別に確認する | C26: 設定!B4のsを変えると、四半期比較シートの輸入QoQ・企業QoQ・相関が更新される。
A27: 11 | B27: データを更新する | C27: (a) raw_月次輸入実績、raw_台湾月次の末尾に新しい月の行を追加する（範囲は20000行まで対応）。(b) 月次集計の最終行を下へコピーし、月の列に翌月を入れる。(c) 月次集計の参照範囲$2:$45と設定!B5のCOUNT範囲を広げる。(d) 企業売上に新しい四半期の行を追加し、ラグ走査_作業に行と月番号e（3ずつ増える）を追加する。
A28: 12 | B28: 注意点 | C28: 輸入データは取得時点の改訂値で、初回公表値ではない。EUR換算は固定レート。米国は一部の月が欠測。中国は2024年12月までの収録のため月次集計に含めていない。輸入額は企業売上ではなく、国別・品目別の統計である。

Sheet 設定
A1: 設定
A3: EUR→USD 固定換算レート | B3: 1.1 | C3: EU輸入額をUSDに揃えるための仮定値。四半期ごとの平均為替は使っていない。
A4: 比較用シフト月 s | B4: 3 | C4: 四半期比較シートで使う。正の値は輸入の3か月窓を企業の四半期末より後ろへずらす（輸入が遅行）。負は先行。
A5: 月次データの行数 | B5: =COUNT(月次集計!A2:A45) -> 44 | C5: 月次集計シートの月の数。月を追加したら範囲も広げる。
A7: 青字は入力値、黒字は数式である。

Sheet 四半期比較
A1: 四半期比較（設定シートのシフト月sで表示）
A2: 現在のs | B2: =設定!B4 -> 3
A4: 四半期 | B4: 韓国QoQ | C4: 台湾QoQ | D4: EU27QoQ | E4: 米国QoQ | F4: CORE3 QoQ | G4: TEL QoQ | H4: SCREEN QoQ | I4: KOKUSAI QoQ | J4: 3社合計QoQ
A5: 2023Q1 | B5: =IF(OR(ラグ走査_作業!$B4+$B$2-3<1,ラグ走査_作業!$B4+$B$2>設定!$B$5),"",IFERROR(LN(INDEX(月次集計!$H$2:$H$45,ラグ走査_作業!$B4+$B$2)/INDEX(月次集計!$H$2:$H$45,ラグ走査_作業!$B4+$B$2-3)),"")) -> 0.053582567 | C5: =IF(OR(ラグ走査_作業!$B4+$B$2-3<1,ラグ走査_作業!$B4+$B$2>設定!$B$5),"",IFERROR(LN(INDEX(月次集計!$I$2:$I$45,ラグ走査_作業!$B4+$B$2)/INDEX(月次集計!$I$2:$I$45,ラグ走査_作業!$B4+$B$2-3)),"")) -> -0.29291864 | D5: =IF(OR(ラグ走査_作業!$B4+$B$2-3<1,ラグ走査_作業!$B4+$B$2>設定!$B$5),"",IFERROR(LN(INDEX(月次集計!$J$2:$J$45,ラグ走査_作業!$B4+$B$2)/INDEX(月次集計!$J$2:$J$45,ラグ走査_作業!$B4+$B$2-3)),"")) -> 0.442155 | E5: =IF(OR(ラグ走査_作業!$B4+$B$2-3<1,ラグ走査_作業!$B4+$B$2>設定!$B$5),"",IFERROR(LN(INDEX(月次集計!$K$2:$K$45,ラグ走査_作業!$B4+$B$2)/INDEX(月次集計!$K$2:$K$45,ラグ走査_作業!$B4+$B$2-3)),"")) -> 0.056795026 | F5: =IF(OR(ラグ走査_作業!$B4+$B$2-3<1,ラグ走査_作業!$B4+$B$2>設定!$B$5),"",IFERROR(LN(INDEX(月次集計!$L$2:$L$45,ラグ走査_作業!$B4+$B$2)/INDEX(月次集計!$L$2:$L$45,ラグ走査_作業!$B4+$B$2-3)),"")) -> -0.0024289034 | G5: =IF(ISNUMBER(企業売上!H4),企業売上!H4,"") | H5: =IF(ISNUMBER(企業売上!I4),企業売上!I4,"") | I5: =IF(ISNUMBER(企業売上!J4),企業売上!J4,"") | J5: =IF(ISNUMBER(企業売上!K4),企業売上!K4,"")
A6: 2023Q2 | B6: =IF(OR(ラグ走査_作業!$B5+$B$2-3<1,ラグ走査_作業!$B5+$B$2>設定!$B$5),"",IFERROR(LN(INDEX(月次集計!$H$2:$H$45,ラグ走査_作業!$B5+$B$2)/INDEX(月次集計!$H$2:$H$45,ラグ走査_作業!$B5+$B$2-3)),"")) -> -0.25966925 | C6: =IF(OR(ラグ走査_作業!$B5+$B$2-3<1,ラグ走査_作業!$B5+$B$2>設定!$B$5),"",IFERROR(LN(INDEX(月次集計!$I$2:$I$45,ラグ走査_作業!$B5+$B$2)/INDEX(月次集計!$I$2:$I$45,ラグ走査_作業!$B5+$B$2-3)),"")) -> -0.57386264 | D6: =IF(OR(ラグ走査_作業!$B5+$B$2-3<1,ラグ走査_作業!$B5+$B$2>設定!$B$5),"",IFERROR(LN(INDEX(月次集計!$J$2:$J$45,ラグ走査_作業!$B5+$B$2)/INDEX(月次集計!$J$2:$J$45,ラグ走査_作業!$B5+$B$2-3)),"")) -> -0.59726621 | E6: =IF(OR(ラグ走査_作業!$B5+$B$2-3<1,ラグ走査_作業!$B5+$B$2>設定!$B$5),"",IFERROR(LN(INDEX(月次集計!$K$2:$K$45,ラグ走査_作業!$B5+$B$2)/INDEX(月次集計!$K$2:$K$45,ラグ走査_作業!$B5+$B$2-3)),"")) | F6: =IF(OR(ラグ走査_作業!$B5+$B$2-3<1,ラグ走査_作業!$B5+$B$2>設定!$B$5),"",IFERROR(LN(INDEX(月次集計!$L$2:$L$45,ラグ走査_作業!$B5+$B$2)/INDEX(月次集計!$L$2:$L$45,ラグ走査_作業!$B5+$B$2-3)),"")) -> -0.44265943 | G6: =IF(ISNUMBER(企業売上!H5),企業売上!H5,"") -> -0.35422108 | H6: =IF(ISNUMBER(企業売上!I5),企業売上!I5,"") -> -0.23114359 | I6: =IF(ISNUMBER(企業売上!J5),企業売上!J5,"") | J6: =IF(ISNUMBER(企業売上!K5),企業売上!K5,"")
A7: 2023Q3 | B7: =IF(OR(ラグ走査_作業!$B6+$B$2-3<1,ラグ走査_作業!$B6+$B$2>設定!$B$5),"",IFERROR(LN(INDEX(月次集計!$H$2:$H$45,ラグ走査_作業!$B6+$B$2)/INDEX(月次集計!$H$2:$H$45,ラグ走査_作業!$B6+$B$2-3)),"")) -> -0.13604851 | C7: =IF(OR(ラグ走査_作業!$B6+$B$2-3<1,ラグ走査_作業!$B6+$B$2>設定!$B$5),"",IFERROR(LN(INDEX(月次集計!$I$2:$I$45,ラグ走査_作業!$B6+$B$2)/INDEX(月次集計!$I$2:$I$45,ラグ走査_作業!$B6+$B$2-3)),"")) -> 0.194051 | D7: =IF(OR(ラグ走査_作業!$B6+$B$2-3<1,ラグ走査_作業!$B6+$B$2>設定!$B$5),"",IFERROR(LN(INDEX(月次集計!$J$2:$J$45,ラグ走査_作業!$B6+$B$2)/INDEX(月次集計!$J$2:$J$45,ラグ走査_作業!$B6+$B$2-3)),"")) -> -0.26273573 | E7: =IF(OR(ラグ走査_作業!$B6+$B$2-3<1,ラグ走査_作業!$B6+$B$2>設定!$B$5),"",IFERROR(LN(INDEX(月次集計!$K$2:$K$45,ラグ走査_作業!$B6+$B$2)/INDEX(月次集計!$K$2:$K$45,ラグ走査_作業!$B6+$B$2-3)),"")) | F7: =IF(OR(ラグ走査_作業!$B6+$B$2-3<1,ラグ走査_作業!$B6+$B$2>設定!$B$5),"",IFERROR(LN(INDEX(月次集計!$L$2:$L$45,ラグ走査_作業!$B6+$B$2)/INDEX(月次集計!$L$2:$L$45,ラグ走査_作業!$B6+$B$2-3)),"")) -> -0.049143958 | G7: =IF(ISNUMBER(企業売上!H6),企業売上!H6,"") -> 0.088159556 | H7: =IF(ISNUMBER(企業売上!I6),企業売上!I6,"") -> 0.21507899 | I7: =IF(ISNUMBER(企業売上!J6),企業売上!J6,"") -> 0.31928741 | J7: =IF(ISNUMBER(企業売上!K6),企業売上!K6,"") -> 0.12925221
A8: 2023Q4 | B8: =IF(OR(ラグ走査_作業!$B7+$B$2-3<1,ラグ走査_作業!$B7+$B$2>設定!$B$5),"",IFERROR(LN(INDEX(月次集計!$H$2:$H$45,ラグ走査_作業!$B7+$B$2)/INDEX(月次集計!$H$2:$H$45,ラグ走査_作業!$B7+$B$2-3)),"")) -> 0.31613837 | C8: =IF(OR(ラグ走査_作業!$B7+$B$2-3<1,ラグ走査_作業!$B7+$B$2>設定!$B$5),"",IFERROR(LN(INDEX(月次集計!$I$2:$I$45,ラグ走査_作業!$B7+$B$2)/INDEX(月次集計!$I$2:$I$45,ラグ走査_作業!$B7+$B$2-3)),"")) -> 0.021462368 | D8: =IF(OR(ラグ走査_作業!$B7+$B$2-3<1,ラグ走査_作業!$B7+$B$2>設定!$B$5),"",IFERROR(LN(INDEX(月次集計!$J$2:$J$45,ラグ走査_作業!$B7+$B$2)/INDEX(月次集計!$J$2:$J$45,ラグ走査_作業!$B7+$B$2-3)),"")) -> 0.27642101 | E8: =IF(OR(ラグ走査_作業!$B7+$B$2-3<1,ラグ走査_作業!$B7+$B$2>設定!$B$5),"",IFERROR(LN(INDEX(月次集計!$K$2:$K$45,ラグ走査_作業!$B7+$B$2)/INDEX(月次集計!$K$2:$K$45,ラグ走査_作業!$B7+$B$2-3)),"")) -> -0.049406848 | F8: =IF(OR(ラグ走査_作業!$B7+$B$2-3<1,ラグ走査_作業!$B7+$B$2>設定!$B$5),"",IFERROR(LN(INDEX(月次集計!$L$2:$L$45,ラグ走査_作業!$B7+$B$2)/INDEX(月次集計!$L$2:$L$45,ラグ走査_作業!$B7+$B$2-3)),"")) -> 0.20544407 | G8: =IF(ISNUMBER(企業売上!H7),企業売上!H7,"") -> 0.080366315 | H8: =IF(ISNUMBER(企業売上!I7),企業売上!I7,"") -> 0.0080645598 | I8: =IF(ISNUMBER(企業売上!J7),企業売上!J7,"") -> 0.18232156 | J8: =IF(ISNUMBER(企業売上!K7),企業売上!K7,"") -> 0.074000159
A9: 2024Q1 | B9: =IF(OR(ラグ走査_作業!$B8+$B$2-3<1,ラグ走査_作業!$B8+$B$2>設定!$B$5),"",IFERROR(LN(INDEX(月次集計!$H$2:$H$45,ラグ走査_作業!$B8+$B$2)/INDEX(月次集計!$H$2:$H$45,ラグ走査_作業!$B8+$B$2-3)),"")) -> -0.18270322 | C9: =IF(OR(ラグ走査_作業!$B8+$B$2-3<1,ラグ走査_作業!$B8+$B$2>設定!$B$5),"",IFERROR(LN(INDEX(月次集計!$I$2:$I$45,ラグ走査_作業!$B8+$B$2)/INDEX(月次集計!$I$2:$I$45,ラグ走査_作業!$B8+$B$2-3)),"")) -> 0.37657784 | D9: =IF(OR(ラグ走査_作業!$B8+$B$2-3<1,ラグ走査_作業!$B8+$B$2>設定!$B$5),"",IFERROR(LN(INDEX(月次集計!$J$2:$J$45,ラグ走査_作業!$B8+$B$2)/INDEX(月次集計!$J$2:$J$45,ラグ走査_作業!$B8+$B$2-3)),"")) -> -0.35434777 | E9: =IF(OR(ラグ走査_作業!$B8+$B$2-3<1,ラグ走査_作業!$B8+$B$2>設定!$B$5),"",IFERROR(LN(INDEX(月次集計!$K$2:$K$45,ラグ走査_作業!$B8+$B$2)/INDEX(月次集計!$K$2:$K$45,ラグ走査_作業!$B8+$B$2-3)),"")) -> 0.082035989 | F9: =IF(OR(ラグ走査_作業!$B8+$B$2-3<1,ラグ走査_作業!$B8+$B$2>設定!$B$5),"",IFERROR(LN(INDEX(月次集計!$L$2:$L$45,ラグ走査_作業!$B8+$B$2)/INDEX(月次集計!$L$2:$L$45,ラグ走査_作業!$B8+$B$2-3)),"")) -> 0.0063762095 | G9: =IF(ISNUMBER(企業売上!H8),企業売上!H8,"") -> 0.16579225 | H9: =IF(ISNUMBER(企業売上!I8),企業売上!I8,"") -> 0.23194009 | I9: =IF(ISNUMBER(企業売上!J8),企業売上!J8,"") -> -0.093090423 | J9: =IF(ISNUMBER(企業売上!K8),企業売上!K8,"") -> 0.15985224
A10: 2024Q2 | B10: =IF(OR(ラグ走査_作業!$B9+$B$2-3<1,ラグ走査_作業!$B9+$B$2>設定!$B$5),"",IFERROR(LN(INDEX(月次集計!$H$2:$H$45,ラグ走査_作業!$B9+$B$2)/INDEX(月次集計!$H$2:$H$45,ラグ走査_作業!$B9+$B$2-3)),"")) -> 0.24786832 | C10: =IF(OR(ラグ走査_作業!$B9+$B$2-3<1,ラグ走査_作業!$B9+$B$2>設定!$B$5),"",IFERROR(LN(INDEX(月次集計!$I$2:$I$45,ラグ走査_作業!$B9+$B$2)/INDEX(月次集計!$I$2:$I$45,ラグ走査_作業!$B9+$B$2-3)),"")) -> 0.036487142 | D10: =IF(OR(ラグ走査_作業!$B9+$B$2-3<1,ラグ走査_作業!$B9+$B$2>設定!$B$5),"",IFERROR(LN(INDEX(月次集計!$J$2:$J$45,ラグ走査_作業!$B9+$B$2)/INDEX(月次集計!$J$2:$J$45,ラグ走査_作業!$B9+$B$2-3)),"")) -> 0.055257611 | E10: =IF(OR(ラグ走査_作業!$B9+$B$2-3<1,ラグ走査_作業!$B9+$B$2>設定!$B$5),"",IFERROR(LN(INDEX(月次集計!$K$2:$K$45,ラグ走査_作業!$B9+$B$2)/INDEX(月次集計!$K$2:$K$45,ラグ走査_作業!$B9+$B$2-3)),"")) -> 0.14452858 | F10: =IF(OR(ラグ走査_作業!$B9+$B$2-3<1,ラグ走査_作業!$B9+$B$2>設定!$B$5),"",IFERROR(LN(INDEX(月次集計!$L$2:$L$45,ラグ走査_作業!$B9+$B$2)/INDEX(月次集計!$L$2:$L$45,ラグ走査_作業!$B9+$B$2-3)),"")) -> 0.1295057 | G10: =IF(ISNUMBER(企業売上!H9),企業売上!H9,"") -> 0.014153747 | H10: =IF(ISNUMBER(企業売上!I9),企業売上!I9,"") -> -0.15691458 | I10: =IF(ISNUMBER(企業売上!J9),企業売上!J9,"") -> 0.28156585 | J10: =IF(ISNUMBER(企業売上!K9),企業売上!K9,"") -> 0.0013264361
A11: 2024Q3 | B11: =IF(OR(ラグ走査_作業!$B10+$B$2-3<1,ラグ走査_作業!$B10+$B$2>設定!$B$5),"",IFERROR(LN(INDEX(月次集計!$H$2:$H$45,ラグ走査_作業!$B10+$B$2)/INDEX(月次集計!$H$2:$H$45,ラグ走査_作業!$B10+$B$2-3)),"")) -> 0.17354617 | C11: =IF(OR(ラグ走査_作業!$B10+$B$2-3<1,ラグ走査_作業!$B10+$B$2>設定!$B$5),"",IFERROR(LN(INDEX(月次集計!$I$2:$I$45,ラグ走査_作業!$B10+$B$2)/INDEX(月次集計!$I$2:$I$45,ラグ走査_作業!$B10+$B$2-3)),"")) -> 0.19204575 | D11: =IF(OR(ラグ走査_作業!$B10+$B$2-3<1,ラグ走査_作業!$B10+$B$2>設定!$B$5),"",IFERROR(LN(INDEX(月次集計!$J$2:$J$45,ラグ走査_作業!$B10+$B$2)/INDEX(月次集計!$J$2:$J$45,ラグ走査_作業!$B10+$B$2-3)),"")) -> -0.11898907 | E11: =IF(OR(ラグ走査_作業!$B10+$B$2-3<1,ラグ走査_作業!$B10+$B$2>設定!$B$5),"",IFERROR(LN(INDEX(月次集計!$K$2:$K$45,ラグ走査_作業!$B10+$B$2)/INDEX(月次集計!$K$2:$K$45,ラグ走査_作業!$B10+$B$2-3)),"")) -> 0.24970646 | F11: =IF(OR(ラグ走査_作業!$B10+$B$2-3<1,ラグ走査_作業!$B10+$B$2>設定!$B$5),"",IFERROR(LN(INDEX(月次集計!$L$2:$L$45,ラグ走査_作業!$B10+$B$2)/INDEX(月次集計!$L$2:$L$45,ラグ走査_作業!$B10+$B$2-3)),"")) -> 0.14921647 | G11: =IF(ISNUMBER(企業売上!H10),企業売上!H10,"") -> 0.020508967 | H11: =IF(ISNUMBER(企業売上!I10),企業売上!I10,"") -> 0.064212462 | I11: =IF(ISNUMBER(企業売上!J10),企業売上!J10,"") -> -0.27953539 | J11: =IF(ISNUMBER(企業売上!K10),企業売上!K10,"") -> 0.0059472851
A12: 2024Q4 | B12: =IF(OR(ラグ走査_作業!$B11+$B$2-3<1,ラグ走査_作業!$B11+$B$2>設定!$B$5),"",IFERROR(LN(INDEX(月次集計!$H$2:$H$45,ラグ走査_作業!$B11+$B$2)/INDEX(月次集計!$H$2:$H$45,ラグ走査_作業!$B11+$B$2-3)),"")) -> 0.11870534 | C12: =IF(OR(ラグ走査_作業!$B11+$B$2-3<1,ラグ走査_作業!$B11+$B$2>設定!$B$5),"",IFERROR(LN(INDEX(月次集計!$I$2:$I$45,ラグ走査_作業!$B11+$B$2)/INDEX(月次集計!$I$2:$I$45,ラグ走査_作業!$B11+$B$2-3)),"")) -> 0.25045359 | D12: =IF(OR(ラグ走査_作業!$B11+$B$2-3<1,ラグ走査_作業!$B11+$B$2>設定!$B$5),"",IFERROR(LN(INDEX(月次集計!$J$2:$J$45,ラグ走査_作業!$B11+$B$2)/INDEX(月次集計!$J$2:$J$45,ラグ走査_作業!$B11+$B$2-3)),"")) -> -0.013987463 | E12: =IF(OR(ラグ走査_作業!$B11+$B$2-3<1,ラグ走査_作業!$B11+$B$2>設定!$B$5),"",IFERROR(LN(INDEX(月次集計!$K$2:$K$45,ラグ走査_作業!$B11+$B$2)/INDEX(月次集計!$K$2:$K$45,ラグ走査_作業!$B11+$B$2-3)),"")) -> -0.41887397 | F12: =IF(OR(ラグ走査_作業!$B11+$B$2-3<1,ラグ走査_作業!$B11+$B$2>設定!$B$5),"",IFERROR(LN(INDEX(月次集計!$L$2:$L$45,ラグ走査_作業!$B11+$B$2)/INDEX(月次集計!$L$2:$L$45,ラグ走査_作業!$B11+$B$2-3)),"")) -> 0.16734406 | G12: =IF(ISNUMBER(企業売上!H11),企業売上!H11,"") -> 0.1443945 | H12: =IF(ISNUMBER(企業売上!I11),企業売上!I11,"") -> 0.24320649 | I12: =IF(ISNUMBER(企業売上!J11),企業売上!J11,"") -> 0.19808576 | J12: =IF(ISNUMBER(企業売上!K11),企業売上!K11,"") -> 0.16729732
A13: 2025Q1 | B13: =IF(OR(ラグ走査_作業!$B12+$B$2-3<1,ラグ走査_作業!$B12+$B$2>設定!$B$5),"",IFERROR(LN(INDEX(月次集計!$H$2:$H$45,ラグ走査_作業!$B12+$B$2)/INDEX(月次集計!$H$2:$H$45,ラグ走査_作業!$B12+$B$2-3)),"")) -> -0.18003483 | C13: =IF(OR(ラグ走査_作業!$B12+$B$2-3<1,ラグ走査_作業!$B12+$B$2>設定!$B$5),"",IFERROR(LN(INDEX(月次集計!$I$2:$I$45,ラグ走査_作業!$B12+$B$2)/INDEX(月次集計!$I$2:$I$45,ラグ走査_作業!$B12+$B$2-3)),"")) -> 0.032947386 | D13: =IF(OR(ラグ走査_作業!$B12+$B$2-3<1,ラグ走査_作業!$B12+$B$2>設定!$B$5),"",IFERROR(LN(INDEX(月次集計!$J$2:$J$45,ラグ走査_作業!$B12+$B$2)/INDEX(月次集計!$J$2:$J$45,ラグ走査_作業!$B12+$B$2-3)),"")) -> -0.21682001 | E13: =IF(OR(ラグ走査_作業!$B12+$B$2-3<1,ラグ走査_作業!$B12+$B$2>設定!$B$5),"",IFERROR(LN(INDEX(月次集計!$K$2:$K$45,ラグ走査_作業!$B12+$B$2)/INDEX(月次集計!$K$2:$K$45,ラグ走査_作業!$B12+$B$2-3)),"")) -> -0.10925416 | F13: =IF(OR(ラグ走査_作業!$B12+$B$2-3<1,ラグ走査_作業!$B12+$B$2>設定!$B$5),"",IFERROR(LN(INDEX(月次集計!$L$2:$L$45,ラグ走査_作業!$B12+$B$2)/INDEX(月次集計!$L$2:$L$45,ラグ走査_作業!$B12+$B$2-3)),"")) -> -0.075425684 | G13: =IF(ISNUMBER(企業売上!H12),企業売上!H12,"") -> 0.0013741509 | H13: =IF(ISNUMBER(企業売上!I12),企業売上!I12,"") -> -0.098988168 | I13: =IF(ISNUMBER(企業売上!J12),企業売上!J12,"") -> 0.06754979 | J13: =IF(ISNUMBER(企業売上!K12),企業売上!K12,"") -> -0.013579694
A14: 2025Q2 | B14: =IF(OR(ラグ走査_作業!$B13+$B$2-3<1,ラグ走査_作業!$B13+$B$2>設定!$B$5),"",IFERROR(LN(INDEX(月次集計!$H$2:$H$45,ラグ走査_作業!$B13+$B$2)/INDEX(月次集計!$H$2:$H$45,ラグ走査_作業!$B13+$B$2-3)),"")) -> -0.093951286 | C14: =IF(OR(ラグ走査_作業!$B13+$B$2-3<1,ラグ走査_作業!$B13+$B$2>設定!$B$5),"",IFERROR(LN(INDEX(月次集計!$I$2:$I$45,ラグ走査_作業!$B13+$B$2)/INDEX(月次集計!$I$2:$I$45,ラグ走査_作業!$B13+$B$2-3)),"")) -> -0.24906273 | D14: =IF(OR(ラグ走査_作業!$B13+$B$2-3<1,ラグ走査_作業!$B13+$B$2>設定!$B$5),"",IFERROR(LN(INDEX(月次集計!$J$2:$J$45,ラグ走査_作業!$B13+$B$2)/INDEX(月次集計!$J$2:$J$45,ラグ走査_作業!$B13+$B$2-3)),"")) -> -0.3267691 | E14: =IF(OR(ラグ走査_作業!$B13+$B$2-3<1,ラグ走査_作業!$B13+$B$2>設定!$B$5),"",IFERROR(LN(INDEX(月次集計!$K$2:$K$45,ラグ走査_作業!$B13+$B$2)/INDEX(月次集計!$K$2:$K$45,ラグ走査_作業!$B13+$B$2-3)),"")) -> -0.57081066 | F14: =IF(OR(ラグ走査_作業!$B13+$B$2-3<1,ラグ走査_作業!$B13+$B$2>設定!$B$5),"",IFERROR(LN(INDEX(月次集計!$L$2:$L$45,ラグ走査_作業!$B13+$B$2)/INDEX(月次集計!$L$2:$L$45,ラグ走査_作業!$B13+$B$2-3)),"")) -> -0.18915025 | G14: =IF(ISNUMBER(企業売上!H13),企業売上!H13,"") -> -0.17623696 | H14: =IF(ISNUMBER(企業売上!I13),企業売上!I13,"") -> -0.19731544 | I14: =IF(ISNUMBER(企業売上!J13),企業売上!J13,"") -> -0.21616948 | J14: =IF(ISNUMBER(企業売上!K13),企業売上!K13,"") -> -0.18299975
A15: 2025Q3 | B15: =IF(OR(ラグ走査_作業!$B14+$B$2-3<1,ラグ走査_作業!$B14+$B$2>設定!$B$5),"",IFERROR(LN(INDEX(月次集計!$H$2:$H$45,ラグ走査_作業!$B14+$B$2)/INDEX(月次集計!$H$2:$H$45,ラグ走査_作業!$B14+$B$2-3)),"")) -> 0.14598239 | C15: =IF(OR(ラグ走査_作業!$B14+$B$2-3<1,ラグ走査_作業!$B14+$B$2>設定!$B$5),"",IFERROR(LN(INDEX(月次集計!$I$2:$I$45,ラグ走査_作業!$B14+$B$2)/INDEX(月次集計!$I$2:$I$45,ラグ走査_作業!$B14+$B$2-3)),"")) -> 0.15175216 | D15: =IF(OR(ラグ走査_作業!$B14+$B$2-3<1,ラグ走査_作業!$B14+$B$2>設定!$B$5),"",IFERROR(LN(INDEX(月次集計!$J$2:$J$45,ラグ走査_作業!$B14+$B$2)/INDEX(月次集計!$J$2:$J$45,ラグ走査_作業!$B14+$B$2-3)),"")) -> 0.34689065 | E15: =IF(OR(ラグ走査_作業!$B14+$B$2-3<1,ラグ走査_作業!$B14+$B$2>設定!$B$5),"",IFERROR(LN(INDEX(月次集計!$K$2:$K$45,ラグ走査_作業!$B14+$B$2)/INDEX(月次集計!$K$2:$K$45,ラグ走査_作業!$B14+$B$2-3)),"")) | F15: =IF(OR(ラグ走査_作業!$B14+$B$2-3<1,ラグ走査_作業!$B14+$B$2>設定!$B$5),"",IFERROR(LN(INDEX(月次集計!$L$2:$L$45,ラグ走査_作業!$B14+$B$2)/INDEX(月次集計!$L$2:$L$45,ラグ走査_作業!$B14+$B$2-3)),"")) -> 0.16224545 | G15: =IF(ISNUMBER(企業売上!H14),企業売上!H14,"") -> 0.13671105 | H15: =IF(ISNUMBER(企業売上!I14),企業売上!I14,"") -> 0.020423759 | I15: =IF(ISNUMBER(企業売上!J14),企業売上!J14,"") -> 0.23313211 | J15: =IF(ISNUMBER(企業売上!K14),企業売上!K14,"") -> 0.1235256
A16: 2025Q4 | B16: =IF(OR(ラグ走査_作業!$B15+$B$2-3<1,ラグ走査_作業!$B15+$B$2>設定!$B$5),"",IFERROR(LN(INDEX(月次集計!$H$2:$H$45,ラグ走査_作業!$B15+$B$2)/INDEX(月次集計!$H$2:$H$45,ラグ走査_作業!$B15+$B$2-3)),"")) -> 0.2068552 | C16: =IF(OR(ラグ走査_作業!$B15+$B$2-3<1,ラグ走査_作業!$B15+$B$2>設定!$B$5),"",IFERROR(LN(INDEX(月次集計!$I$2:$I$45,ラグ走査_作業!$B15+$B$2)/INDEX(月次集計!$I$2:$I$45,ラグ走査_作業!$B15+$B$2-3)),"")) -> 0.040798408 | D16: =IF(OR(ラグ走査_作業!$B15+$B$2-3<1,ラグ走査_作業!$B15+$B$2>設定!$B$5),"",IFERROR(LN(INDEX(月次集計!$J$2:$J$45,ラグ走査_作業!$B15+$B$2)/INDEX(月次集計!$J$2:$J$45,ラグ走査_作業!$B15+$B$2-3)),"")) -> 0.4458411 | E16: =IF(OR(ラグ走査_作業!$B15+$B$2-3<1,ラグ走査_作業!$B15+$B$2>設定!$B$5),"",IFERROR(LN(INDEX(月次集計!$K$2:$K$45,ラグ走査_作業!$B15+$B$2)/INDEX(月次集計!$K$2:$K$45,ラグ走査_作業!$B15+$B$2-3)),"")) | F16: =IF(OR(ラグ走査_作業!$B15+$B$2-3<1,ラグ走査_作業!$B15+$B$2>設定!$B$5),"",IFERROR(LN(INDEX(月次集計!$L$2:$L$45,ラグ走査_作業!$B15+$B$2)/INDEX(月次集計!$L$2:$L$45,ラグ走査_作業!$B15+$B$2-3)),"")) -> 0.14914874 | G16: =IF(ISNUMBER(企業売上!H15),企業売上!H15,"") -> -0.13217177 | H16: =IF(ISNUMBER(企業売上!I15),企業売上!I15,"") -> 0.086409511 | I16: =IF(ISNUMBER(企業売上!J15),企業売上!J15,"") -> -0.15695788 | J16: =IF(ISNUMBER(企業売上!K15),企業売上!K15,"") -> -0.094243475
... A18: 2026Q2 | B18: =IF(OR(ラグ走査_作業!$B17+$B$2-3<1,ラグ走査_作業!$B17+$B$2>設定!$B$5),"",IFERROR(LN(INDEX(月次集計!$H$2:$H$45,ラグ走査_作業!$B17+$B$2)/INDEX(月次集計!$H$2:$H$45,ラグ走査_作業!$B17+$B$2-3)),"")) | C18: =IF(OR(ラグ走査_作業!$B17+$B$2-3<1,ラグ走査_作業!$B17+$B$2>設定!$B$5),"",IFERROR(LN(INDEX(月次集計!$I$2:$I$45,ラグ走査_作業!$B17+$B$2)/INDEX(月次集計!$I$2:$I$45,ラグ走査_作業!$B17+$B$2-3)),"")) | D18: =IF(OR(ラグ走査_作業!$B17+$B$2-3<1,ラグ走査_作業!$B17+$B$2>設定!$B$5),"",IFERROR(LN(INDEX(月次集計!$J$2:$J$45,ラグ走査_作業!$B17+$B$2)/INDEX(月次集計!$J$2:$J$45,ラグ走査_作業!$B17+$B$2-3)),"")) | E18: =IF(OR(ラグ走査_作業!$B17+$B$2-3<1,ラグ走査_作業!$B17+$B$2>設定!$B$5),"",IFERROR(LN(INDEX(月次集計!$K$2:$K$45,ラグ走査_作業!$B17+$B$2)/INDEX(月次集計!$K$2:$K$45,ラグ走査_作業!$B17+$B$2-3)),"")) | F18: =IF(OR(ラグ走査_作業!$B17+$B$2-3<1,ラグ走査_作業!$B17+$B$2>設定!$B$5),"",IFERROR(LN(INDEX(月次集計!$L$2:$L$45,ラグ走査_作業!$B17+$B$2)/INDEX(月次集計!$L$2:$L$45,ラグ走査_作業!$B17+$B$2-3)),"")) | G18: =IF(ISNUMBER(企業売上!H17),企業売上!H17,"") -> 0.028393293 | H18: =IF(ISNUMBER(企業売上!I17),企業売上!I17,"") -> -0.39306313 | I18: =IF(ISNUMBER(企業売上!J17),企業売上!J17,"") -> 0.19567289 | J18: =IF(ISNUMBER(企業売上!K17),企業売上!K17,"") -> -0.026229271
A21: 相関
B22: TEL | C22: SCREEN | D22: KOKUSAI | E22: 3社合計
A23: 韓国 | B23: =IF(SUMPRODUCT(--ISNUMBER($B$5:$B$18),--ISNUMBER($G$5:$G$18))<6,"",IFERROR(CORREL($B$5:$B$18,$G$5:$G$18),"")) -> 0.25736001 | C23: =IF(SUMPRODUCT(--ISNUMBER($B$5:$B$18),--ISNUMBER($H$5:$H$18))<6,"",IFERROR(CORREL($B$5:$B$18,$H$5:$H$18),"")) -> 0.092859222 | D23: =IF(SUMPRODUCT(--ISNUMBER($B$5:$B$18),--ISNUMBER($I$5:$I$18))<6,"",IFERROR(CORREL($B$5:$B$18,$I$5:$I$18),"")) -> 0.1261783 | E23: =IF(SUMPRODUCT(--ISNUMBER($B$5:$B$18),--ISNUMBER($J$5:$J$18))<6,"",IFERROR(CORREL($B$5:$B$18,$J$5:$J$18),"")) -> -0.10116672
A24: 台湾 | B24: =IF(SUMPRODUCT(--ISNUMBER($C$5:$C$18),--ISNUMBER($G$5:$G$18))<6,"",IFERROR(CORREL($C$5:$C$18,$G$5:$G$18),"")) -> 0.90235786 | C24: =IF(SUMPRODUCT(--ISNUMBER($C$5:$C$18),--ISNUMBER($H$5:$H$18))<6,"",IFERROR(CORREL($C$5:$C$18,$H$5:$H$18),"")) -> 0.84299116 | D24: =IF(SUMPRODUCT(--ISNUMBER($C$5:$C$18),--ISNUMBER($I$5:$I$18))<6,"",IFERROR(CORREL($C$5:$C$18,$I$5:$I$18),"")) -> 0.20484279 | E24: =IF(SUMPRODUCT(--ISNUMBER($C$5:$C$18),--ISNUMBER($J$5:$J$18))<6,"",IFERROR(CORREL($C$5:$C$18,$J$5:$J$18),"")) -> 0.8391116
A25: EU27 | B25: =IF(SUMPRODUCT(--ISNUMBER($D$5:$D$18),--ISNUMBER($G$5:$G$18))<6,"",IFERROR(CORREL($D$5:$D$18,$G$5:$G$18),"")) -> 0.49613563 | C25: =IF(SUMPRODUCT(--ISNUMBER($D$5:$D$18),--ISNUMBER($H$5:$H$18))<6,"",IFERROR(CORREL($D$5:$D$18,$H$5:$H$18),"")) -> 0.31788664 | D25: =IF(SUMPRODUCT(--ISNUMBER($D$5:$D$18),--ISNUMBER($I$5:$I$18))<6,"",IFERROR(CORREL($D$5:$D$18,$I$5:$I$18),"")) -> 0.21771703 | E25: =IF(SUMPRODUCT(--ISNUMBER($D$5:$D$18),--ISNUMBER($J$5:$J$18))<6,"",IFERROR(CORREL($D$5:$D$18,$J$5:$J$18),"")) -> 0.21797565
A26: 米国 | B26: =IF(SUMPRODUCT(--ISNUMBER($E$5:$E$18),--ISNUMBER($G$5:$G$18))<6,"",IFERROR(CORREL($E$5:$E$18,$G$5:$G$18),"")) -> 0.39449757 | C26: =IF(SUMPRODUCT(--ISNUMBER($E$5:$E$18),--ISNUMBER($H$5:$H$18))<6,"",IFERROR(CORREL($E$5:$E$18,$H$5:$H$18),"")) -> 0.13313642 | D26: =IF(SUMPRODUCT(--ISNUMBER($E$5:$E$18),--ISNUMBER($I$5:$I$18))<6,"",IFERROR(CORREL($E$5:$E$18,$I$5:$I$18),"")) -> 0.0020247768 | E26: =IF(SUMPRODUCT(--ISNUMBER($E$5:$E$18),--ISNUMBER($J$5:$J$18))<6,"",IFERROR(CORREL($E$5:$E$18,$J$5:$J$18),"")) -> 0.31158705
A27: CORE3 | B27: =IF(SUMPRODUCT(--ISNUMBER($F$5:$F$18),--ISNUMBER($G$5:$G$18))<6,"",IFERROR(CORREL($F$5:$F$18,$G$5:$G$18),"")) -> 0.73696699 | C27: =IF(SUMPRODUCT(--ISNUMBER($F$5:$F$18),--ISNUMBER($H$5:$H$18))<6,"",IFERROR(CORREL($F$5:$F$18,$H$5:$H$18),"")) -> 0.55687294 | D27: =IF(SUMPRODUCT(--ISNUMBER($F$5:$F$18),--ISNUMBER($I$5:$I$18))<6,"",IFERROR(CORREL($F$5:$F$18,$I$5:$I$18),"")) -> 0.25058135 | E27: =IF(SUMPRODUCT(--ISNUMBER($F$5:$F$18),--ISNUMBER($J$5:$J$18))<6,"",IFERROR(CORREL($F$5:$F$18,$J$5:$J$18),"")) -> 0.44188733
A29: 使い方：設定シートのB4（s）を変えると、この表と相関が更新される。

Sheet raw_月次輸入実績
A1: 月 | B1: 輸入地域 | C1: HS6 | D1: 輸入額（通貨単位） | E1: 通貨 | F1: FPD除外フラグ
A2: 44927 | B2: EU27 | C2: 848610 | D2: 2701068 | E2: EUR | F2: =IF(C2="848630",0,1) -> 1
A3: 44927 | B3: EU27 | C3: 848620 | D3: 59768177 | E3: EUR | F3: =IF(C3="848630",0,1) -> 1
A4: 44927 | B4: EU27 | C4: 848640 | D4: 8897655 | E4: EUR | F4: =IF(C4="848630",0,1) -> 1
A5: 44927 | B5: EU27 | C5: 848690 | D5: 31245786 | E5: EUR | F5: =IF(C5="848630",0,1) -> 1
A6: 44927 | B6: EU27 | C6: 903082 | D6: 4639682 | E6: EUR | F6: =IF(C6="848630",0,1) -> 1
A7: 44927 | B7: EU27 | C7: 903141 | D7: 1854842 | E7: EUR | F7: =IF(C7="848630",0,1) -> 1
A8: 44958 | B8: EU27 | C8: 848610 | D8: 2457116 | E8: EUR | F8: =IF(C8="848630",0,1) -> 1
A9: 44958 | B9: EU27 | C9: 848620 | D9: 72816528 | E9: EUR | F9: =IF(C9="848630",0,1) -> 1
A10: 44958 | B10: EU27 | C10: 848640 | D10: 6258595 | E10: EUR | F10: =IF(C10="848630",0,1) -> 1
A11: 44958 | B11: EU27 | C11: 848690 | D11: 31829306 | E11: EUR | F11: =IF(C11="848630",0,1) -> 1
A12: 44958 | B12: EU27 | C12: 903082 | D12: 3083575 | E12: EUR | F12: =IF(C12="848630",0,1) -> 1
A13: 44958 | B13: EU27 | C13: 903141 | D13: 2453415 | E13: EUR | F13: =IF(C13="848630",0,1) -> 1
... A3426: 46235 | B3426: 韓国 | C3426: 903141 | D3426: 23720000 | E3426: USD | F3426: =IF(C3426="848630",0,1) -> 1

Sheet raw_台湾月次
A1: 年月 | B1: CCCコード | C1: 分析用金額（USD） | D1: 利用状態
A2: 44927 | B2: 8486 | C2: 491979231 | D2: 利用可
A3: 44958 | B3: 8486 | C3: 504745637 | D3: 利用可
A4: 44986 | B4: 8486 | C4: 502856760 | D4: 利用可
A5: 45017 | B5: 8486 | C5: 344651016 | D5: 利用可
A6: 45047 | B6: 8486 | C6: 478045743 | D6: 利用可
A7: 45078 | B7: 8486 | C7: 296115358 | D7: 利用可
A8: 45108 | B8: 8486 | C8: 281048307 | D8: 利用可
A9: 45139 | B9: 8486 | C9: 167344017 | D9: 利用可
A10: 45170 | B10: 8486 | C10: 181885144 | D10: 利用可
A11: 45200 | B11: 8486 | C11: 236236817 | D11: 利用可
A12: 45231 | B12: 8486 | C12: 236798470 | D12: 利用可
A13: 45261 | B13: 8486 | C13: 292221271 | D13: 利用可
... A45: 46235 | B45: 8486 | C45: 651926933 | D45: 利用可
A46: 44927 | B46: 84861000201 | D46: 秘匿影響・利用除外
A47: 44958 | B47: 84861000201 | D47: 秘匿影響・利用除外
A48: 44986 | B48: 84861000201 | D48: 秘匿影響・利用除外
A49: 45017 | B49: 84861000201 | D49: 秘匿影響・利用除外
A50: 45047 | B50: 84861000201 | D50: 秘匿影響・利用除外
A51: 45078 | B51: 84861000201 | D51: 秘匿影響・利用除外
A52: 45108 | B52: 84861000201 | D52: 秘匿影響・利用除外
A53: 45139 | B53: 84861000201 | D53: 秘匿影響・利用除外
A54: 45170 | B54: 84861000201 | D54: 秘匿影響・利用除外
A55: 45200 | B55: 84861000201 | D55: 秘匿影響・利用除外
A56: 45231 | B56: 84861000201 | D56: 秘匿影響・利用除外
A57: 45261 | B57: 84861000201 | D57: 秘匿影響・利用除外
... A62: 45413 | B62: 84861000201 | D62: 秘匿影響・利用除外
A63: 45444 | B63: 84861000201 | C63: 27196939 | D63: 利用可
A64: 45474 | B64: 84861000201 | C64: 20619906 | D64: 利用可
A65: 45505 | B65: 84861000201 | C65: 37486776 | D65: 利用可
A66: 45536 | B66: 84861000201 | C66: 24835115 | D66: 利用可
A67: 45566 | B67: 84861000201 | C67: 25536228 | D67: 利用可
A68: 45597 | B68: 84861000201 | C68: 32748896 | D68: 利用可
A69: 45627 | B69: 84861000201 | C69: 42504342 | D69: 利用可
A70: 45658 | B70: 84861000201 | C70: 27950441 | D70: 利用可
A71: 45689 | B71: 84861000201 | C71: 41377266 | D71: 利用可
A72: 45717 | B72: 84861000201 | C72: 53227057 | D72: 利用可
A73: 45748 | B73: 84861000201 | C73: 87920825 | D73: 利用可
A74: 45778 | B74: 84861000201 | C74: 71288756 | D74: 利用可
... A96: 45108 | B96: 84862000209 | C96: 3357295 | D96: 利用可
...

Sheet 月次集計
A1: 月 | B1: 韓国(USD) | C1: EU27(EUR) | D1: 米国(USD) | E1: 台湾(USD) | F1: EU27(USD換算) | G1: CORE3(KR+TW+EU) | H1: 韓国_3M | I1: 台湾_3M | J1: EU27_3M | K1: 米国_3M | L1: CORE3_3M
A2: 44927 | B2: =IF(COUNTIFS(raw_月次輸入実績!$A$2:$A$20000,$A2,raw_月次輸入実績!$B$2:$B$20000,"韓国",raw_月次輸入実績!$F$2:$F$20000,1)=0,"",SUMIFS(raw_月次輸入実績!$D$2:$D$20000,raw_月次輸入実績!$A$2:$A$20000,$A2,raw_月次輸入実績!$B$2:$B$20000,"韓国",raw_月次輸入実績!$F$2:$F$20000,1)) -> 304186000 | C2: =IF(COUNTIFS(raw_月次輸入実績!$A$2:$A$20000,$A2,raw_月次輸入実績!$B$2:$B$20000,"EU27",raw_月次輸入実績!$F$2:$F$20000,1)=0,"",SUMIFS(raw_月次輸入実績!$D$2:$D$20000,raw_月次輸入実績!$A$2:$A$20000,$A2,raw_月次輸入実績!$B$2:$B$20000,"EU27",raw_月次輸入実績!$F$2:$F$20000,1)) -> 109107210 | D2: =IF(COUNTIFS(raw_月次輸入実績!$A$2:$A$20000,$A2,raw_月次輸入実績!$B$2:$B$20000,"米国",raw_月次輸入実績!$F$2:$F$20000,1)=0,"",SUMIFS(raw_月次輸入実績!$D$2:$D$20000,raw_月次輸入実績!$A$2:$A$20000,$A2,raw_月次輸入実績!$B$2:$B$20000,"米国",raw_月次輸入実績!$F$2:$F$20000,1)) -> 293644294 | E2: =IF(COUNTIFS(raw_台湾月次!$A$2:$A$20000,$A2,raw_台湾月次!$B$2:$B$20000,"8486",raw_台湾月次!$D$2:$D$20000,"利用可")=0,"",SUMIFS(raw_台湾月次!$C$2:$C$20000,raw_台湾月次!$A$2:$A$20000,$A2,raw_台湾月次!$B$2:$B$20000,"8486",raw_台湾月次!$D$2:$D$20000,"利用可")) -> 491979231 | F2: =IF(C2="","",C2*設定!$B$3) -> 120017931 | G2: =IF(COUNT(B2,E2,F2)=3,B2+E2+F2,"") -> 916183162
A3: 44958 | B3: =IF(COUNTIFS(raw_月次輸入実績!$A$2:$A$20000,$A3,raw_月次輸入実績!$B$2:$B$20000,"韓国",raw_月次輸入実績!$F$2:$F$20000,1)=0,"",SUMIFS(raw_月次輸入実績!$D$2:$D$20000,raw_月次輸入実績!$A$2:$A$20000,$A3,raw_月次輸入実績!$B$2:$B$20000,"韓国",raw_月次輸入実績!$F$2:$F$20000,1)) -> 377138000 | C3: =IF(COUNTIFS(raw_月次輸入実績!$A$2:$A$20000,$A3,raw_月次輸入実績!$B$2:$B$20000,"EU27",raw_月次輸入実績!$F$2:$F$20000,1)=0,"",SUMIFS(raw_月次輸入実績!$D$2:$D$20000,raw_月次輸入実績!$A$2:$A$20000,$A3,raw_月次輸入実績!$B$2:$B$20000,"EU27",raw_月次輸入実績!$F$2:$F$20000,1)) -> 118898535 | D3: =IF(COUNTIFS(raw_月次輸入実績!$A$2:$A$20000,$A3,raw_月次輸入実績!$B$2:$B$20000,"米国",raw_月次輸入実績!$F$2:$F$20000,1)=0,"",SUMIFS(raw_月次輸入実績!$D$2:$D$20000,raw_月次輸入実績!$A$2:$A$20000,$A3,raw_月次輸入実績!$B$2:$B$20000,"米国",raw_月次輸入実績!$F$2:$F$20000,1)) -> 349797338 | E3: =IF(COUNTIFS(raw_台湾月次!$A$2:$A$20000,$A3,raw_台湾月次!$B$2:$B$20000,"8486",raw_台湾月次!$D$2:$D$20000,"利用可")=0,"",SUMIFS(raw_台湾月次!$C$2:$C$20000,raw_台湾月次!$A$2:$A$20000,$A3,raw_台湾月次!$B$2:$B$20000,"8486",raw_台湾月次!$D$2:$D$20000,"利用可")) -> 504745637 | F3: =IF(C3="","",C3*設定!$B$3) -> 1.3078839e+08 | G3: =IF(COUNT(B3,E3,F3)=3,B3+E3+F3,"") -> 1.012672e+09
A4: 44986 | B4: =IF(COUNTIFS(raw_月次輸入実績!$A$2:$A$20000,$A4,raw_月次輸入実績!$B$2:$B$20000,"韓国",raw_月次輸入実績!$F$2:$F$20000,1)=0,"",SUMIFS(raw_月次輸入実績!$D$2:$D$20000,raw_月次輸入実績!$A$2:$A$20000,$A4,raw_月次輸入実績!$B$2:$B$20000,"韓国",raw_月次輸入実績!$F$2:$F$20000,1)) -> 545674000 | C4: =IF(COUNTIFS(raw_月次輸入実績!$A$2:$A$20000,$A4,raw_月次輸入実績!$B$2:$B$20000,"EU27",raw_月次輸入実績!$F$2:$F$20000,1)=0,"",SUMIFS(raw_月次輸入実績!$D$2:$D$20000,raw_月次輸入実績!$A$2:$A$20000,$A4,raw_月次輸入実績!$B$2:$B$20000,"EU27",raw_月次輸入実績!$F$2:$F$20000,1)) -> 271099575 | D4: =IF(COUNTIFS(raw_月次輸入実績!$A$2:$A$20000,$A4,raw_月次輸入実績!$B$2:$B$20000,"米国",raw_月次輸入実績!$F$2:$F$20000,1)=0,"",SUMIFS(raw_月次輸入実績!$D$2:$D$20000,raw_月次輸入実績!$A$2:$A$20000,$A4,raw_月次輸入実績!$B$2:$B$20000,"米国",raw_月次輸入実績!$F$2:$F$20000,1)) -> 474108474 | E4: =IF(COUNTIFS(raw_台湾月次!$A$2:$A$20000,$A4,raw_台湾月次!$B$2:$B$20000,"8486",raw_台湾月次!$D$2:$D$20000,"利用可")=0,"",SUMIFS(raw_台湾月次!$C$2:$C$20000,raw_台湾月次!$A$2:$A$20000,$A4,raw_台湾月次!$B$2:$B$20000,"8486",raw_台湾月次!$D$2:$D$20000,"利用可")) -> 502856760 | F4: =IF(C4="","",C4*設定!$B$3) -> 2.9820953e+08 | G4: =IF(COUNT(B4,E4,F4)=3,B4+E4+F4,"") -> 1.3467403e+09 | H4: =IF(COUNT(B2:B4)=3,SUM(B2:B4),"") -> 1226998000 | I4: =IF(COUNT(E2:E4)=3,SUM(E2:E4),"") -> 1499581628 | J4: =IF(COUNT(F2:F4)=3,SUM(F2:F4),"") -> 549015852 | K4: =IF(COUNT(D2:D4)=3,SUM(D2:D4),"") -> 1117550106 | L4: =IF(COUNT(G2:G4)=3,SUM(G2:G4),"") -> 3275595480
A5: 45017 | B5: =IF(COUNTIFS(raw_月次輸入実績!$A$2:$A$20000,$A5,raw_月次輸入実績!$B$2:$B$20000,"韓国",raw_月次輸入実績!$F$2:$F$20000,1)=0,"",SUMIFS(raw_月次輸入実績!$D$2:$D$20000,raw_月次輸入実績!$A$2:$A$20000,$A5,raw_月次輸入実績!$B$2:$B$20000,"韓国",raw_月次輸入実績!$F$2:$F$20000,1)) -> 444608000 | C5: =IF(COUNTIFS(raw_月次輸入実績!$A$2:$A$20000,$A5,raw_月次輸入実績!$B$2:$B$20000,"EU27",raw_月次輸入実績!$F$2:$F$20000,1)=0,"",SUMIFS(raw_月次輸入実績!$D$2:$D$20000,raw_月次輸入実績!$A$2:$A$20000,$A5,raw_月次輸入実績!$B$2:$B$20000,"EU27",raw_月次輸入実績!$F$2:$F$20000,1)) -> 241413843 | D5: =IF(COUNTIFS(raw_月次輸入実績!$A$2:$A$20000,$A5,raw_月次輸入実績!$B$2:$B$20000,"米国",raw_月次輸入実績!$F$2:$F$20000,1)=0,"",SUMIFS(raw_月次輸入実績!$D$2:$D$20000,raw_月次輸入実績!$A$2:$A$20000,$A5,raw_月次輸入実績!$B$2:$B$20000,"米国",raw_月次輸入実績!$F$2:$F$20000,1)) -> 565164996 | E5: =IF(COUNTIFS(raw_台湾月次!$A$2:$A$20000,$A5,raw_台湾月次!$B$2:$B$20000,"8486",raw_台湾月次!$D$2:$D$20000,"利用可")=0,"",SUMIFS(raw_台湾月次!$C$2:$C$20000,raw_台湾月次!$A$2:$A$20000,$A5,raw_台湾月次!$B$2:$B$20000,"8486",raw_台湾月次!$D$2:$D$20000,"利用可")) -> 344651016 | F5: =IF(C5="","",C5*設定!$B$3) -> 2.6555523e+08 | G5: =IF(COUNT(B5,E5,F5)=3,B5+E5+F5,"") -> 1.0548142e+09 | H5: =IF(COUNT(B3:B5)=3,SUM(B3:B5),"") -> 1367420000 | I5: =IF(COUNT(E3:E5)=3,SUM(E3:E5),"") -> 1352253413 | J5: =IF(COUNT(F3:F5)=3,SUM(F3:F5),"") -> 6.9455315e+08 | K5: =IF(COUNT(D3:D5)=3,SUM(D3:D5),"") -> 1389070808 | L5: =IF(COUNT(G3:G5)=3,SUM(G3:G5),"") -> 3.4142266e+09
A6: 45047 | B6: =IF(COUNTIFS(raw_月次輸入実績!$A$2:$A$20000,$A6,raw_月次輸入実績!$B$2:$B$20000,"韓国",raw_月次輸入実績!$F$2:$F$20000,1)=0,"",SUMIFS(raw_月次輸入実績!$D$2:$D$20000,raw_月次輸入実績!$A$2:$A$20000,$A6,raw_月次輸入実績!$B$2:$B$20000,"韓国",raw_月次輸入実績!$F$2:$F$20000,1)) -> 381300000 | C6: =IF(COUNTIFS(raw_月次輸入実績!$A$2:$A$20000,$A6,raw_月次輸入実績!$B$2:$B$20000,"EU27",raw_月次輸入実績!$F$2:$F$20000,1)=0,"",SUMIFS(raw_月次輸入実績!$D$2:$D$20000,raw_月次輸入実績!$A$2:$A$20000,$A6,raw_月次輸入実績!$B$2:$B$20000,"EU27",raw_月次輸入実績!$F$2:$F$20000,1)) -> 289915110 | D6: =IF(COUNTIFS(raw_月次輸入実績!$A$2:$A$20000,$A6,raw_月次輸入実績!$B$2:$B$20000,"米国",raw_月次輸入実績!$F$2:$F$20000,1)=0,"",SUMIFS(raw_月次輸入実績!$D$2:$D$20000,raw_月次輸入実績!$A$2:$A$20000,$A6,raw_月次輸入実績!$B$2:$B$20000,"米国",raw_月次輸入実績!$F$2:$F$20000,1)) -> 362202336 | E6: =IF(COUNTIFS(raw_台湾月次!$A$2:$A$20000,$A6,raw_台湾月次!$B$2:$B$20000,"8486",raw_台湾月次!$D$2:$D$20000,"利用可")=0,"",SUMIFS(raw_台湾月次!$C$2:$C$20000,raw_台湾月次!$A$2:$A$20000,$A6,raw_台湾月次!$B$2:$B$20000,"8486",raw_台湾月次!$D$2:$D$20000,"利用可")) -> 478045743 | F6: =IF(C6="","",C6*設定!$B$3) -> 318906621 | G6: =IF(COUNT(B6,E6,F6)=3,B6+E6+F6,"") -> 1178252364 | H6: =IF(COUNT(B4:B6)=3,SUM(B4:B6),"") -> 1371582000 | I6: =IF(COUNT(E4:E6)=3,SUM(E4:E6),"") -> 1325553519 | J6: =IF(COUNT(F4:F6)=3,SUM(F4:F6),"") -> 8.8267138e+08 | K6: =IF(COUNT(D4:D6)=3,SUM(D4:D6),"") -> 1401475806 | L6: =IF(COUNT(G4:G6)=3,SUM(G4:G6),"") -> 3.5798069e+09
A7: 45078 | B7: =IF(COUNTIFS(raw_月次輸入実績!$A$2:$A$20000,$A7,raw_月次輸入実績!$B$2:$B$20000,"韓国",raw_月次輸入実績!$F$2:$F$20000,1)=0,"",SUMIFS(raw_月次輸入実績!$D$2:$D$20000,raw_月次輸入実績!$A$2:$A$20000,$A7,raw_月次輸入実績!$B$2:$B$20000,"韓国",raw_月次輸入実績!$F$2:$F$20000,1)) -> 468629000 | C7: =IF(COUNTIFS(raw_月次輸入実績!$A$2:$A$20000,$A7,raw_月次輸入実績!$B$2:$B$20000,"EU27",raw_月次輸入実績!$F$2:$F$20000,1)=0,"",SUMIFS(raw_月次輸入実績!$D$2:$D$20000,raw_月次輸入実績!$A$2:$A$20000,$A7,raw_月次輸入実績!$B$2:$B$20000,"EU27",raw_月次輸入実績!$F$2:$F$20000,1)) -> 245307331 | D7: =IF(COUNTIFS(raw_月次輸入実績!$A$2:$A$20000,$A7,raw_月次輸入実績!$B$2:$B$20000,"米国",raw_月次輸入実績!$F$2:$F$20000,1)=0,"",SUMIFS(raw_月次輸入実績!$D$2:$D$20000,raw_月次輸入実績!$A$2:$A$20000,$A7,raw_月次輸入実績!$B$2:$B$20000,"米国",raw_月次輸入実績!$F$2:$F$20000,1)) -> 255491101 | E7: =IF(COUNTIFS(raw_台湾月次!$A$2:$A$20000,$A7,raw_台湾月次!$B$2:$B$20000,"8486",raw_台湾月次!$D$2:$D$20000,"利用可")=0,"",SUMIFS(raw_台湾月次!$C$2:$C$20000,raw_台湾月次!$A$2:$A$20000,$A7,raw_台湾月次!$B$2:$B$20000,"8486",raw_台湾月次!$D$2:$D$20000,"利用可")) -> 296115358 | F7: =IF(C7="","",C7*設定!$B$3) -> 2.6983806e+08 | G7: =IF(COUNT(B7,E7,F7)=3,B7+E7+F7,"") -> 1.0345824e+09 | H7: =IF(COUNT(B5:B7)=3,SUM(B5:B7),"") -> 1294537000 | I7: =IF(COUNT(E5:E7)=3,SUM(E5:E7),"") -> 1118812117 | J7: =IF(COUNT(F5:F7)=3,SUM(F5:F7),"") -> 8.5429991e+08 | K7: =IF(COUNT(D5:D7)=3,SUM(D5:D7),"") -> 1182858433 | L7: =IF(COUNT(G5:G7)=3,SUM(G5:G7),"") -> 3.267649e+09
A8: 45108 | B8: =IF(COUNTIFS(raw_月次輸入実績!$A$2:$A$20000,$A8,raw_月次輸入実績!$B$2:$B$20000,"韓国",raw_月次輸入実績!$F$2:$F$20000,1)=0,"",SUMIFS(raw_月次輸入実績!$D$2:$D$20000,raw_月次輸入実績!$A$2:$A$20000,$A8,raw_月次輸入実績!$B$2:$B$20000,"韓国",raw_月次輸入実績!$F$2:$F$20000,1)) -> 412611000 | C8: =IF(COUNTIFS(raw_月次輸入実績!$A$2:$A$20000,$A8,raw_月次輸入実績!$B$2:$B$20000,"EU27",raw_月次輸入実績!$F$2:$F$20000,1)=0,"",SUMIFS(raw_月次輸入実績!$D$2:$D$20000,raw_月次輸入実績!$A$2:$A$20000,$A8,raw_月次輸入実績!$B$2:$B$20000,"EU27",raw_月次輸入実績!$F$2:$F$20000,1)) -> 154212097 | D8: =IF(COUNTIFS(raw_月次輸入実績!$A$2:$A$20000,$A8,raw_月次輸入実績!$B$2:$B$20000,"米国",raw_月次輸入実績!$F$2:$F$20000,1)=0,"",SUMIFS(raw_月次輸入実績!$D$2:$D$20000,raw_月次輸入実績!$A$2:$A$20000,$A8,raw_月次輸入実績!$B$2:$B$20000,"米国",raw_月次輸入実績!$F$2:$F$20000,1)) | E8: =IF(COUNTIFS(raw_台湾月次!$A$2:$A$20000,$A8,raw_台湾月次!$B$2:$B$20000,"8486",raw_台湾月次!$D$2:$D$20000,"利用可")=0,"",SUMIFS(raw_台湾月次!$C$2:$C$20000,raw_台湾月次!$A$2:$A$20000,$A8,raw_台湾月次!$B$2:$B$20000,"8486",raw_台湾月次!$D$2:$D$20000,"利用可")) -> 281048307 | F8: =IF(C8="","",C8*設定!$B$3) -> 1.6963331e+08 | G8: =IF(COUNT(B8,E8,F8)=3,B8+E8+F8,"") -> 8.6329261e+08 | H8: =IF(COUNT(B6:B8)=3,SUM(B6:B8),"") -> 1262540000 | I8: =IF(COUNT(E6:E8)=3,SUM(E6:E8),"") -> 1055209408 | J8: =IF(COUNT(F6:F8)=3,SUM(F6:F8),"") -> 7.5837799e+08 | K8: =IF(COUNT(D6:D8)=3,SUM(D6:D8),"") | L8: =IF(COUNT(G6:G8)=3,SUM(G6:G8),"") -> 3.0761274e+09
A9: 45139 | B9: =IF(COUNTIFS(raw_月次輸入実績!$A$2:$A$20000,$A9,raw_月次輸入実績!$B$2:$B$20000,"韓国",raw_月次輸入実績!$F$2:$F$20000,1)=0,"",SUMIFS(raw_月次輸入実績!$D$2:$D$20000,raw_月次輸入実績!$A$2:$A$20000,$A9,raw_月次輸入実績!$B$2:$B$20000,"韓国",raw_月次輸入実績!$F$2:$F$20000,1)) -> 258491000 | C9: =IF(COUNTIFS(raw_月次輸入実績!$A$2:$A$20000,$A9,raw_月次輸入実績!$B$2:$B$20000,"EU27",raw_月次輸入実績!$F$2:$F$20000,1)=0,"",SUMIFS(raw_月次輸入実績!$D$2:$D$20000,raw_月次輸入実績!$A$2:$A$20000,$A9,raw_月次輸入実績!$B$2:$B$20000,"EU27",raw_月次輸入実績!$F$2:$F$20000,1)) -> 139911138 | D9: =IF(COUNTIFS(raw_月次輸入実績!$A$2:$A$20000,$A9,raw_月次輸入実績!$B$2:$B$20000,"米国",raw_月次輸入実績!$F$2:$F$20000,1)=0,"",SUMIFS(raw_月次輸入実績!$D$2:$D$20000,raw_月次輸入実績!$A$2:$A$20000,$A9,raw_月次輸入実績!$B$2:$B$20000,"米国",raw_月次輸入実績!$F$2:$F$20000,1)) -> 244571745 | E9: =IF(COUNTIFS(raw_台湾月次!$A$2:$A$20000,$A9,raw_台湾月次!$B$2:$B$20000,"8486",raw_台湾月次!$D$2:$D$20000,"利用可")=0,"",SUMIFS(raw_台湾月次!$C$2:$C$20000,raw_台湾月次!$A$2:$A$20000,$A9,raw_台湾月次!$B$2:$B$20000,"8486",raw_台湾月次!$D$2:$D$20000,"利用可")) -> 167344017 | F9: =IF(C9="","",C9*設定!$B$3) -> 1.5390225e+08 | G9: =IF(COUNT(B9,E9,F9)=3,B9+E9+F9,"") -> 5.7973727e+08 | H9: =IF(COUNT(B7:B9)=3,SUM(B7:B9),"") -> 1139731000 | I9: =IF(COUNT(E7:E9)=3,SUM(E7:E9),"") -> 744507682 | J9: =IF(COUNT(F7:F9)=3,SUM(F7:F9),"") -> 5.9337362e+08 | K9: =IF(COUNT(D7:D9)=3,SUM(D7:D9),"") | L9: =IF(COUNT(G7:G9)=3,SUM(G7:G9),"") -> 2.4776123e+09
A10: 45170 | B10: =IF(COUNTIFS(raw_月次輸入実績!$A$2:$A$20000,$A10,raw_月次輸入実績!$B$2:$B$20000,"韓国",raw_月次輸入実績!$F$2:$F$20000,1)=0,"",SUMIFS(raw_月次輸入実績!$D$2:$D$20000,raw_月次輸入実績!$A$2:$A$20000,$A10,raw_月次輸入実績!$B$2:$B$20000,"韓国",raw_月次輸入実績!$F$2:$F$20000,1)) -> 327383000 | C10: =IF(COUNTIFS(raw_月次輸入実績!$A$2:$A$20000,$A10,raw_月次輸入実績!$B$2:$B$20000,"EU27",raw_月次輸入実績!$F$2:$F$20000,1)=0,"",SUMIFS(raw_月次輸入実績!$D$2:$D$20000,raw_月次輸入実績!$A$2:$A$20000,$A10,raw_月次輸入実績!$B$2:$B$20000,"EU27",raw_月次輸入実績!$F$2:$F$20000,1)) -> 133270606 | D10: =IF(COUNTIFS(raw_月次輸入実績!$A$2:$A$20000,$A10,raw_月次輸入実績!$B$2:$B$20000,"米国",raw_月次輸入実績!$F$2:$F$20000,1)=0,"",SUMIFS(raw_月次輸入実績!$D$2:$D$20000,raw_月次輸入実績!$A$2:$A$20000,$A10,raw_月次輸入実績!$B$2:$B$20000,"米国",raw_月次輸入実績!$F$2:$F$20000,1)) -> 252977840 | E10: =IF(COUNTIFS(raw_台湾月次!$A$2:$A$20000,$A10,raw_台湾月次!$B$2:$B$20000,"8486",raw_台湾月次!$D$2:$D$20000,"利用可")=0,"",SUMIFS(raw_台湾月次!$C$2:$C$20000,raw_台湾月次!$A$2:$A$20000,$A10,raw_台湾月次!$B$2:$B$20000,"8486",raw_台湾月次!$D$2:$D$20000,"利用可")) -> 181885144 | F10: =IF(C10="","",C10*設定!$B$3) -> 1.4659767e+08 | G10: =IF(COUNT(B10,E10,F10)=3,B10+E10+F10,"") -> 6.5586581e+08 | H10: =IF(COUNT(B8:B10)=3,SUM(B8:B10),"") -> 998485000 | I10: =IF(COUNT(E8:E10)=3,SUM(E8:E10),"") -> 630277468 | J10: =IF(COUNT(F8:F10)=3,SUM(F8:F10),"") -> 4.7013323e+08 | K10: =IF(COUNT(D8:D10)=3,SUM(D8:D10),"") | L10: =IF(COUNT(G8:G10)=3,SUM(G8:G10),"") -> 2.0988957e+09
A11: 45200 | B11: =IF(COUNTIFS(raw_月次輸入実績!$A$2:$A$20000,$A11,raw_月次輸入実績!$B$2:$B$20000,"韓国",raw_月次輸入実績!$F$2:$F$20000,1)=0,"",SUMIFS(raw_月次輸入実績!$D$2:$D$20000,raw_月次輸入実績!$A$2:$A$20000,$A11,raw_月次輸入実績!$B$2:$B$20000,"韓国",raw_月次輸入実績!$F$2:$F$20000,1)) -> 242689000 | C11: =IF(COUNTIFS(raw_月次輸入実績!$A$2:$A$20000,$A11,raw_月次輸入実績!$B$2:$B$20000,"EU27",raw_月次輸入実績!$F$2:$F$20000,1)=0,"",SUMIFS(raw_月次輸入実績!$D$2:$D$20000,raw_月次輸入実績!$A$2:$A$20000,$A11,raw_月次輸入実績!$B$2:$B$20000,"EU27",raw_月次輸入実績!$F$2:$F$20000,1)) -> 155521919 | D11: =IF(COUNTIFS(raw_月次輸入実績!$A$2:$A$20000,$A11,raw_月次輸入実績!$B$2:$B$20000,"米国",raw_月次輸入実績!$F$2:$F$20000,1)=0,"",SUMIFS(raw_月次輸入実績!$D$2:$D$20000,raw_月次輸入実績!$A$2:$A$20000,$A11,raw_月次輸入実績!$B$2:$B$20000,"米国",raw_月次輸入実績!$F$2:$F$20000,1)) -> 284168551 | E11: =IF(COUNTIFS(raw_台湾月次!$A$2:$A$20000,$A11,raw_台湾月次!$B$2:$B$20000,"8486",raw_台湾月次!$D$2:$D$20000,"利用可")=0,"",SUMIFS(raw_台湾月次!$C$2:$C$20000,raw_台湾月次!$A$2:$A$20000,$A11,raw_台湾月次!$B$2:$B$20000,"8486",raw_台湾月次!$D$2:$D$20000,"利用可")) -> 236236817 | F11: =IF(C11="","",C11*設定!$B$3) -> 1.7107411e+08 | G11: =IF(COUNT(B11,E11,F11)=3,B11+E11+F11,"") -> 6.4999993e+08 | H11: =IF(COUNT(B9:B11)=3,SUM(B9:B11),"") -> 828563000 | I11: =IF(COUNT(E9:E11)=3,SUM(E9:E11),"") -> 585465978 | J11: =IF(COUNT(F9:F11)=3,SUM(F9:F11),"") -> 4.7157403e+08 | K11: =IF(COUNT(D9:D11)=3,SUM(D9:D11),"") -> 781718136 | L11: =IF(COUNT(G9:G11)=3,SUM(G9:G11),"") -> 1.885603e+09
A12: 45231 | B12: =IF(COUNTIFS(raw_月次輸入実績!$A$2:$A$20000,$A12,raw_月次輸入実績!$B$2:$B$20000,"韓国",raw_月次輸入実績!$F$2:$F$20000,1)=0,"",SUMIFS(raw_月次輸入実績!$D$2:$D$20000,raw_月次輸入実績!$A$2:$A$20000,$A12,raw_月次輸入実績!$B$2:$B$20000,"韓国",raw_月次輸入実績!$F$2:$F$20000,1)) -> 266275000 | C12: =IF(COUNTIFS(raw_月次輸入実績!$A$2:$A$20000,$A12,raw_月次輸入実績!$B$2:$B$20000,"EU27",raw_月次輸入実績!$F$2:$F$20000,1)=0,"",SUMIFS(raw_月次輸入実績!$D$2:$D$20000,raw_月次輸入実績!$A$2:$A$20000,$A12,raw_月次輸入実績!$B$2:$B$20000,"EU27",raw_月次輸入実績!$F$2:$F$20000,1)) -> 113816534 | D12: =IF(COUNTIFS(raw_月次輸入実績!$A$2:$A$20000,$A12,raw_月次輸入実績!$B$2:$B$20000,"米国",raw_月次輸入実績!$F$2:$F$20000,1)=0,"",SUMIFS(raw_月次輸入実績!$D$2:$D$20000,raw_月次輸入実績!$A$2:$A$20000,$A12,raw_月次輸入実績!$B$2:$B$20000,"米国",raw_月次輸入実績!$F$2:$F$20000,1)) -> 325764618 | E12: =IF(COUNTIFS(raw_台湾月次!$A$2:$A$20000,$A12,raw_台湾月次!$B$2:$B$20000,"8486",raw_台湾月次!$D$2:$D$20000,"利用可")=0,"",SUMIFS(raw_台湾月次!$C$2:$C$20000,raw_台湾月次!$A$2:$A$20000,$A12,raw_台湾月次!$B$2:$B$20000,"8486",raw_台湾月次!$D$2:$D$20000,"利用可")) -> 236798470 | F12: =IF(C12="","",C12*設定!$B$3) -> 1.2519819e+08 | G12: =IF(COUNT(B12,E12,F12)=3,B12+E12+F12,"") -> 6.2827166e+08 | H12: =IF(COUNT(B10:B12)=3,SUM(B10:B12),"") -> 836347000 | I12: =IF(COUNT(E10:E12)=3,SUM(E10:E12),"") -> 654920431 | J12: =IF(COUNT(F10:F12)=3,SUM(F10:F12),"") -> 4.4286996e+08 | K12: =IF(COUNT(D10:D12)=3,SUM(D10:D12),"") -> 862911009 | L12: =IF(COUNT(G10:G12)=3,SUM(G10:G12),"") -> 1.9341374e+09
A13: 45261 | B13: =IF(COUNTIFS(raw_月次輸入実績!$A$2:$A$20000,$A13,raw_月次輸入実績!$B$2:$B$20000,"韓国",raw_月次輸入実績!$F$2:$F$20000,1)=0,"",SUMIFS(raw_月次輸入実績!$D$2:$D$20000,raw_月次輸入実績!$A$2:$A$20000,$A13,raw_月次輸入実績!$B$2:$B$20000,"韓国",raw_月次輸入実績!$F$2:$F$20000,1)) -> 362514000 | C13: =IF(COUNTIFS(raw_月次輸入実績!$A$2:$A$20000,$A13,raw_月次輸入実績!$B$2:$B$20000,"EU27",raw_月次輸入実績!$F$2:$F$20000,1)=0,"",SUMIFS(raw_月次輸入実績!$D$2:$D$20000,raw_月次輸入実績!$A$2:$A$20000,$A13,raw_月次輸入実績!$B$2:$B$20000,"EU27",raw_月次輸入実績!$F$2:$F$20000,1)) -> 59303938 | D13: =IF(COUNTIFS(raw_月次輸入実績!$A$2:$A$20000,$A13,raw_月次輸入実績!$B$2:$B$20000,"米国",raw_月次輸入実績!$F$2:$F$20000,1)=0,"",SUMIFS(raw_月次輸入実績!$D$2:$D$20000,raw_月次輸入実績!$A$2:$A$20000,$A13,raw_月次輸入実績!$B$2:$B$20000,"米国",raw_月次輸入実績!$F$2:$F$20000,1)) -> 274987453 | E13: =IF(COUNTIFS(raw_台湾月次!$A$2:$A$20000,$A13,raw_台湾月次!$B$2:$B$20000,"8486",raw_台湾月次!$D$2:$D$20000,"利用可")=0,"",SUMIFS(raw_台湾月次!$C$2:$C$20000,raw_台湾月次!$A$2:$A$20000,$A13,raw_台湾月次!$B$2:$B$20000,"8486",raw_台湾月次!$D$2:$D$20000,"利用可")) -> 292221271 | F13: =IF(C13="","",C13*設定!$B$3) -> 65234332 | G13: =IF(COUNT(B13,E13,F13)=3,B13+E13+F13,"") -> 7.199696e+08 | H13: =IF(COUNT(B11:B13)=3,SUM(B11:B13),"") -> 871478000 | I13: =IF(COUNT(E11:E13)=3,SUM(E11:E13),"") -> 765256558 | J13: =IF(COUNT(F11:F13)=3,SUM(F11:F13),"") -> 3.6150663e+08 | K13: =IF(COUNT(D11:D13)=3,SUM(D11:D13),"") -> 884920622 | L13: =IF(COUNT(G11:G13)=3,SUM(G11:G13),"") -> 1.9982412e+09
A14: 45292 | B14: =IF(COUNTIFS(raw_月次輸入実績!$A$2:$A$20000,$A14,raw_月次輸入実績!$B$2:$B$20000,"韓国",raw_月次輸入実績!$F$2:$F$20000,1)=0,"",SUMIFS(raw_月次輸入実績!$D$2:$D$20000,raw_月次輸入実績!$A$2:$A$20000,$A14,raw_月次輸入実績!$B$2:$B$20000,"韓国",raw_月次輸入実績!$F$2:$F$20000,1)) -> 390312000 | C14: =IF(COUNTIFS(raw_月次輸入実績!$A$2:$A$20000,$A14,raw_月次輸入実績!$B$2:$B$20000,"EU27",raw_月次輸入実績!$F$2:$F$20000,1)=0,"",SUMIFS(raw_月次輸入実績!$D$2:$D$20000,raw_月次輸入実績!$A$2:$A$20000,$A14,raw_月次輸入実績!$B$2:$B$20000,"EU27",raw_月次輸入実績!$F$2:$F$20000,1)) -> 144482449 | D14: =IF(COUNTIFS(raw_月次輸入実績!$A$2:$A$20000,$A14,raw_月次輸入実績!$B$2:$B$20000,"米国",raw_月次輸入実績!$F$2:$F$20000,1)=0,"",SUMIFS(raw_月次輸入実績!$D$2:$D$20000,raw_月次輸入実績!$A$2:$A$20000,$A14,raw_月次輸入実績!$B$2:$B$20000,"米国",raw_月次輸入実績!$F$2:$F$20000,1)) -> 244964160 | E14: =IF(COUNTIFS(raw_台湾月次!$A$2:$A$20000,$A14,raw_台湾月次!$B$2:$B$20000,"8486",raw_台湾月次!$D$2:$D$20000,"利用可")=0,"",SUMIFS(raw_台湾月次!$C$2:$C$20000,raw_台湾月次!$A$2:$A$20000,$A14,raw_台湾月次!$B$2:$B$20000,"8486",raw_台湾月次!$D$2:$D$20000,"利用可")) -> 257692564 | F14: =IF(C14="","",C14*設定!$B$3) -> 1.5893069e+08 | G14: =IF(COUNT(B14,E14,F14)=3,B14+E14+F14,"") -> 8.0693526e+08 | H14: =IF(COUNT(B12:B14)=3,SUM(B12:B14),"") -> 1019101000 | I14: =IF(COUNT(E12:E14)=3,SUM(E12:E14),"") -> 786712305 | J14: =IF(COUNT(F12:F14)=3,SUM(F12:F14),"") -> 3.4936321e+08 | K14: =IF(COUNT(D12:D14)=3,SUM(D12:D14),"") -> 845716231 | L14: =IF(COUNT(G12:G14)=3,SUM(G12:G14),"") -> 2.1551765e+09
A15: 45323 | B15: =IF(COUNTIFS(raw_月次輸入実績!$A$2:$A$20000,$A15,raw_月次輸入実績!$B$2:$B$20000,"韓国",raw_月次輸入実績!$F$2:$F$20000,1)=0,"",SUMIFS(raw_月次輸入実績!$D$2:$D$20000,raw_月次輸入実績!$A$2:$A$20000,$A15,raw_月次輸入実績!$B$2:$B$20000,"韓国",raw_月次輸入実績!$F$2:$F$20000,1)) -> 388391000 | C15: =IF(COUNTIFS(raw_月次輸入実績!$A$2:$A$20000,$A15,raw_月次輸入実績!$B$2:$B$20000,"EU27",raw_月次輸入実績!$F$2:$F$20000,1)=0,"",SUMIFS(raw_月次輸入実績!$D$2:$D$20000,raw_月次輸入実績!$A$2:$A$20000,$A15,raw_月次輸入実績!$B$2:$B$20000,"EU27",raw_月次輸入実績!$F$2:$F$20000,1)) -> 135039798 | D15: =IF(COUNTIFS(raw_月次輸入実績!$A$2:$A$20000,$A15,raw_月次輸入実績!$B$2:$B$20000,"米国",raw_月次輸入実績!$F$2:$F$20000,1)=0,"",SUMIFS(raw_月次輸入実績!$D$2:$D$20000,raw_月次輸入実績!$A$2:$A$20000,$A15,raw_月次輸入実績!$B$2:$B$20000,"米国",raw_月次輸入実績!$F$2:$F$20000,1)) -> 287762563 | E15: =IF(COUNTIFS(raw_台湾月次!$A$2:$A$20000,$A15,raw_台湾月次!$B$2:$B$20000,"8486",raw_台湾月次!$D$2:$D$20000,"利用可")=0,"",SUMIFS(raw_台湾月次!$C$2:$C$20000,raw_台湾月次!$A$2:$A$20000,$A15,raw_台湾月次!$B$2:$B$20000,"8486",raw_台湾月次!$D$2:$D$20000,"利用可")) -> 202843270 | F15: =IF(C15="","",C15*設定!$B$3) -> 1.4854378e+08 | G15: =IF(COUNT(B15,E15,F15)=3,B15+E15+F15,"") -> 7.3977805e+08 | H15: =IF(COUNT(B13:B15)=3,SUM(B13:B15),"") -> 1141217000 | I15: =IF(COUNT(E13:E15)=3,SUM(E13:E15),"") -> 752757105 | J15: =IF(COUNT(F13:F15)=3,SUM(F13:F15),"") -> 3.727088e+08 | K15: =IF(COUNT(D13:D15)=3,SUM(D13:D15),"") -> 807714176 | L15: =IF(COUNT(G13:G15)=3,SUM(G13:G15),"") -> 2.2666829e+09
... A45: 46235 | B45: =IF(COUNTIFS(raw_月次輸入実績!$A$2:$A$20000,$A45,raw_月次輸入実績!$B$2:$B$20000,"韓国",raw_月次輸入実績!$F$2:$F$20000,1)=0,"",SUMIFS(raw_月次輸入実績!$D$2:$D$20000,raw_月次輸入実績!$A$2:$A$20000,$A45,raw_月次輸入実績!$B$2:$B$20000,"韓国",raw_月次輸入実績!$F$2:$F$20000,1)) -> 681614000 | C45: =IF(COUNTIFS(raw_月次輸入実績!$A$2:$A$20000,$A45,raw_月次輸入実績!$B$2:$B$20000,"EU27",raw_月次輸入実績!$F$2:$F$20000,1)=0,"",SUMIFS(raw_月次輸入実績!$D$2:$D$20000,raw_月次輸入実績!$A$2:$A$20000,$A45,raw_月次輸入実績!$B$2:$B$20000,"EU27",raw_月次輸入実績!$F$2:$F$20000,1)) | D45: =IF(COUNTIFS(raw_月次輸入実績!$A$2:$A$20000,$A45,raw_月次輸入実績!$B$2:$B$20000,"米国",raw_月次輸入実績!$F$2:$F$20000,1)=0,"",SUMIFS(raw_月次輸入実績!$D$2:$D$20000,raw_月次輸入実績!$A$2:$A$20000,$A45,raw_月次輸入実績!$B$2:$B$20000,"米国",raw_月次輸入実績!$F$2:$F$20000,1)) | E45: =IF(COUNTIFS(raw_台湾月次!$A$2:$A$20000,$A45,raw_台湾月次!$B$2:$B$20000,"8486",raw_台湾月次!$D$2:$D$20000,"利用可")=0,"",SUMIFS(raw_台湾月次!$C$2:$C$20000,raw_台湾月次!$A$2:$A$20000,$A45,raw_台湾月次!$B$2:$B$20000,"8486",raw_台湾月次!$D$2:$D$20000,"利用可")) -> 651926933 | F45: =IF(C45="","",C45*設定!$B$3) | G45: =IF(COUNT(B45,E45,F45)=3,B45+E45+F45,"") | H45: =IF(COUNT(B43:B45)=3,SUM(B43:B45),"") -> 1944119000 | I45: =IF(COUNT(E43:E45)=3,SUM(E43:E45),"") -> 2343740523 | J45: =IF(COUNT(F43:F45)=3,SUM(F43:F45),"") | K45: =IF(COUNT(D43:D45)=3,SUM(D43:D45),"") | L45: =IF(COUNT(G43:G45)=3,SUM(G43:G45),"")

Sheet 企業売上
A1: 企業売上（暦四半期・億円）。青字は決算資料から転記した入力値
A3: 四半期 | B3: 東京エレクトロン | C3: SCREEN | D3: SCREEN_SPE | E3: KOKUSAI | F3: 3社合計 | H3: TEL_QoQ | I3: SCREEN_QoQ | J3: KOKUSAI_QoQ | K3: 3社合計_QoQ
A4: 2023Q1 | B4: 5582 | C4: 1255 | D4: 1002 | F4: =IF(COUNT(B4,C4,E4)=3,B4+C4+E4,"")
A5: 2023Q2 | B5: 3917 | C5: 996 | D5: 823 | E5: 327 | F5: =IF(COUNT(B5,C5,E5)=3,B5+C5+E5,"") -> 5240 | H5: =IF(AND(ISNUMBER(B5),ISNUMBER(B4)),LN(B5/B4),"") -> -0.35422108 | I5: =IF(AND(ISNUMBER(C5),ISNUMBER(C4)),LN(C5/C4),"") -> -0.23114359 | J5: =IF(AND(ISNUMBER(E5),ISNUMBER(E4)),LN(E5/E4),"") | K5: =IF(AND(ISNUMBER(F5),ISNUMBER(F4)),LN(F5/F4),"")
A6: 2023Q3 | B6: 4278 | C6: 1235 | D6: 1037 | E6: 450 | F6: =IF(COUNT(B6,C6,E6)=3,B6+C6+E6,"") -> 5963 | H6: =IF(AND(ISNUMBER(B6),ISNUMBER(B5)),LN(B6/B5),"") -> 0.088159556 | I6: =IF(AND(ISNUMBER(C6),ISNUMBER(C5)),LN(C6/C5),"") -> 0.21507899 | J6: =IF(AND(ISNUMBER(E6),ISNUMBER(E5)),LN(E6/E5),"") -> 0.31928741 | K6: =IF(AND(ISNUMBER(F6),ISNUMBER(F5)),LN(F6/F5),"") -> 0.12925221
A7: 2023Q4 | B7: 4636 | C7: 1245 | D7: 1019 | E7: 540 | F7: =IF(COUNT(B7,C7,E7)=3,B7+C7+E7,"") -> 6421 | H7: =IF(AND(ISNUMBER(B7),ISNUMBER(B6)),LN(B7/B6),"") -> 0.080366315 | I7: =IF(AND(ISNUMBER(C7),ISNUMBER(C6)),LN(C7/C6),"") -> 0.0080645598 | J7: =IF(AND(ISNUMBER(E7),ISNUMBER(E6)),LN(E7/E6),"") -> 0.18232156 | K7: =IF(AND(ISNUMBER(F7),ISNUMBER(F6)),LN(F7/F6),"") -> 0.074000159
A8: 2024Q1 | B8: 5472 | C8: 1570 | D8: 1296 | E8: 492 | F8: =IF(COUNT(B8,C8,E8)=3,B8+C8+E8,"") -> 7534 | H8: =IF(AND(ISNUMBER(B8),ISNUMBER(B7)),LN(B8/B7),"") -> 0.16579225 | I8: =IF(AND(ISNUMBER(C8),ISNUMBER(C7)),LN(C8/C7),"") -> 0.23194009 | J8: =IF(AND(ISNUMBER(E8),ISNUMBER(E7)),LN(E8/E7),"") -> -0.093090423 | K8: =IF(AND(ISNUMBER(F8),ISNUMBER(F7)),LN(F8/F7),"") -> 0.15985224
A9: 2024Q2 | B9: 5550 | C9: 1342 | D9: 1121 | E9: 652 | F9: =IF(COUNT(B9,C9,E9)=3,B9+C9+E9,"") -> 7544 | H9: =IF(AND(ISNUMBER(B9),ISNUMBER(B8)),LN(B9/B8),"") -> 0.014153747 | I9: =IF(AND(ISNUMBER(C9),ISNUMBER(C8)),LN(C9/C8),"") -> -0.15691458 | J9: =IF(AND(ISNUMBER(E9),ISNUMBER(E8)),LN(E9/E8),"") -> 0.28156585 | K9: =IF(AND(ISNUMBER(F9),ISNUMBER(F8)),LN(F9/F8),"") -> 0.0013264361
A10: 2024Q3 | B10: 5665 | C10: 1431 | D10: 1168 | E10: 493 | F10: =IF(COUNT(B10,C10,E10)=3,B10+C10+E10,"") -> 7589 | H10: =IF(AND(ISNUMBER(B10),ISNUMBER(B9)),LN(B10/B9),"") -> 0.020508967 | I10: =IF(AND(ISNUMBER(C10),ISNUMBER(C9)),LN(C10/C9),"") -> 0.064212462 | J10: =IF(AND(ISNUMBER(E10),ISNUMBER(E9)),LN(E10/E9),"") -> -0.27953539 | K10: =IF(AND(ISNUMBER(F10),ISNUMBER(F9)),LN(F10/F9),"") -> 0.0059472851
A11: 2024Q4 | B11: 6545 | C11: 1825 | D11: 1548 | E11: 601 | F11: =IF(COUNT(B11,C11,E11)=3,B11+C11+E11,"") -> 8971 | H11: =IF(AND(ISNUMBER(B11),ISNUMBER(B10)),LN(B11/B10),"") -> 0.1443945 | I11: =IF(AND(ISNUMBER(C11),ISNUMBER(C10)),LN(C11/C10),"") -> 0.24320649 | J11: =IF(AND(ISNUMBER(E11),ISNUMBER(E10)),LN(E11/E10),"") -> 0.19808576 | K11: =IF(AND(ISNUMBER(F11),ISNUMBER(F10)),LN(F11/F10),"") -> 0.16729732
A12: 2025Q1 | B12: 6554 | C12: 1653 | D12: 1355 | E12: 643 | F12: =IF(COUNT(B12,C12,E12)=3,B12+C12+E12,"") -> 8850 | H12: =IF(AND(ISNUMBER(B12),ISNUMBER(B11)),LN(B12/B11),"") -> 0.0013741509 | I12: =IF(AND(ISNUMBER(C12),ISNUMBER(C11)),LN(C12/C11),"") -> -0.098988168 | J12: =IF(AND(ISNUMBER(E12),ISNUMBER(E11)),LN(E12/E11),"") -> 0.06754979 | K12: =IF(AND(ISNUMBER(F12),ISNUMBER(F11)),LN(F12/F11),"") -> -0.013579694
A13: 2025Q2 | B13: 5495 | C13: 1357 | D13: 1095 | E13: 518 | F13: =IF(COUNT(B13,C13,E13)=3,B13+C13+E13,"") -> 7370 | H13: =IF(AND(ISNUMBER(B13),ISNUMBER(B12)),LN(B13/B12),"") -> -0.17623696 | I13: =IF(AND(ISNUMBER(C13),ISNUMBER(C12)),LN(C13/C12),"") -> -0.19731544 | J13: =IF(AND(ISNUMBER(E13),ISNUMBER(E12)),LN(E13/E12),"") -> -0.21616948 | K13: =IF(AND(ISNUMBER(F13),ISNUMBER(F12)),LN(F13/F12),"") -> -0.18299975
A14: 2025Q3 | B14: 6300 | C14: 1385 | D14: 1090 | E14: 654 | F14: =IF(COUNT(B14,C14,E14)=3,B14+C14+E14,"") -> 8339 | H14: =IF(AND(ISNUMBER(B14),ISNUMBER(B13)),LN(B14/B13),"") -> 0.13671105 | I14: =IF(AND(ISNUMBER(C14),ISNUMBER(C13)),LN(C14/C13),"") -> 0.020423759 | J14: =IF(AND(ISNUMBER(E14),ISNUMBER(E13)),LN(E14/E13),"") -> 0.23313211 | K14: =IF(AND(ISNUMBER(F14),ISNUMBER(F13)),LN(F14/F13),"") -> 0.1235256
A15: 2025Q4 | B15: 5520 | C15: 1510 | D15: 1200 | E15: 559 | F15: =IF(COUNT(B15,C15,E15)=3,B15+C15+E15,"") -> 7589 | H15: =IF(AND(ISNUMBER(B15),ISNUMBER(B14)),LN(B15/B14),"") -> -0.13217177 | I15: =IF(AND(ISNUMBER(C15),ISNUMBER(C14)),LN(C15/C14),"") -> 0.086409511 | J15: =IF(AND(ISNUMBER(E15),ISNUMBER(E14)),LN(E15/E14),"") -> -0.15695788 | K15: =IF(AND(ISNUMBER(F15),ISNUMBER(F14)),LN(F15/F14),"") -> -0.094243475
A16: 2026Q1 | B16: 7118 | C16: 1803 | D16: 1473 | E16: 620 | F16: =IF(COUNT(B16,C16,E16)=3,B16+C16+E16,"") -> 9541 | H16: =IF(AND(ISNUMBER(B16),ISNUMBER(B15)),LN(B16/B15),"") -> 0.25424893 | I16: =IF(AND(ISNUMBER(C16),ISNUMBER(C15)),LN(C16/C15),"") -> 0.17734229 | J16: =IF(AND(ISNUMBER(E16),ISNUMBER(E15)),LN(E16/E15),"") -> 0.10357 | K16: =IF(AND(ISNUMBER(F16),ISNUMBER(F15)),LN(F16/F15),"") -> 0.22889847
A17: 2026Q2 | B17: 7323 | C17: 1217 | D17: 931 | E17: 754 | F17: =IF(COUNT(B17,C17,E17)=3,B17+C17+E17,"") -> 9294 | H17: =IF(AND(ISNUMBER(B17),ISNUMBER(B16)),LN(B17/B16),"") -> 0.028393293 | I17: =IF(AND(ISNUMBER(C17),ISNUMBER(C16)),LN(C17/C16),"") -> -0.39306313 | J17: =IF(AND(ISNUMBER(E17),ISNUMBER(E16)),LN(E17/E16),"") -> 0.19567289 | K17: =IF(AND(ISNUMBER(F17),ISNUMBER(F16)),LN(F17/F16),"") -> -0.026229271
A19: QoQは自然対数の差 LN(今期/前期)。KOKUSAIの2023年1〜3月は資料で確認できず空欄。

Sheet ラグ走査_作業
A1: 輸入額の3か月窓QoQ（シフト別）。ラグ相関シートの元データ | C1: KR | D1: KR | E1: KR | F1: KR | G1: KR | H1: KR | I1: KR | J1: KR | K1: KR | L1: KR | M1: KR | N1: KR | O1: KR | P1: TW | Q1: TW | R1: TW | S1: TW | T1: TW | U1: TW | V1: TW | W1: TW | X1: TW | Y1: TW | Z1: TW | AA1: TW | AB1: TW | AC1: EU | AD1: EU | AE1: EU | AF1: EU | AG1: EU | AH1: EU | AI1: EU | AJ1: EU | AK1: EU | AL1: EU | AM1: EU | AN1: EU | AO1: EU | AP1: US | AQ1: US | AR1: US | AS1: US | AT1: US | AU1: US | AV1: US | AW1: US | AX1: US | AY1: US | AZ1: US | BA1: US | BB1: US | BC1: CORE3 | BD1: CORE3 | BE1: CORE3 | BF1: CORE3 | BG1: CORE3 | BH1: CORE3 | BI1: CORE3 | BJ1: CORE3 | BK1: CORE3 | BL1: CORE3 | BM1: CORE3 | BN1: CORE3 | BO1: CORE3
C2: -6 | D2: -5 | E2: -4 | F2: -3 | G2: -2 | H2: -1 | I2: 0 | J2: 1 | K2: 2 | L2: 3 | M2: 4 | N2: 5 | O2: 6 | P2: -6 | Q2: -5 | R2: -4 | S2: -3 | T2: -2 | U2: -1 | V2: 0 | W2: 1 | X2: 2 | Y2: 3 | Z2: 4 | AA2: 5 | AB2: 6 | AC2: -6 | AD2: -5 | AE2: -4 | AF2: -3 | AG2: -2 | AH2: -1 | AI2: 0 | AJ2: 1 | AK2: 2 | AL2: 3 | AM2: 4 | AN2: 5 | AO2: 6 | AP2: -6 | AQ2: -5 | AR2: -4 | AS2: -3 | AT2: -2 | AU2: -1 | AV2: 0 | AW2: 1 | AX2: 2 | AY2: 3 | AZ2: 4 | BA2: 5 | BB2: 6 | BC2: -6 | BD2: -5 | BE2: -4 | BF2: -3 | BG2: -2 | BH2: -1 | BI2: 0 | BJ2: 1 | BK2: 2 | BL2: 3 | BM2: 4 | BN2: 5 | BO2: 6
A3: 四半期 | B3: 四半期末の月番号e | C3: KR_s-6 | D3: KR_s-5 | E3: KR_s-4 | F3: KR_s-3 | G3: KR_s-2 | H3: KR_s-1 | I3: KR_s+0 | J3: KR_s+1 | K3: KR_s+2 | L3: KR_s+3 | M3: KR_s+4 | N3: KR_s+5 | O3: KR_s+6 | P3: TW_s-6 | Q3: TW_s-5 | R3: TW_s-4 | S3: TW_s-3 | T3: TW_s-2 | U3: TW_s-1 | V3: TW_s+0 | W3: TW_s+1 | X3: TW_s+2 | Y3: TW_s+3 | Z3: TW_s+4 | AA3: TW_s+5 | AB3: TW_s+6 | AC3: EU_s-6 | AD3: EU_s-5 | AE3: EU_s-4 | AF3: EU_s-3 | AG3: EU_s-2 | AH3: EU_s-1 | AI3: EU_s+0 | AJ3: EU_s+1 | AK3: EU_s+2 | AL3: EU_s+3 | AM3: EU_s+4 | AN3: EU_s+5 | AO3: EU_s+6 | AP3: US_s-6 | AQ3: US_s-5 | AR3: US_s-4 | AS3: US_s-3 | AT3: US_s-2 | AU3: US_s-1 | AV3: US_s+0 | AW3: US_s+1 | AX3: US_s+2 | AY3: US_s+3 | AZ3: US_s+4 | BA3: US_s+5 | BB3: US_s+6 | BC3: CORE3_s-6 | BD3: CORE3_s-5 | BE3: CORE3_s-4 | BF3: CORE3_s-3 | BG3: CORE3_s-2 | BH3: CORE3_s-1 | BI3: CORE3_s+0 | BJ3: CORE3_s+1 | BK3: CORE3_s+2 | BL3: CORE3_s+3 | BM3: CORE3_s+4 | BN3: CORE3_s+5 | BO3: CORE3_s+6
A4: 2023Q1 | B4: 3 | C4: =IF(OR($B4+C$2-3<1,$B4+C$2>設定!$B$5),"",IFERROR(LN(INDEX(月次集計!$H$2:$H$45,$B4+C$2)/INDEX(月次集計!$H$2:$H$45,$B4+C$2-3)),"")) | D4: =IF(OR($B4+D$2-3<1,$B4+D$2>設定!$B$5),"",IFERROR(LN(INDEX(月次集計!$H$2:$H$45,$B4+D$2)/INDEX(月次集計!$H$2:$H$45,$B4+D$2-3)),"")) | E4: =IF(OR($B4+E$2-3<1,$B4+E$2>設定!$B$5),"",IFERROR(LN(INDEX(月次集計!$H$2:$H$45,$B4+E$2)/INDEX(月次集計!$H$2:$H$45,$B4+E$2-3)),"")) | F4: =IF(OR($B4+F$2-3<1,$B4+F$2>設定!$B$5),"",IFERROR(LN(INDEX(月次集計!$H$2:$H$45,$B4+F$2)/INDEX(月次集計!$H$2:$H$45,$B4+F$2-3)),"")) | G4: =IF(OR($B4+G$2-3<1,$B4+G$2>設定!$B$5),"",IFERROR(LN(INDEX(月次集計!$H$2:$H$45,$B4+G$2)/INDEX(月次集計!$H$2:$H$45,$B4+G$2-3)),"")) | H4: =IF(OR($B4+H$2-3<1,$B4+H$2>設定!$B$5),"",IFERROR(LN(INDEX(月次集計!$H$2:$H$45,$B4+H$2)/INDEX(月次集計!$H$2:$H$45,$B4+H$2-3)),"")) | I4: =IF(OR($B4+I$2-3<1,$B4+I$2>設定!$B$5),"",IFERROR(LN(INDEX(月次集計!$H$2:$H$45,$B4+I$2)/INDEX(月次集計!$H$2:$H$45,$B4+I$2-3)),"")) | J4: =IF(OR($B4+J$2-3<1,$B4+J$2>設定!$B$5),"",IFERROR(LN(INDEX(月次集計!$H$2:$H$45,$B4+J$2)/INDEX(月次集計!$H$2:$H$45,$B4+J$2-3)),"")) | ... O4: =IF(OR($B4+O$2-3<1,$B4+O$2>設定!$B$5),"",IFERROR(LN(INDEX(月次集計!$H$2:$H$45,$B4+O$2)/INDEX(月次集計!$H$2:$H$45,$B4+O$2-3)),"")) -> -0.25966925 | P4: =IF(OR($B4+P$2-3<1,$B4+P$2>設定!$B$5),"",IFERROR(LN(INDEX(月次集計!$I$2:$I$45,$B4+P$2)/INDEX(月次集計!$I$2:$I$45,$B4+P$2-3)),"")) | Q4: =IF(OR($B4+Q$2-3<1,$B4+Q$2>設定!$B$5),"",IFERROR(LN(INDEX(月次集計!$I$2:$I$45,$B4+Q$2)/INDEX(月次集計!$I$2:$I$45,$B4+Q$2-3)),"")) | R4: =IF(OR($B4+R$2-3<1,$B4+R$2>設定!$B$5),"",IFERROR(LN(INDEX(月次集計!$I$2:$I$45,$B4+R$2)/INDEX(月次集計!$I$2:$I$45,$B4+R$2-3)),"")) | S4: =IF(OR($B4+S$2-3<1,$B4+S$2>設定!$B$5),"",IFERROR(LN(INDEX(月次集計!$I$2:$I$45,$B4+S$2)/INDEX(月次集計!$I$2:$I$45,$B4+S$2-3)),"")) | T4: =IF(OR($B4+T$2-3<1,$B4+T$2>設定!$B$5),"",IFERROR(LN(INDEX(月次集計!$I$2:$I$45,$B4+T$2)/INDEX(月次集計!$I$2:$I$45,$B4+T$2-3)),"")) | U4: =IF(OR($B4+U$2-3<1,$B4+U$2>設定!$B$5),"",IFERROR(LN(INDEX(月次集計!$I$2:$I$45,$B4+U$2)/INDEX(月次集計!$I$2:$I$45,$B4+U$2-3)),"")) | V4: =IF(OR($B4+V$2-3<1,$B4+V$2>設定!$B$5),"",IFERROR(LN(INDEX(月次集計!$I$2:$I$45,$B4+V$2)/INDEX(月次集計!$I$2:$I$45,$B4+V$2-3)),"")) | W4: =IF(OR($B4+W$2-3<1,$B4+W$2>設定!$B$5),"",IFERROR(LN(INDEX(月次集計!$I$2:$I$45,$B4+W$2)/INDEX(月次集計!$I$2:$I$45,$B4+W$2-3)),"")) | ... AB4: =IF(OR($B4+AB$2-3<1,$B4+AB$2>設定!$B$5),"",IFERROR(LN(INDEX(月次集計!$I$2:$I$45,$B4+AB$2)/INDEX(月次集計!$I$2:$I$45,$B4+AB$2-3)),"")) -> -0.57386264 | AC4: =IF(OR($B4+AC$2-3<1,$B4+AC$2>設定!$B$5),"",IFERROR(LN(INDEX(月次集計!$J$2:$J$45,$B4+AC$2)/INDEX(月次集計!$J$2:$J$45,$B4+AC$2-3)),"")) | AD4: =IF(OR($B4+AD$2-3<1,$B4+AD$2>設定!$B$5),"",IFERROR(LN(INDEX(月次集計!$J$2:$J$45,$B4+AD$2)/INDEX(月次集計!$J$2:$J$45,$B4+AD$2-3)),"")) | AE4: =IF(OR($B4+AE$2-3<1,$B4+AE$2>設定!$B$5),"",IFERROR(LN(INDEX(月次集計!$J$2:$J$45,$B4+AE$2)/INDEX(月次集計!$J$2:$J$45,$B4+AE$2-3)),"")) | AF4: =IF(OR($B4+AF$2-3<1,$B4+AF$2>設定!$B$5),"",IFERROR(LN(INDEX(月次集計!$J$2:$J$45,$B4+AF$2)/INDEX(月次集計!$J$2:$J$45,$B4+AF$2-3)),"")) | AG4: =IF(OR($B4+AG$2-3<1,$B4+AG$2>設定!$B$5),"",IFERROR(LN(INDEX(月次集計!$J$2:$J$45,$B4+AG$2)/INDEX(月次集計!$J$2:$J$45,$B4+AG$2-3)),"")) | AH4: =IF(OR($B4+AH$2-3<1,$B4+AH$2>設定!$B$5),"",IFERROR(LN(INDEX(月次集計!$J$2:$J$45,$B4+AH$2)/INDEX(月次集計!$J$2:$J$45,$B4+AH$2-3)),"")) | AI4: =IF(OR($B4+AI$2-3<1,$B4+AI$2>設定!$B$5),"",IFERROR(LN(INDEX(月次集計!$J$2:$J$45,$B4+AI$2)/INDEX(月次集計!$J$2:$J$45,$B4+AI$2-3)),"")) | AJ4: =IF(OR($B4+AJ$2-3<1,$B4+AJ$2>設定!$B$5),"",IFERROR(LN(INDEX(月次集計!$J$2:$J$45,$B4+AJ$2)/INDEX(月次集計!$J$2:$J$45,$B4+AJ$2-3)),"")) | ... AO4: =IF(OR($B4+AO$2-3<1,$B4+AO$2>設定!$B$5),"",IFERROR(LN(INDEX(月次集計!$J$2:$J$45,$B4+AO$2)/INDEX(月次集計!$J$2:$J$45,$B4+AO$2-3)),"")) -> -0.59726621 | AP4: =IF(OR($B4+AP$2-3<1,$B4+AP$2>設定!$B$5),"",IFERROR(LN(INDEX(月次集計!$K$2:$K$45,$B4+AP$2)/INDEX(月次集計!$K$2:$K$45,$B4+AP$2-3)),"")) | AQ4: =IF(OR($B4+AQ$2-3<1,$B4+AQ$2>設定!$B$5),"",IFERROR(LN(INDEX(月次集計!$K$2:$K$45,$B4+AQ$2)/INDEX(月次集計!$K$2:$K$45,$B4+AQ$2-3)),"")) | AR4: =IF(OR($B4+AR$2-3<1,$B4+AR$2>設定!$B$5),"",IFERROR(LN(INDEX(月次集計!$K$2:$K$45,$B4+AR$2)/INDEX(月次集計!$K$2:$K$45,$B4+AR$2-3)),"")) | AS4: =IF(OR($B4+AS$2-3<1,$B4+AS$2>設定!$B$5),"",IFERROR(LN(INDEX(月次集計!$K$2:$K$45,$B4+AS$2)/INDEX(月次集計!$K$2:$K$45,$B4+AS$2-3)),"")) | AT4: =IF(OR($B4+AT$2-3<1,$B4+AT$2>設定!$B$5),"",IFERROR(LN(INDEX(月次集計!$K$2:$K$45,$B4+AT$2)/INDEX(月次集計!$K$2:$K$45,$B4+AT$2-3)),"")) | AU4: =IF(OR($B4+AU$2-3<1,$B4+AU$2>設定!$B$5),"",IFERROR(LN(INDEX(月次集計!$K$2:$K$45,$B4+AU$2)/INDEX(月次集計!$K$2:$K$45,$B4+AU$2-3)),"")) | AV4: =IF(OR($B4+AV$2-3<1,$B4+AV$2>設定!$B$5),"",IFERROR(LN(INDEX(月次集計!$K$2:$K$45,$B4+AV$2)/INDEX(月次集計!$K$2:$K$45,$B4+AV$2-3)),"")) | AW4: =IF(OR($B4+AW$2-3<1,$B4+AW$2>設定!$B$5),"",IFERROR(LN(INDEX(月次集計!$K$2:$K$45,$B4+AW$2)/INDEX(月次集計!$K$2:$K$45,$B4+AW$2-3)),"")) | ... BB4: =IF(OR($B4+BB$2-3<1,$B4+BB$2>設定!$B$5),"",IFERROR(LN(INDEX(月次集計!$K$2:$K$45,$B4+BB$2)/INDEX(月次集計!$K$2:$K$45,$B4+BB$2-3)),"")) | BC4: =IF(OR($B4+BC$2-3<1,$B4+BC$2>設定!$B$5),"",IFERROR(LN(INDEX(月次集計!$L$2:$L$45,$B4+BC$2)/INDEX(月次集計!$L$2:$L$45,$B4+BC$2-3)),"")) | BD4: =IF(OR($B4+BD$2-3<1,$B4+BD$2>設定!$B$5),"",IFERROR(LN(INDEX(月次集計!$L$2:$L$45,$B4+BD$2)/INDEX(月次集計!$L$2:$L$45,$B4+BD$2-3)),"")) | BE4: =IF(OR($B4+BE$2-3<1,$B4+BE$2>設定!$B$5),"",IFERROR(LN(INDEX(月次集計!$L$2:$L$45,$B4+BE$2)/INDEX(月次集計!$L$2:$L$45,$B4+BE$2-3)),"")) | BF4: =IF(OR($B4+BF$2-3<1,$B4+BF$2>設定!$B$5),"",IFERROR(LN(INDEX(月次集計!$L$2:$L$45,$B4+BF$2)/INDEX(月次集計!$L$2:$L$45,$B4+BF$2-3)),"")) | BG4: =IF(OR($B4+BG$2-3<1,$B4+BG$2>設定!$B$5),"",IFERROR(LN(INDEX(月次集計!$L$2:$L$45,$B4+BG$2)/INDEX(月次集計!$L$2:$L$45,$B4+BG$2-3)),"")) | BH4: =IF(OR($B4+BH$2-3<1,$B4+BH$2>設定!$B$5),"",IFERROR(LN(INDEX(月次集計!$L$2:$L$45,$B4+BH$2)/INDEX(月次集計!$L$2:$L$45,$B4+BH$2-3)),"")) | BI4: =IF(OR($B4+BI$2-3<1,$B4+BI$2>設定!$B$5),"",IFERROR(LN(INDEX(月次集計!$L$2:$L$45,$B4+BI$2)/INDEX(月次集計!$L$2:$L$45,$B4+BI$2-3)),"")) | BJ4: =IF(OR($B4+BJ$2-3<1,$B4+BJ$2>設定!$B$5),"",IFERROR(LN(INDEX(月次集計!$L$2:$L$45,$B4+BJ$2)/INDEX(月次集計!$L$2:$L$45,$B4+BJ$2-3)),"")) | ... BO4: =IF(OR($B4+BO$2-3<1,$B4+BO$2>設定!$B$5),"",IFERROR(LN(INDEX(月次集計!$L$2:$L$45,$B4+BO$2)/INDEX(月次集計!$L$2:$L$45,$B4+BO$2-3)),"")) -> -0.44265943
